Workbook

Sheet TABLEAU

Sheet MAHMOUD CHAALAN
H2: 0
D3: ANNEE | E3: CHIFFRE AFFAIRE | F3: TOTAL VERSEMENT | G3: SOLDE
D4: BILAN | E4: =+SUM(MAHMOUDCHAALAN[TOTAL MONTANT]) -> 4030000 | F4: =+SUM(MAHMOUDCHAALAN[VERSEMENT]) -> 1000000 | G4: =+E4-F4 -> 3030000
B5: NOM CLIENT
B6: MAHMOUD CHAALAN | E6: TRUE
A8: DATE | B8: DESIGNATION | C8: QUANTITE | D8: PRIX UNITAIRE | E8: TOTAL MONTANT | F8: VERSEMENT | G8: SOLDE
A9: 46069 | B9: SOLDE DEPART | C9: 1 | D9: 3355000 | E9: 3355000 | F9: 0 | G9: =SUM(E$9:$E9)-SUM(F$9:$F9) -> 3355000
A10: 46071 | B10: HOUSSE ROYAL | C10: 1 | D10: 35000 | E10: 35000 | F10: 0 | G10: =SUM(E$9:$E10)-SUM(F$9:$F10) -> 3390000
A11: 46071 | B11: HOUSSE RELAX | C11: 1 | D11: 25000 | E11: 25000 | F11: 0 | G11: =SUM(E$9:$E11)-SUM(F$9:$F11) -> 3415000
A12: 46077 | B12: MOUNTAIN TOP | C12: 1 | D12: 400000 | E12: 400000 | F12: 0 | G12: =SUM(E$9:$E12)-SUM(F$9:$F12) -> 3815000
A13: 46081 | B13: VERSEMENT | C13: 1 | D13: 0 | E13: 0 | F13: 500000 | G13: =SUM(E$9:$E13)-SUM(F$9:$F13) -> 3315000
A14: 46083 | B14: AMPOULE H7 LED | C14: 2 | D14: 7500 | E14: 15000 | F14: 0 | G14: =SUM(E$9:$E14)-SUM(F$9:$F14) -> 3330000
A15: 46083 | B15: EXTINCTEUR 1KG | C15: 5 | D15: 3500 | E15: 17500 | F15: 0 | G15: =SUM(E$9:$E15)-SUM(F$9:$F15) -> 3347500
A16: 46083 | B16: NETTOYANT MOTEUR | C16: 12 | D16: 0 | E16: 32500 | F16: 0 | G16: =SUM(E$9:$E16)-SUM(F$9:$F16) -> 3380000
A17: 46085 | B17: NETTOYANT DISC CADEAU | C17: 1 | D17: 0 | E17: 0 | F17: 0 | G17: =SUM(E$9:$E17)-SUM(F$9:$F17) -> 3380000
A18: 46085 | B18: EXCTINCTEUR 2 KG RECHARGEABLE | C18: 2 | D18: 10000 | E18: 20000 | F18: 0 | G18: =SUM(E$9:$E18)-SUM(F$9:$F18) -> 3400000
A19: 46086 | B19: BACHE LC | C19: 1 | D19: 30000 | E19: 30000 | F19: 0 | G19: =SUM(E$9:$E19)-SUM(F$9:$F19) -> 3430000
A20: 46086 | B20: BACHE GMC | C20: 1 | D20: 30000 | E20: 30000 | F20: 0 | G20: =SUM(E$9:$E20)-SUM(F$9:$F20) -> 3460000
... A22: 46094 | B22: VERSEMENT | C22: 1 | D22: 0 | E22: 0 | F22: 500000 | G22: =SUM(E$9:$E22)-SUM(F$9:$F22) -> 3030000
E23: =+$H$2+(MAHMOUDCHAALAN[[#This Row],[QUANTITE]]*MAHMOUDCHAALAN[[#This Row],[PRIX UNITAIRE]]) -> 0 | G23: =SUM(E$9:$E23)-SUM(F$9:$F23) -> 3030000
E24: =+$H$2+(MAHMOUDCHAALAN[[#This Row],[QUANTITE]]*MAHMOUDCHAALAN[[#This Row],[PRIX UNITAIRE]]) -> 0 | G24: =SUM(E$9:$E24)-SUM(F$9:$F24) -> 3030000
E25: =+$H$2+(MAHMOUDCHAALAN[[#This Row],[QUANTITE]]*MAHMOUDCHAALAN[[#This Row],[PRIX UNITAIRE]]) -> 0 | G25: =SUM(E$9:$E25)-SUM(F$9:$F25) -> 3030000
E26: =+$H$2+(MAHMOUDCHAALAN[[#This Row],[QUANTITE]]*MAHMOUDCHAALAN[[#This Row],[PRIX UNITAIRE]]) -> 0 | G26: =SUM(E$9:$E26)-SUM(F$9:$F26) -> 3030000
E27: =+$H$2+(MAHMOUDCHAALAN[[#This Row],[QUANTITE]]*MAHMOUDCHAALAN[[#This Row],[PRIX UNITAIRE]]) -> 0 | G27: =SUM(E$9:$E27)-SUM(F$9:$F27) -> 3030000
E28: =+$H$2+(MAHMOUDCHAALAN[[#This Row],[QUANTITE]]*MAHMOUDCHAALAN[[#This Row],[PRIX UNITAIRE]]) -> 0 | G28: =SUM(E$9:$E28)-SUM(F$9:$F28) -> 3030000
E29: =+$H$2+(MAHMOUDCHAALAN[[#This Row],[QUANTITE]]*MAHMOUDCHAALAN[[#This Row],[PRIX UNITAIRE]]) -> 0 | G29: =SUM(E$9:$E29)-SUM(F$9:$F29) -> 3030000
E30: =+$H$2+(MAHMOUDCHAALAN[[#This Row],[QUANTITE]]*MAHMOUDCHAALAN[[#This Row],[PRIX UNITAIRE]]) -> 0 | G30: =SUM(E$9:$E30)-SUM(F$9:$F30) -> 3030000
E31: =+$H$2+(MAHMOUDCHAALAN[[#This Row],[QUANTITE]]*MAHMOUDCHAALAN[[#This Row],[PRIX UNITAIRE]]) -> 0 | G31: =SUM(E$9:$E31)-SUM(F$9:$F31) -> 3030000
E32: =+$H$2+(MAHMOUDCHAALAN[[#This Row],[QUANTITE]]*MAHMOUDCHAALAN[[#This Row],[PRIX UNITAIRE]]) -> 0 | G32: =SUM(E$9:$E32)-SUM(F$9:$F32) -> 3030000
E33: =+$H$2+(MAHMOUDCHAALAN[[#This Row],[QUANTITE]]*MAHMOUDCHAALAN[[#This Row],[PRIX UNITAIRE]]) -> 0 | G33: =SUM(E$9:$E33)-SUM(F$9:$F33) -> 3030000
E34: =+$H$2+(MAHMOUDCHAALAN[[#This Row],[QUANTITE]]*MAHMOUDCHAALAN[[#This Row],[PRIX UNITAIRE]]) -> 0 | G34: =SUM(E$9:$E34)-SUM(F$9:$F34) -> 3030000
... E159: =+$H$2+(MAHMOUDCHAALAN[[#This Row],[QUANTITE]]*MAHMOUDCHAALAN[[#This Row],[PRIX UNITAIRE]]) -> 0 | G159: =SUM(E$9:$E159)-SUM(F$9:$F159) -> 3030000

Sheet CHINOIS
I2: 0
D3: ANNEE | E3: CHIFFRE AFFAIRE | F3: TOTAL VERSEMENT | G3: SOLDE
D4: BILAN | E4: =+SUM(CHINOIS[TOTAL MONTANT]) -> 12350000 | F4: =+SUM(CHINOIS[VERSEMENT]) -> 4200000 | G4: =+E4-F4 -> 8150000
B5: NOM CLIENT
B6: CHINOIS | E6: TRUE
A8: DATE | B8: DESIGNATION | C8: QUANTITE | D8: PRIX UNITAIRE | E8: TOTAL MONTANT | F8: VERSEMENT | G8: SOLDE
A9: 46069 | B9: SOLDE DEPART | C9: 1 | D9: 2200000 | E9: 2200000 | F9: 0 | G9: =SUM(E$9:$E9)-SUM(F$9:$F9) -> 2200000
A10: 46084 | B10: VERSEMENT | C10: 1 | D10: 0 | E10: 0 | F10: 1200000 | G10: =SUM(E$9:$E10)-SUM(F$9:$F10) -> 1000000
A11: 46093 | B11: 315/80R22,5 MACROYAL | C11: 25 | D11: 88000 | E11: 2200000 | F11: 0 | G11: =SUM(E$9:$E11)-SUM(F$9:$F11) -> 3200000
A12: 46094 | B12: 13R22,5 MACROYAL | C12: 25 | D12: 115000 | E12: 2875000 | F12: 0 | G12: =SUM(E$9:$E12)-SUM(F$9:$F12) -> 6075000
A13: 46098 | B13: 315/80R22,5 MACROYAL | C13: 25 | D13: 88000 | E13: 2200000 | F13: 0 | G13: =SUM(E$9:$E13)-SUM(F$9:$F13) -> 8275000
A14: 46098 | B14: 13R22,5 MACROYAL | C14: 25 | D14: 115000 | E14: 2875000 | F14: 0 | G14: =SUM(E$9:$E14)-SUM(F$9:$F14) -> 11150000
A15: 46098 | B15: VERSEMENT | C15: 1 | D15: 0 | E15: 0 | F15: 3000000 | G15: =SUM(E$9:$E15)-SUM(F$9:$F15) -> 8150000
G16: =SUM(E$9:$E16)-SUM(F$9:$F16) -> 8150000
G17: =SUM(E$9:$E17)-SUM(F$9:$F17) -> 8150000
G18: =SUM(E$9:$E18)-SUM(F$9:$F18) -> 8150000
G19: =SUM(E$9:$E19)-SUM(F$9:$F19) -> 8150000
G20: =SUM(E$9:$E20)-SUM(F$9:$F20) -> 8150000
G21: =SUM(E$9:$E21)-SUM(F$9:$F21) -> 8150000
G22: =SUM(E$9:$E22)-SUM(F$9:$F22) -> 8150000
G23: =SUM(E$9:$E23)-SUM(F$9:$F23) -> 8150000
G24: =SUM(E$9:$E24)-SUM(F$9:$F24) -> 8150000
G25: =SUM(E$9:$E25)-SUM(F$9:$F25) -> 8150000
G26: =SUM(E$9:$E26)-SUM(F$9:$F26) -> 8150000
G27: =SUM(E$9:$E27)-SUM(F$9:$F27) -> 8150000
... G104: =SUM(E$9:$E104)-SUM(F$9:$F104) -> 8150000
E105: =+$I$2+(CHINOIS[[#This Row],[QUANTITE]]*CHINOIS[[#This Row],[PRIX UNITAIRE]]) -> 0 | G105: =SUM(E$9:$E105)-SUM(F$9:$F105) -> 8150000
E106: =+$I$2+(CHINOIS[[#This Row],[QUANTITE]]*CHINOIS[[#This Row],[PRIX UNITAIRE]]) -> 0 | G106: =SUM(E$9:$E106)-SUM(F$9:$F106) -> 8150000
E107: =+$I$2+(CHINOIS[[#This Row],[QUANTITE]]*CHINOIS[[#This Row],[PRIX UNITAIRE]]) -> 0 | G107: =SUM(E$9:$E107)-SUM(F$9:$F107) -> 8150000
E108: =+$I$2+(CHINOIS[[#This Row],[QUANTITE]]*CHINOIS[[#This Row],[PRIX UNITAIRE]]) -> 0 | G108: =SUM(E$9:$E108)-SUM(F$9:$F108) -> 8150000
E109: =+$I$2+(CHINOIS[[#This Row],[QUANTITE]]*CHINOIS[[#This Row],[PRIX UNITAIRE]]) -> 0 | G109: =SUM(E$9:$E109)-SUM(F$9:$F109) -> 8150000

Sheet SUNSTEEL - KEVIN
I2: 0
D3: ANNEE | E3: CHIFFRE AFFAIRE | F3: TOTAL VERSEMENT | G3: SOLDE
D4: BILAN | E4: =+SUM(SUNSTEEKEVIN[TOTAL MONTANT]) -> 7750000 | F4: =+SUM(SUNSTEEKEVIN[VERSEMENT]) -> 7750000 | G4: =+E4-F4 -> 0
B5: NOM CLIENT
B6: SUNSTEEL - KEVIN | E6: TRUE
A8: DATE | B8: DESIGNATION | C8: QUANTITE | D8: PRIX UNITAIRE | E8: TOTAL MONTANT | F8: VERSEMENT | G8: SOLDE
A9: 46069 | B9: SOLDE DEPART | C9: 1 | D9: 3690000 | E9: 3690000 | F9: 0 | G9: =SUM(E$9:$E9)-SUM(F$9:$F9) -> 3690000
A10: 46079 | B10: VERSEMENT | C10: 1 | D10: 0 | E10: 0 | F10: 3690000 | G10: =SUM(E$9:$E10)-SUM(F$9:$F10) -> 0
A11: 46081 | B11: 13/22,5 DRIVEMASTER | C11: 20 | D11: 115000 | E11: 2300000 | F11: 0 | G11: =SUM(E$9:$E11)-SUM(F$9:$F11) -> 2300000
A12: 46081 | B12: 315/80R22,5 | C12: 20 | D12: 88000 | E12: 1760000 | F12: 0 | G12: =SUM(E$9:$E12)-SUM(F$9:$F12) -> 4060000
A13: 46081 | B13: VERSEMENT | C13: 1 | D13: 0 | E13: 0 | F13: 1060000 | G13: =SUM(E$9:$E13)-SUM(F$9:$F13) -> 3000000
A14: 46093 | B14: VERSEMENT | C14: 1 | D14: 0 | E14: 0 | F14: 3000000 | G14: =SUM(E$9:$E14)-SUM(F$9:$F14) -> 0
G15: =SUM(E$9:$E15)-SUM(F$9:$F15) -> 0
G16: =SUM(E$9:$E16)-SUM(F$9:$F16) -> 0
G17: =SUM(E$9:$E17)-SUM(F$9:$F17) -> 0
G18: =SUM(E$9:$E18)-SUM(F$9:$F18) -> 0
G19: =SUM(E$9:$E19)-SUM(F$9:$F19) -> 0
G20: =SUM(E$9:$E20)-SUM(F$9:$F20) -> 0
G21: =SUM(E$9:$E21)-SUM(F$9:$F21) -> 0
G22: =SUM(E$9:$E22)-SUM(F$9:$F22) -> 0
G23: =SUM(E$9:$E23)-SUM(F$9:$F23) -> 0
G24: =SUM(E$9:$E24)-SUM(F$9:$F24) -> 0
G25: =SUM(E$9:$E25)-SUM(F$9:$F25) -> 0
G26: =SUM(E$9:$E26)-SUM(F$9:$F26) -> 0
... G508: =SUM(E$9:$E508)-SUM(F$9:$F508) -> 0
E509: =+$I$2+(SUNSTEEKEVIN[[#This Row],[QUANTITE]]*SUNSTEEKEVIN[[#This Row],[PRIX UNITAIRE]]) -> 0 | G509: =SUM(E$9:$E509)-SUM(F$9:$F509) -> 0
E510: =+$I$2+(SUNSTEEKEVIN[[#This Row],[QUANTITE]]*SUNSTEEKEVIN[[#This Row],[PRIX UNITAIRE]]) -> 0 | G510: =SUM(E$9:$E510)-SUM(F$9:$F510) -> 0
E511: =+$I$2+(SUNSTEEKEVIN[[#This Row],[QUANTITE]]*SUNSTEEKEVIN[[#This Row],[PRIX UNITAIRE]]) -> 0 | G511: =SUM(E$9:$E511)-SUM(F$9:$F511) -> 0
E512: =+$I$2+(SUNSTEEKEVIN[[#This Row],[QUANTITE]]*SUNSTEEKEVIN[[#This Row],[PRIX UNITAIRE]]) -> 0 | G512: =SUM(E$9:$E512)-SUM(F$9:$F512) -> 0

Sheet MOUSTAPHA FAWAZ
I2: 0
D3: ANNEE | E3: CHIFFRE AFFAIRE | F3: TOTAL VERSEMENT | G3: SOLDE
D4: BILAN | E4: =+SUM(MOUSTAPHAFAWAZ[TOTAL MONTANT]) -> 1137500 | F4: =+SUM(MOUSTAPHAFAWAZ[VERSEMENT]) -> 807500 | G4: =+E4-F4 -> 330000
B5: NOM CLIENT
B6: MOUSTAPHA FAWAZ
A8: DATE | B8: DESIGNATION | C8: QUANTITE | D8: PRIX UNITAIRE | E8: TOTAL MONTANT | F8: VERSEMENT | G8: SOLDE
A9: 46069 | B9: SOLDE DEPART | C9: 1 | D9: 332500 | E9: 332500 | F9: 0 | G9: =SUM(E$9:$E9)-SUM(F$9:$F9) -> 332500
A10: 46066 | B10: 275/40R22 KAPSEN | C10: 3 | D10: 65000 | E10: 195000 | F10: 0 | G10: =SUM(E$9:$E10)-SUM(F$9:$F10) -> 527500
A11: 46072 | B11: PNEU 195/R15C PERFLY | C11: 2 | D11: 32500 | E11: 65000 | F11: 0 | G11: =SUM(E$9:$E11)-SUM(F$9:$F11) -> 592500
A12: 46080 | B12: PNEU 215/65R17 KAPSEN | C12: 2 | D12: 35000 | E12: 70000 | F12: 0 | G12: =SUM(E$9:$E12)-SUM(F$9:$F12) -> 662500
A13: 46083 | B13: 215/60R17 TRACMAX | C13: 2 | D13: 35000 | E13: 70000 | F13: 0 | G13: =SUM(E$9:$E13)-SUM(F$9:$F13) -> 732500
A14: 46084 | B14: 225/65R17 KAPSEN | C14: 2 | D14: 37500 | E14: 75000 | F14: 0 | G14: =SUM(E$9:$E14)-SUM(F$9:$F14) -> 807500
A15: 46091 | B15: VERSEMENT | C15: 1 | D15: 0 | E15: 0 | F15: 807500 | G15: =SUM(E$9:$E15)-SUM(F$9:$F15) -> 0
A16: 46092 | B16: PNEU 225/65R17 KAPSEN | C16: 4 | D16: 37500 | E16: 150000 | F16: 0 | G16: =SUM(E$9:$E16)-SUM(F$9:$F16) -> 150000
A17: 46099 | B17: PNEU 235/60R18 KAPSEN | C17: 4 | D17: 45000 | E17: 180000 | F17: 0 | G17: =SUM(E$9:$E17)-SUM(F$9:$F17) -> 330000
E18: =MOUSTAPHAFAWAZ[[#This Row],[PRIX UNITAIRE]]*MOUSTAPHAFAWAZ[[#This Row],[QUANTITE]] -> 0 | G18: =SUM(E$9:$E18)-SUM(F$9:$F18) -> 330000
E19: =MOUSTAPHAFAWAZ[[#This Row],[PRIX UNITAIRE]]*MOUSTAPHAFAWAZ[[#This Row],[QUANTITE]] -> 0 | G19: =SUM(E$9:$E19)-SUM(F$9:$F19) -> 330000
E20: =MOUSTAPHAFAWAZ[[#This Row],[PRIX UNITAIRE]]*MOUSTAPHAFAWAZ[[#This Row],[QUANTITE]] -> 0 | G20: =SUM(E$9:$E20)-SUM(F$9:$F20) -> 330000
E21: =MOUSTAPHAFAWAZ[[#This Row],[PRIX UNITAIRE]]*MOUSTAPHAFAWAZ[[#This Row],[QUANTITE]] -> 0 | G21: =SUM(E$9:$E21)-SUM(F$9:$F21) -> 330000
E22: =MOUSTAPHAFAWAZ[[#This Row],[PRIX UNITAIRE]]*MOUSTAPHAFAWAZ[[#This Row],[QUANTITE]] -> 0 | G22: =SUM(E$9:$E22)-SUM(F$9:$F22) -> 330000
E23: =MOUSTAPHAFAWAZ[[#This Row],[PRIX UNITAIRE]]*MOUSTAPHAFAWAZ[[#This Row],[QUANTITE]] -> 0 | G23: =SUM(E$9:$E23)-SUM(F$9:$F23) -> 330000
E24: =MOUSTAPHAFAWAZ[[#This Row],[PRIX UNITAIRE]]*MOUSTAPHAFAWAZ[[#This Row],[QUANTITE]] -> 0 | G24: =SUM(E$9:$E24)-SUM(F$9:$F24) -> 330000
E25: =MOUSTAPHAFAWAZ[[#This Row],[PRIX UNITAIRE]]*MOUSTAPHAFAWAZ[[#This Row],[QUANTITE]] -> 0 | G25: =SUM(E$9:$E25)-SUM(F$9:$F25) -> 330000
E26: =MOUSTAPHAFAWAZ[[#This Row],[PRIX UNITAIRE]]*MOUSTAPHAFAWAZ[[#This Row],[QUANTITE]] -> 0 | G26: =SUM(E$9:$E26)-SUM(F$9:$F26) -> 330000
E27: =MOUSTAPHAFAWAZ[[#This Row],[PRIX UNITAIRE]]*MOUSTAPHAFAWAZ[[#This Row],[QUANTITE]] -> 0 | G27: =SUM(E$9:$E27)-SUM(F$9:$F27) -> 330000
E28: =MOUSTAPHAFAWAZ[[#This Row],[PRIX UNITAIRE]]*MOUSTAPHAFAWAZ[[#This Row],[QUANTITE]] -> 0 | G28: =SUM(E$9:$E28)-SUM(F$9:$F28) -> 330000
E29: =MOUSTAPHAFAWAZ[[#This Row],[PRIX UNITAIRE]]*MOUSTAPHAFAWAZ[[#This Row],[QUANTITE]] -> 0 | G29: =SUM(E$9:$E29)-SUM(F$9:$F29) -> 330000
... E109: =MOUSTAPHAFAWAZ[[#This Row],[PRIX UNITAIRE]]*MOUSTAPHAFAWAZ[[#This Row],[QUANTITE]] -> 0 | G109: =SUM(E$9:$E109)-SUM(F$9:$F109) -> 330000

Sheet PETIT SOLO
I2: 0
D3: ANNEE | E3: CHIFFRE AFFAIRE | F3: TOTAL VERSEMENT | G3: SOLDE
D4: BILAN | E4: =+SUM(PETITSOLO[TOTAL MONTANT]) -> 5357500 | F4: =+SUM(PETITSOLO[VERSEMENT]) -> 5177500 | G4: =+E4-F4 -> 180000
B5: NOM CLIENT
B6: PETIT SOLO
A8: DATE | B8: DESIGNATION | C8: QUANTITE | D8: PRIX UNITAIRE | E8: TOTAL MONTANT | F8: VERSEMENT | G8: SOLDE
A9: 45834 | B9: PNEU TRANSMATE 235/55R17 | C9: 4 | D9: 35000 | E9: =+$I$2+(PETITSOLO[[#This Row],[QUANTITE]]*PETITSOLO[[#This Row],[PRIX UNITAIRE]]) -> 140000 | G9: =SUM(E$9:$E9)-SUM(F$9:$F9) -> 140000
A10: 45839 | B10: PNEUTRANSMATE 225/45R17 | C10: 2 | D10: 35000 | E10: =+$I$2+(PETITSOLO[[#This Row],[QUANTITE]]*PETITSOLO[[#This Row],[PRIX UNITAIRE]]) -> 70000 | G10: =SUM(E$9:$E10)-SUM(F$9:$F10) -> 210000
A11: 45840 | B11: PNEU 235/60R18 TRANSMATE | C11: 4 | D11: 40000 | E11: =+$I$2+(PETITSOLO[[#This Row],[QUANTITE]]*PETITSOLO[[#This Row],[PRIX UNITAIRE]]) -> 160000 | G11: =SUM(E$9:$E11)-SUM(F$9:$F11) -> 370000
A12: 45846 | B12: PNEU 245/40R20 GLEDE | C12: 2 | D12: 50000 | E12: =+$I$2+(PETITSOLO[[#This Row],[QUANTITE]]*PETITSOLO[[#This Row],[PRIX UNITAIRE]]) -> 100000 | G12: =SUM(E$9:$E12)-SUM(F$9:$F12) -> 470000
A13: 45847 | B13: PNEU 235/65R17 GLEDE | C13: 4 | D13: 35000 | E13: =+$I$2+(PETITSOLO[[#This Row],[QUANTITE]]*PETITSOLO[[#This Row],[PRIX UNITAIRE]]) -> 140000 | G13: =SUM(E$9:$E13)-SUM(F$9:$F13) -> 610000
A14: 45848 | B14: PNEU 235/60R18 GLEDE | C14: 2 | D14: 40000 | E14: =+$I$2+(PETITSOLO[[#This Row],[QUANTITE]]*PETITSOLO[[#This Row],[PRIX UNITAIRE]]) -> 80000 | G14: =SUM(E$9:$E14)-SUM(F$9:$F14) -> 690000
A15: 45849 | B15: PNEU 225/50R17 GLEDDE | C15: 10 | D15: 35000 | E15: =+$I$2+(PETITSOLO[[#This Row],[QUANTITE]]*PETITSOLO[[#This Row],[PRIX UNITAIRE]]) -> 350000 | G15: =SUM(E$9:$E15)-SUM(F$9:$F15) -> 1040000
A16: 45849 | B16: PNEU 235/60R18 GLEDE | C16: 4 | D16: 42500 | E16: =+$I$2+(PETITSOLO[[#This Row],[QUANTITE]]*PETITSOLO[[#This Row],[PRIX UNITAIRE]]) -> 170000 | G16: =SUM(E$9:$E16)-SUM(F$9:$F16) -> 1210000
A17: 45836 | B17: PNEU 235/55R19 GLEDE | C17: 4 | D17: 42500 | E17: =+$I$2+(PETITSOLO[[#This Row],[QUANTITE]]*PETITSOLO[[#This Row],[PRIX UNITAIRE]]) -> 170000 | G17: =SUM(E$9:$E17)-SUM(F$9:$F17) -> 1380000
A18: 45850 | B18: PAYE | E18: =+$I$2+(PETITSOLO[[#This Row],[QUANTITE]]*PETITSOLO[[#This Row],[PRIX UNITAIRE]]) -> 0 | F18: 1380000 | G18: =SUM(E$9:$E18)-SUM(F$9:$F18) -> 0
A19: 45852 | B19: PNEU 235/60R18 GLED | C19: 4 | D19: 40000 | E19: =+$I$2+(PETITSOLO[[#This Row],[QUANTITE]]*PETITSOLO[[#This Row],[PRIX UNITAIRE]]) -> 160000 | G19: =SUM(E$9:$E19)-SUM(F$9:$F19) -> 160000
A20: 45852 | B20: PNEU 255/55R20 GLEDE | C20: 4 | D20: 50000 | E20: =+$I$2+(PETITSOLO[[#This Row],[QUANTITE]]*PETITSOLO[[#This Row],[PRIX UNITAIRE]]) -> 200000 | G20: =SUM(E$9:$E20)-SUM(F$9:$F20) -> 360000
A21: 45856 | B21: PNEU 205/55R16 GLEDE | C21: 2 | D21: 25000 | E21: =+$I$2+(PETITSOLO[[#This Row],[QUANTITE]]*PETITSOLO[[#This Row],[PRIX UNITAIRE]]) -> 50000 | G21: =SUM(E$9:$E21)-SUM(F$9:$F21) -> 410000
A22: 45853 | B22: PNEU 225.65R17 GLEDE | C22: 0 | E22: =+$I$2+(PETITSOLO[[#This Row],[QUANTITE]]*PETITSOLO[[#This Row],[PRIX UNITAIRE]]) -> 0 | G22: =SUM(E$9:$E22)-SUM(F$9:$F22) -> 410000
A23: 45855 | B23: PNEU 255/50R20 GLEDE | C23: 4 | D23: 50000 | E23: =+$I$2+(PETITSOLO[[#This Row],[QUANTITE]]*PETITSOLO[[#This Row],[PRIX UNITAIRE]]) -> 200000 | G23: =SUM(E$9:$E23)-SUM(F$9:$F23) -> 610000
A24: 45856 | B24: PAYE | E24: =+$I$2+(PETITSOLO[[#This Row],[QUANTITE]]*PETITSOLO[[#This Row],[PRIX UNITAIRE]]) -> 0 | F24: 610000 | G24: =SUM(E$9:$E24)-SUM(F$9:$F24) -> 0
A25: 45860 | B25: PNEU 225/55R19 GLEDE | C25: 2 | D25: 42500 | E25: =+$I$2+(PETITSOLO[[#This Row],[QUANTITE]]*PETITSOLO[[#This Row],[PRIX UNITAIRE]]) -> 85000 | G25: =SUM(E$9:$E25)-SUM(F$9:$F25) -> 85000
A26: 45861 | B26: PNEU 175/70R14 | C26: 6 | D26: 16000 | E26: =+$I$2+(PETITSOLO[[#This Row],[QUANTITE]]*PETITSOLO[[#This Row],[PRIX UNITAIRE]]) -> 96000 | G26: =SUM(E$9:$E26)-SUM(F$9:$F26) -> 181000
A27: 45862 | B27: PNEU 235/60R18 GLEDE | C27: 2 | D27: 40000 | E27: =+$I$2+(PETITSOLO[[#This Row],[QUANTITE]]*PETITSOLO[[#This Row],[PRIX UNITAIRE]]) -> 80000 | G27: =SUM(E$9:$E27)-SUM(F$9:$F27) -> 261000
A28: 45863 | B28: PNEU 225/55R18 GLEDE | C28: 6 | D28: 40000 | E28: =+$I$2+(PETITSOLO[[#This Row],[QUANTITE]]*PETITSOLO[[#This Row],[PRIX UNITAIRE]]) -> 240000 | G28: =SUM(E$9:$E28)-SUM(F$9:$F28) -> 501000
A29: 45864 | B29: PNEU 225/55R19 GLEDE | C29: 4 | E29: =+$I$2+(PETITSOLO[[#This Row],[QUANTITE]]*PETITSOLO[[#This Row],[PRIX UNITAIRE]]) -> 0 | G29: =SUM(E$9:$E29)-SUM(F$9:$F29) -> 501000
A30: 45861 | B30: PNEU 245/50R20 KHUMO | C30: 2 | D30: 140000 | E30: =+$I$2+(PETITSOLO[[#This Row],[QUANTITE]]*PETITSOLO[[#This Row],[PRIX UNITAIRE]]) -> 280000 | G30: =SUM(E$9:$E30)-SUM(F$9:$F30) -> 781000
A31: 45857 | B31: PNEU 225/65R17 GLEDE | C31: 2 | D31: 35000 | E31: =+$I$2+(PETITSOLO[[#This Row],[QUANTITE]]*PETITSOLO[[#This Row],[PRIX UNITAIRE]]) -> 70000 | G31: =SUM(E$9:$E31)-SUM(F$9:$F31) -> 851000
A32: 45857 | B32: PNEU 225/55R18 GLEDE | C32: 4 | D32: 40000 | E32: =+$I$2+(PETITSOLO[[#This Row],[QUANTITE]]*PETITSOLO[[#This Row],[PRIX UNITAIRE]]) -> 160000 | G32: =SUM(E$9:$E32)-SUM(F$9:$F32) -> 1011000
A33: 45864 | B33: PAYE | E33: =+$I$2+(PETITSOLO[[#This Row],[QUANTITE]]*PETITSOLO[[#This Row],[PRIX UNITAIRE]]) -> 0 | F33: 780000 | G33: =SUM(E$9:$E33)-SUM(F$9:$F33) -> 231000
A34: 45868 | B34: PNEU 225/65R17 GLEDE | C34: 4 | D34: 35000 | E34: =+$I$2+(PETITSOLO[[#This Row],[QUANTITE]]*PETITSOLO[[#This Row],[PRIX UNITAIRE]]) -> 140000 | G34: =SUM(E$9:$E34)-SUM(F$9:$F34) -> 371000
A35: 45871 | B35: PNEU 225/55R19 GLEDE | C35: 2 | D35: 42500 | E35: =+$I$2+(PETITSOLO[[#This Row],[QUANTITE]]*PETITSOLO[[#This Row],[PRIX UNITAIRE]]) -> 85000 | G35: =SUM(E$9:$E35)-SUM(F$9:$F35) -> 456000
A36: 45874 | B36: PNEU 265/60R18 GLEDE | C36: 4 | E36: =+$I$2+(PETITSOLO[[#This Row],[QUANTITE]]*PETITSOLO[[#This Row],[PRIX UNITAIRE]]) -> 0 | G36: =SUM(E$9:$E36)-SUM(F$9:$F36) -> 456000
A37: 45864 | B37: PNEU 235/55R19 GLEDE | C37: 3 | D37: 42500 | E37: =+$I$2+(PETITSOLO[[#This Row],[QUANTITE]]*PETITSOLO[[#This Row],[PRIX UNITAIRE]]) -> 127500 | G37: =SUM(E$9:$E37)-SUM(F$9:$F37) -> 583500
A38: 45864 | B38: PNEU 225/655R19 GLEDE | C38: 4 | D38: 42500 | E38: =+$I$2+(PETITSOLO[[#This Row],[QUANTITE]]*PETITSOLO[[#This Row],[PRIX UNITAIRE]]) -> 170000 | G38: =SUM(E$9:$E38)-SUM(F$9:$F38) -> 753500
A39: 45877 | B39: PNEU 225/60R18 GLEDE | C39: 4 | D39: 40000 | E39: =+$I$2+(PETITSOLO[[#This Row],[QUANTITE]]*PETITSOLO[[#This Row],[PRIX UNITAIRE]]) -> 160000 | G39: =SUM(E$9:$E39)-SUM(F$9:$F39) -> 913500
A40: 45877 | B40: PNEU 235/60R18 GLEDE | C40: 4 | E40: =+$I$2+(PETITSOLO[[#This Row],[QUANTITE]]*PETITSOLO[[#This Row],[PRIX UNITAIRE]]) -> 0 | G40: =SUM(E$9:$E40)-SUM(F$9:$F40) -> 913500
A41: 45880 | B41: PNEU 255/40R18 GLEDE | C41: 2 | E41: =+$I$2+(PETITSOLO[[#This Row],[QUANTITE]]*PETITSOLO[[#This Row],[PRIX UNITAIRE]]) -> 0 | G41: =SUM(E$9:$E41)-SUM(F$9:$F41) -> 913500
A42: 45881 | B42: PNEU 225./60R17 GLEDE | C42: 4 | D42: 35000 | E42: =+$I$2+(PETITSOLO[[#This Row],[QUANTITE]]*PETITSOLO[[#This Row],[PRIX UNITAIRE]]) -> 140000 | G42: =SUM(E$9:$E42)-SUM(F$9:$F42) -> 1053500
...

Sheet GEDIS 
I2: 0
D3: ANNEE | E3: CHIFFRE AFFAIRE | F3: TOTAL VERSEMENT | G3: SOLDE
D4: BILAN | E4: =+SUM(GEDIS[TOTAL MONTANT]) -> 9035000 | F4: =+SUM(GEDIS[VERSEMENT]) -> 3500000 | G4: =+E4-F4 -> 5535000
B5: NOM CLIENT
B6: GEDIS
A8: DATE | B8: DESIGNATION | C8: QUANTITE | D8: PRIX UNITAIRE | E8: TOTAL MONTANT | F8: VERSEMENT | G8: SOLDE
A9: 46069 | B9: SOLDE DEPART | C9: 1 | D9: 3302000 | E9: 3302000 | F9: 0 | G9: =SUM(E$9:$E9)-SUM(F$9:$F9) -> 3302000
A10: 46077 | B10: 15w40 ENI 200 LITRES | C10: 2 | D10: 350000 | E10: 700000 | F10: 0 | G10: =SUM(E$9:$E10)-SUM(F$9:$F10) -> 4002000
A11: 46077 | B11: GENIX 68 200 LITRES | C11: 1 | D11: 195000 | E11: 195000 | F11: 0 | G11: =SUM(E$9:$E11)-SUM(F$9:$F11) -> 4197000
A12: 46083 | B12: 15W40 ENI 200 LITRES | C12: 2 | D12: 350000 | E12: 700000 | F12: 0 | G12: =SUM(E$9:$E12)-SUM(F$9:$F12) -> 4897000
A13: 46083 | B13: GENIX 68 200 LITRES | C13: 2 | D13: 195000 | E13: 390000 | F13: 0 | G13: =SUM(E$9:$E13)-SUM(F$9:$F13) -> 5287000
A14: 46083 | B14: SAE 50 ENI 200 LITRES | C14: 1 | D14: 390000 | E14: 390000 | F14: 0 | G14: =SUM(E$9:$E14)-SUM(F$9:$F14) -> 5677000
A15: 46083 | B15: 15w40 ENI 200 LITRES | C15: 2 | D15: 350000 | E15: 700000 | F15: 0 | G15: =SUM(E$9:$E15)-SUM(F$9:$F15) -> 6377000
A16: 46083 | B16: OSO 46 GENIX 200 LITREES | C16: 2 | D16: 195000 | E16: 390000 | F16: 0 | G16: =SUM(E$9:$E16)-SUM(F$9:$F16) -> 6767000
A17: 46083 | B17: GENIX 68 200 LITRES | C17: 1 | D17: 195000 | E17: 195000 | F17: 0 | G17: =SUM(E$9:$E17)-SUM(F$9:$F17) -> 6962000
A18: 46084 | B18: VERSEMENT | C18: 1 | D18: 0 | E18: 0 | F18: 3500000 | G18: =SUM(E$9:$E18)-SUM(F$9:$F18) -> 3462000
A19: 46087 | B19: 15w40 ENI 200 LITRES | C19: 2 | D19: 350000 | E19: 700000 | F19: 0 | G19: =SUM(E$9:$E19)-SUM(F$9:$F19) -> 4162000
A20: 46087 | B20: GENIX 68 200 LITRES | C20: 1 | D20: 195000 | E20: 195000 | F20: 0 | G20: =SUM(E$9:$E20)-SUM(F$9:$F20) -> 4357000
... A22: 46099 | B22: 15w40 ENI 200 LITRES | C22: 2 | D22: 350000 | E22: 700000 | F22: 0 | G22: =SUM(E$9:$E22)-SUM(F$9:$F22) -> 5447000
A23: 46100 | B23: GRAISSE CAMION 15 KG | C23: 5 | D23: 17600 | E23: =GEDIS[[#This Row],[PRIX UNITAIRE]]*GEDIS[[#This Row],[QUANTITE]] -> 88000 | G23: =SUM(E$9:$E23)-SUM(F$9:$F23) -> 5535000
G24: =SUM(E$9:$E24)-SUM(F$9:$F24) -> 5535000
G25: =SUM(E$9:$E25)-SUM(F$9:$F25) -> 5535000
G26: =SUM(E$9:$E26)-SUM(F$9:$F26) -> 5535000
G27: =SUM(E$9:$E27)-SUM(F$9:$F27) -> 5535000
G28: =SUM(E$9:$E28)-SUM(F$9:$F28) -> 5535000
G29: =SUM(E$9:$E29)-SUM(F$9:$F29) -> 5535000
G30: =SUM(E$9:$E30)-SUM(F$9:$F30) -> 5535000
G31: =SUM(E$9:$E31)-SUM(F$9:$F31) -> 5535000
G32: =SUM(E$9:$E32)-SUM(F$9:$F32) -> 5535000
G33: =SUM(E$9:$E33)-SUM(F$9:$F33) -> 5535000
G34: =SUM(E$9:$E34)-SUM(F$9:$F34) -> 5535000
G35: =SUM(E$9:$E35)-SUM(F$9:$F35) -> 5535000
... G102: =SUM(E$9:$E102)-SUM(F$9:$F102) -> 5535000
E103: =+$I$2+(GEDIS[[#This Row],[QUANTITE]]*GEDIS[[#This Row],[PRIX UNITAIRE]]) -> 0 | G103: =SUM(E$9:$E103)-SUM(F$9:$F103) -> 5535000
E104: =+$I$2+(GEDIS[[#This Row],[QUANTITE]]*GEDIS[[#This Row],[PRIX UNITAIRE]]) -> 0 | G104: =SUM(E$9:$E104)-SUM(F$9:$F104) -> 5535000
E105: =+$I$2+(GEDIS[[#This Row],[QUANTITE]]*GEDIS[[#This Row],[PRIX UNITAIRE]]) -> 0 | G105: =SUM(E$9:$E105)-SUM(F$9:$F105) -> 5535000
E106: =+$I$2+(GEDIS[[#This Row],[QUANTITE]]*GEDIS[[#This Row],[PRIX UNITAIRE]]) -> 0 | G106: =SUM(E$9:$E106)-SUM(F$9:$F106) -> 5535000
E107: =+$I$2+(GEDIS[[#This Row],[QUANTITE]]*GEDIS[[#This Row],[PRIX UNITAIRE]]) -> 0 | G107: =SUM(E$9:$E107)-SUM(F$9:$F107) -> 5535000
E108: =+$I$2+(GEDIS[[#This Row],[QUANTITE]]*GEDIS[[#This Row],[PRIX UNITAIRE]]) -> 0 | G108: =SUM(E$9:$E108)-SUM(F$9:$F108) -> 5535000
E109: =+$I$2+(GEDIS[[#This Row],[QUANTITE]]*GEDIS[[#This Row],[PRIX UNITAIRE]]) -> 0 | G109: =SUM(E$9:$E109)-SUM(F$9:$F109) -> 5535000
...

Sheet MOHAMED ZALZALE
I2: 0
D3: ANNEE | E3: CHIFFRE AFFAIRE | F3: TOTAL VERSEMENT | G3: SOLDE
D4: BILAN | E4: =+SUM(MOHAMEDZALZALE[TOTAL MONTANT]) -> 169171000 | F4: =+SUM(MOHAMEDZALZALE[VERSEMENT]) -> 0 | G4: =+E4-F4 -> 169171000
B5: NOM CLIENT
B6: MOHAMED ZALZALE
A8: DATE | B8: DESIGNATION | C8: QUANTITE | D8: PRIX UNITAIRE | E8: TOTAL MONTANT | F8: VERSEMENT | G8: SOLDE
A9: 46069 | B9: SOLDE DEPART | C9: 1 | D9: 169171000 | E9: 169171000 | G9: =+SUM(E$9:$E9)-SUM(F$9:$F9) -> 169171000
G10: =+SUM(E$9:$E10)-SUM(F$9:$F10) -> 169171000
G11: =+SUM(E$9:$E11)-SUM(F$9:$F11) -> 169171000
G12: =+SUM(E$9:$E12)-SUM(F$9:$F12) -> 169171000
G13: =+SUM(E$9:$E13)-SUM(F$9:$F13) -> 169171000
G14: =+SUM(E$9:$E14)-SUM(F$9:$F14) -> 169171000
G15: =+SUM(E$9:$E15)-SUM(F$9:$F15) -> 169171000
G16: =+SUM(E$9:$E16)-SUM(F$9:$F16) -> 169171000
G17: =+SUM(E$9:$E17)-SUM(F$9:$F17) -> 169171000
G18: =+SUM(E$9:$E18)-SUM(F$9:$F18) -> 169171000
G19: =+SUM(E$9:$E19)-SUM(F$9:$F19) -> 169171000
G20: =+SUM(E$9:$E20)-SUM(F$9:$F20) -> 169171000
G21: =+SUM(E$9:$E21)-SUM(F$9:$F21) -> 169171000
... G268: =+SUM(E$9:$E268)-SUM(F$9:$F268) -> 169171000
E269: =+$I$2+(MOHAMEDZALZALE[[#This Row],[QUANTITE]]*MOHAMEDZALZALE[[#This Row],[PRIX UNITAIRE]]) -> 0 | G269: =+SUM(E$9:$E269)-SUM(F$9:$F269) -> 169171000
E270: =+$I$2+(MOHAMEDZALZALE[[#This Row],[QUANTITE]]*MOHAMEDZALZALE[[#This Row],[PRIX UNITAIRE]]) -> 0 | G270: =+SUM(E$9:$E270)-SUM(F$9:$F270) -> 169171000
E271: =+$I$2+(MOHAMEDZALZALE[[#This Row],[QUANTITE]]*MOHAMEDZALZALE[[#This Row],[PRIX UNITAIRE]]) -> 0 | G271: =+SUM(E$9:$E271)-SUM(F$9:$F271) -> 169171000
E272: =+$I$2+(MOHAMEDZALZALE[[#This Row],[QUANTITE]]*MOHAMEDZALZALE[[#This Row],[PRIX UNITAIRE]]) -> 0 | G272: =+SUM(E$9:$E272)-SUM(F$9:$F272) -> 169171000
E273: =+$I$2+(MOHAMEDZALZALE[[#This Row],[QUANTITE]]*MOHAMEDZALZALE[[#This Row],[PRIX UNITAIRE]]) -> 0 | G273: =+SUM(E$9:$E273)-SUM(F$9:$F273) -> 169171000
E274: =+$I$2+(MOHAMEDZALZALE[[#This Row],[QUANTITE]]*MOHAMEDZALZALE[[#This Row],[PRIX UNITAIRE]]) -> 0 | G274: =+SUM(E$9:$E274)-SUM(F$9:$F274) -> 169171000
E275: =+$I$2+(MOHAMEDZALZALE[[#This Row],[QUANTITE]]*MOHAMEDZALZALE[[#This Row],[PRIX UNITAIRE]]) -> 0 | G275: =+SUM(E$9:$E275)-SUM(F$9:$F275) -> 169171000
E276: =+$I$2+(MOHAMEDZALZALE[[#This Row],[QUANTITE]]*MOHAMEDZALZALE[[#This Row],[PRIX UNITAIRE]]) -> 0 | G276: =+SUM(E$9:$E276)-SUM(F$9:$F276) -> 169171000
E277: =+$I$2+(MOHAMEDZALZALE[[#This Row],[QUANTITE]]*MOHAMEDZALZALE[[#This Row],[PRIX UNITAIRE]]) -> 0 | G277: =+SUM(E$9:$E277)-SUM(F$9:$F277) -> 169171000
E278: =+$I$2+(MOHAMEDZALZALE[[#This Row],[QUANTITE]]*MOHAMEDZALZALE[[#This Row],[PRIX UNITAIRE]]) -> 0 | G278: =+SUM(E$9:$E278)-SUM(F$9:$F278) -> 169171000

Sheet AUTO ROY 
I2: 0
D3: ANNEE | E3: CHIFFRE AFFAIRE | F3: TOTAL VERSEMENT | G3: SOLDE
D4: BILAN | E4: =+SUM(AUTOROY[TOTAL MONTANT]) -> 195000 | F4: =+SUM(AUTOROY[VERSEMENT]) -> 195000 | G4: =+E4-F4 -> 0
B5: NOM CLIENT
B6: AUTO ROY
A8: DATE | B8: DESIGNATION | C8: QUANTITE | D8: PRIX UNITAIRE | E8: TOTAL MONTANT | F8: VERSEMENT | G8: SOLDE
A9: 46069 | B9: SOLDE DEPART | C9: 1 | D9: 195000 | E9: 195000 | F9: 0 | G9: =+SUM(E$9:$E9)-SUM(F$9:$F9) -> 195000
A10: 46078 | B10: PAYE CACHE | C10: 0 | D10: 0 | E10: 0 | F10: 195000 | G10: =+SUM(E$9:$E10)-SUM(F$9:$F10) -> 0
E11: 0 | G11: =+SUM(E$9:$E11)-SUM(F$9:$F11) -> 0
E12: 0 | G12: =+SUM(E$9:$E12)-SUM(F$9:$F12) -> 0
E13: 0 | G13: =+SUM(E$9:$E13)-SUM(F$9:$F13) -> 0
E14: 0 | G14: =+SUM(E$9:$E14)-SUM(F$9:$F14) -> 0
E15: 0 | G15: =+SUM(E$9:$E15)-SUM(F$9:$F15) -> 0
E16: 0 | G16: =+SUM(E$9:$E16)-SUM(F$9:$F16) -> 0
E17: 0 | G17: =+SUM(E$9:$E17)-SUM(F$9:$F17) -> 0
E18: 0 | G18: =+SUM(E$9:$E18)-SUM(F$9:$F18) -> 0
E19: 0 | G19: =+SUM(E$9:$E19)-SUM(F$9:$F19) -> 0
E20: 0 | G20: =+SUM(E$9:$E20)-SUM(F$9:$F20) -> 0
E21: =+$I$2+(AUTOROY[[#This Row],[QUANTITE]]*AUTOROY[[#This Row],[PRIX UNITAIRE]]) -> 0 | G21: =+SUM(E$9:$E21)-SUM(F$9:$F21) -> 0
E22: =+$I$2+(AUTOROY[[#This Row],[QUANTITE]]*AUTOROY[[#This Row],[PRIX UNITAIRE]]) -> 0 | G22: =+SUM(E$9:$E22)-SUM(F$9:$F22) -> 0
E23: =+$I$2+(AUTOROY[[#This Row],[QUANTITE]]*AUTOROY[[#This Row],[PRIX UNITAIRE]]) -> 0 | G23: =+SUM(E$9:$E23)-SUM(F$9:$F23) -> 0
E24: =+$I$2+(AUTOROY[[#This Row],[QUANTITE]]*AUTOROY[[#This Row],[PRIX UNITAIRE]]) -> 0 | G24: =+SUM(E$9:$E24)-SUM(F$9:$F24) -> 0
E25: =+$I$2+(AUTOROY[[#This Row],[QUANTITE]]*AUTOROY[[#This Row],[PRIX UNITAIRE]]) -> 0 | G25: =+SUM(E$9:$E25)-SUM(F$9:$F25) -> 0
E26: =+$I$2+(AUTOROY[[#This Row],[QUANTITE]]*AUTOROY[[#This Row],[PRIX UNITAIRE]]) -> 0 | G26: =+SUM(E$9:$E26)-SUM(F$9:$F26) -> 0
E27: =+$I$2+(AUTOROY[[#This Row],[QUANTITE]]*AUTOROY[[#This Row],[PRIX UNITAIRE]]) -> 0 | G27: =+SUM(E$9:$E27)-SUM(F$9:$F27) -> 0
E28: =+$I$2+(AUTOROY[[#This Row],[QUANTITE]]*AUTOROY[[#This Row],[PRIX UNITAIRE]]) -> 0 | G28: =+SUM(E$9:$E28)-SUM(F$9:$F28) -> 0
E29: =+$I$2+(AUTOROY[[#This Row],[QUANTITE]]*AUTOROY[[#This Row],[PRIX UNITAIRE]]) -> 0 | G29: =+SUM(E$9:$E29)-SUM(F$9:$F29) -> 0
E30: =+$I$2+(AUTOROY[[#This Row],[QUANTITE]]*AUTOROY[[#This Row],[PRIX UNITAIRE]]) -> 0 | G30: =+SUM(E$9:$E30)-SUM(F$9:$F30) -> 0
E31: =+$I$2+(AUTOROY[[#This Row],[QUANTITE]]*AUTOROY[[#This Row],[PRIX UNITAIRE]]) -> 0 | G31: =+SUM(E$9:$E31)-SUM(F$9:$F31) -> 0
E32: =+$I$2+(AUTOROY[[#This Row],[QUANTITE]]*AUTOROY[[#This Row],[PRIX UNITAIRE]]) -> 0 | G32: =+SUM(E$9:$E32)-SUM(F$9:$F32) -> 0
... E57: =+$I$2+(AUTOROY[[#This Row],[QUANTITE]]*AUTOROY[[#This Row],[PRIX UNITAIRE]]) -> 0 | G57: =+SUM(E$9:$E57)-SUM(F$9:$F57) -> 0

Sheet DUNLOP
I1: 0
D3: ANNEE | E3: CHIFFRE AFFAIRE | F3: TOTAL VERSEMENT | G3: SOLDE
D4: BILAN | E4: =+SUM(DUNLOP[TOTAL MONTANT]) -> 16947660 | F4: =+SUM(DUNLOP[VERSEMENT]) -> 5000000 | G4: =+E4-F4 -> 11947660
B5: NOM CLIENT
B6: DUNLOP
A8: DATE | B8: DESIGNATION | C8: QUANTITE | D8: PRIX UNITAIRE | E8: TOTAL MONTANT | F8: VERSEMENT | G8: SOLDE
A9: 46069 | B9: SOLDE DEPART | C9: 1 | D9: 16947660 | E9: 16947660 | F9: 0 | G9: =SUM(E$9:$E9)-SUM(F$9:$F9) -> 16947660
A10: 46092 | B10: VERSEMENT | C10: 1 | D10: 0 | E10: 0 | F10: 5000000 | G10: =SUM(E$9:$E10)-SUM(F$9:$F10) -> 11947660
G11: =SUM(E$9:$E11)-SUM(F$9:$F11) -> 11947660
G12: =SUM(E$9:$E12)-SUM(F$9:$F12) -> 11947660
G13: =SUM(E$9:$E13)-SUM(F$9:$F13) -> 11947660
G14: =SUM(E$9:$E14)-SUM(F$9:$F14) -> 11947660
G15: =SUM(E$9:$E15)-SUM(F$9:$F15) -> 11947660
G16: =SUM(E$9:$E16)-SUM(F$9:$F16) -> 11947660
G17: =SUM(E$9:$E17)-SUM(F$9:$F17) -> 11947660
G18: =SUM(E$9:$E18)-SUM(F$9:$F18) -> 11947660
G19: =SUM(E$9:$E19)-SUM(F$9:$F19) -> 11947660
G20: =SUM(E$9:$E20)-SUM(F$9:$F20) -> 11947660
G21: =SUM(E$9:$E21)-SUM(F$9:$F21) -> 11947660
G22: =SUM(E$9:$E22)-SUM(F$9:$F22) -> 11947660
... G71: =SUM(E$9:$E71)-SUM(F$9:$F71) -> 11947660

Sheet NABILCO
I2: 0
D3: ANNEE | E3: CHIFFRE AFFAIRE | F3: TOTAL VERSEMENT | G3: SOLDE
D4: BILAN | E4: =+SUM(NABILCO[TOTAL MONTANT]) -> 4461000 | F4: =+SUM(NABILCO[VERSEMENT]) -> 1846000 | G4: =+E4-F4 -> 2615000
B5: NOM CLIENT
B6: NABILCO
A8: DATE | B8: DESIGNATION | C8: QUANTITE | D8: PRIX UNITAIRE | E8: TOTAL MONTANT | F8: VERSEMENT | G8: SOLDE
A9: 46069 | B9: SOLDE DEPART | C9: 1 | D9: 3318500 | E9: 3318500 | F9: 0 | G9: =+SUM(E$9:$E9)-SUM(F$9:$F9) -> 3318500
A10: 46071 | B10: HUILE BOITE SAE 75W90 1L WOLVER | C10: 3 | D10: 7500 | E10: 22500 | F10: 0 | G10: =+SUM(E$9:$E10)-SUM(F$9:$F10) -> 3341000
A11: 46076 | B11: CAPTEUR DE TEMPERATURE EXTERNE MERCEDES | C11: 1 | D11: 10000 | E11: 10000 | F11: 0 | G11: =+SUM(E$9:$E11)-SUM(F$9:$F11) -> 3351000
A12: 46078 | B12: MOYEUX AVANT L200 | C12: 2 | D12: 35000 | E12: 70000 | F12: 0 | G12: =+SUM(E$9:$E12)-SUM(F$9:$F12) -> 3421000
A13: 46078 | B13: ROULEMENT AR L200 | C13: 2 | D13: 22500 | E13: 45000 | F13: 0 | G13: =+SUM(E$9:$E13)-SUM(F$9:$F13) -> 3466000
A14: 46080 | B14: BOBINE ALLUMAGE AVENSIS | C14: 2 | D14: 20000 | E14: 40000 | F14: 0 | G14: =+SUM(E$9:$E14)-SUM(F$9:$F14) -> 3506000
A15: 46080 | B15: CAPTEUR ABS AV AVENSIS | C15: 1 | D15: 20000 | E15: 20000 | F15: 0 | G15: =+SUM(E$9:$E15)-SUM(F$9:$F15) -> 3526000
A16: 46083 | B16: HUILE DE BOITE SAE 75W90 1L WOLVER MULTIPURPOSE GEAR | C16: 2 | D16: 7500 | E16: 15000 | F16: 0 | G16: =+SUM(E$9:$E16)-SUM(F$9:$F16) -> 3541000
A17: 46086 | B17: VENTILATEUR MERCEDES W213 SENAT (E200) | C17: 1 | D17: 300000 | E17: 300000 | F17: 0 | G17: =+SUM(E$9:$E17)-SUM(F$9:$F17) -> 3841000
A18: 46087 | B18: filtre a huile bt50 | C18: 1 | D18: 5000 | E18: 5000 | F18: 0 | G18: =+SUM(E$9:$E18)-SUM(F$9:$F18) -> 3846000
A19: 46088 | B19: VER5SEMENT | C19: 1 | D19: 0 | E19: 0 | F19: 1846000 | G19: =+SUM(E$9:$E19)-SUM(F$9:$F19) -> 2000000
A20: 46090 | B20: DISQUE DE FREIN AV MERCEDES E200 | C20: 2 | D20: 65000 | E20: 130000 | F20: 0 | G20: =+SUM(E$9:$E20)-SUM(F$9:$F20) -> 2130000
... A29: 46099 | B29: FERMETURE RADIATEUR | C29: 1 | D29: 5000 | E29: 5000 | F29: 0 | G29: =+SUM(E$9:$E29)-SUM(F$9:$F29) -> 2615000
G30: =+SUM(E$9:$E30)-SUM(F$9:$F30) -> 2615000
G31: =+SUM(E$9:$E31)-SUM(F$9:$F31) -> 2615000
G32: =+SUM(E$9:$E32)-SUM(F$9:$F32) -> 2615000
G33: =+SUM(E$9:$E33)-SUM(F$9:$F33) -> 2615000
G34: =+SUM(E$9:$E34)-SUM(F$9:$F34) -> 2615000
G35: =+SUM(E$9:$E35)-SUM(F$9:$F35) -> 2615000
G36: =+SUM(E$9:$E36)-SUM(F$9:$F36) -> 2615000
G37: =+SUM(E$9:$E37)-SUM(F$9:$F37) -> 2615000
G38: =+SUM(E$9:$E38)-SUM(F$9:$F38) -> 2615000
G39: =+SUM(E$9:$E39)-SUM(F$9:$F39) -> 2615000
G40: =+SUM(E$9:$E40)-SUM(F$9:$F40) -> 2615000
G41: =+SUM(E$9:$E41)-SUM(F$9:$F41) -> 2615000
... G72: =+SUM(E$9:$E72)-SUM(F$9:$F72) -> 2615000

Sheet KABALANE
I2: 0
D3: ANNEE | E3: CHIFFRE AFFAIRE | F3: TOTAL VERSEMENT | G3: SOLDE
D4: BILAN | E4: =+SUM(KABALANE[TOTAL MONTANT]) -> 2689649 | F4: =+SUM(KABALANE[VERSEMENT]) -> 0 | G4: =+E4-F4 -> 2689649
B5: NOM CLIENT
B6: KABALANE
A8: DATE | B8: DESIGNATION | C8: QUANTITE | D8: PRIX UNITAIRE | E8: TOTAL MONTANT | F8: VERSEMENT | G8: SOLDE
A9: 46069 | B9: SOLDE DEPART | C9: 1 | D9: 2689649 | E9: =+$I$2+(KABALANE[[#This Row],[QUANTITE]]*KABALANE[[#This Row],[PRIX UNITAIRE]]) -> 2689649 | G9: =+SUM(E$9:$E9)-SUM(F$9:$F9) -> 2689649
E10: =+$I$2+(KABALANE[[#This Row],[QUANTITE]]*KABALANE[[#This Row],[PRIX UNITAIRE]]) -> 0 | G10: =+SUM(E$9:$E10)-SUM(F$9:$F10) -> 2689649
E11: =+$I$2+(KABALANE[[#This Row],[QUANTITE]]*KABALANE[[#This Row],[PRIX UNITAIRE]]) -> 0 | G11: =+SUM(E$9:$E11)-SUM(F$9:$F11) -> 2689649
E12: =+$I$2+(KABALANE[[#This Row],[QUANTITE]]*KABALANE[[#This Row],[PRIX UNITAIRE]]) -> 0 | G12: =+SUM(E$9:$E12)-SUM(F$9:$F12) -> 2689649
E13: =+$I$2+(KABALANE[[#This Row],[QUANTITE]]*KABALANE[[#This Row],[PRIX UNITAIRE]]) -> 0 | G13: =+SUM(E$9:$E13)-SUM(F$9:$F13) -> 2689649
E14: =+$I$2+(KABALANE[[#This Row],[QUANTITE]]*KABALANE[[#This Row],[PRIX UNITAIRE]]) -> 0 | G14: =+SUM(E$9:$E14)-SUM(F$9:$F14) -> 2689649
E15: =+$I$2+(KABALANE[[#This Row],[QUANTITE]]*KABALANE[[#This Row],[PRIX UNITAIRE]]) -> 0 | G15: =+SUM(E$9:$E15)-SUM(F$9:$F15) -> 2689649
E16: =+$I$2+(KABALANE[[#This Row],[QUANTITE]]*KABALANE[[#This Row],[PRIX UNITAIRE]]) -> 0 | G16: =+SUM(E$9:$E16)-SUM(F$9:$F16) -> 2689649
E17: =+$I$2+(KABALANE[[#This Row],[QUANTITE]]*KABALANE[[#This Row],[PRIX UNITAIRE]]) -> 0 | G17: =+SUM(E$9:$E17)-SUM(F$9:$F17) -> 2689649
E18: =+$I$2+(KABALANE[[#This Row],[QUANTITE]]*KABALANE[[#This Row],[PRIX UNITAIRE]]) -> 0 | G18: =+SUM(E$9:$E18)-SUM(F$9:$F18) -> 2689649
E19: =+$I$2+(KABALANE[[#This Row],[QUANTITE]]*KABALANE[[#This Row],[PRIX UNITAIRE]]) -> 0 | G19: =+SUM(E$9:$E19)-SUM(F$9:$F19) -> 2689649
E20: =+$I$2+(KABALANE[[#This Row],[QUANTITE]]*KABALANE[[#This Row],[PRIX UNITAIRE]]) -> 0 | G20: =+SUM(E$9:$E20)-SUM(F$9:$F20) -> 2689649
E21: =+$I$2+(KABALANE[[#This Row],[QUANTITE]]*KABALANE[[#This Row],[PRIX UNITAIRE]]) -> 0 | G21: =+SUM(E$9:$E21)-SUM(F$9:$F21) -> 2689649
... E290: =+$I$2+(KABALANE[[#This Row],[QUANTITE]]*KABALANE[[#This Row],[PRIX UNITAIRE]]) -> 0 | G290: =+SUM(E$9:$E290)-SUM(F$9:$F290) -> 2689649
C291: 0 | D291: 0 | E291: 0 | G291: =+SUM(E$9:$E291)-SUM(F$9:$F291) -> 2689649

Sheet ABASS BOUGI
I2: 0
D3: ANNEE | E3: CHIFFRE AFFAIRE | F3: TOTAL VERSEMENT | G3: SOLDE
D4: BILAN | E4: =+SUM(ABASSBOUGI[TOTAL MONTANT]) -> 275000 | F4: =+SUM(ABASSBOUGI[VERSEMENT]) -> 200000 | G4: =+E4-F4 -> 75000
B5: NOM CLIENT
B6: ABASS BOUGI
A8: DATE | B8: DESIGNATION | C8: QUANTITE | D8: PRIX UNITAIRE | E8: TOTAL MONTANT | F8: VERSEMENT | G8: SOLDE
A9: 46069 | B9: SOLDE DEPART | C9: 1 | D9: 275000 | E9: =+$I$2+(ABASSBOUGI[[#This Row],[QUANTITE]]*ABASSBOUGI[[#This Row],[PRIX UNITAIRE]]) -> 275000 | F9: 0 | G9: =+SUM(E$9:$E9)-SUM(F$9:$F9) -> 275000
A10: 46095 | B10: versement | C10: 1 | D10: 0 | E10: =+$I$2+(ABASSBOUGI[[#This Row],[QUANTITE]]*ABASSBOUGI[[#This Row],[PRIX UNITAIRE]]) -> 0 | F10: 200000 | G10: =+SUM(E$9:$E10)-SUM(F$9:$F10) -> 75000
E11: =+$I$2+(ABASSBOUGI[[#This Row],[QUANTITE]]*ABASSBOUGI[[#This Row],[PRIX UNITAIRE]]) -> 0 | G11: =+SUM(E$9:$E11)-SUM(F$9:$F11) -> 75000
E12: =+$I$2+(ABASSBOUGI[[#This Row],[QUANTITE]]*ABASSBOUGI[[#This Row],[PRIX UNITAIRE]]) -> 0 | G12: =+SUM(E$9:$E12)-SUM(F$9:$F12) -> 75000
E13: =+$I$2+(ABASSBOUGI[[#This Row],[QUANTITE]]*ABASSBOUGI[[#This Row],[PRIX UNITAIRE]]) -> 0 | G13: =+SUM(E$9:$E13)-SUM(F$9:$F13) -> 75000
E14: =+$I$2+(ABASSBOUGI[[#This Row],[QUANTITE]]*ABASSBOUGI[[#This Row],[PRIX UNITAIRE]]) -> 0 | G14: =+SUM(E$9:$E14)-SUM(F$9:$F14) -> 75000
E15: =+$I$2+(ABASSBOUGI[[#This Row],[QUANTITE]]*ABASSBOUGI[[#This Row],[PRIX UNITAIRE]]) -> 0 | G15: =+SUM(E$9:$E15)-SUM(F$9:$F15) -> 75000
E16: =+$I$2+(ABASSBOUGI[[#This Row],[QUANTITE]]*ABASSBOUGI[[#This Row],[PRIX UNITAIRE]]) -> 0 | G16: =+SUM(E$9:$E16)-SUM(F$9:$F16) -> 75000
E17: =+$I$2+(ABASSBOUGI[[#This Row],[QUANTITE]]*ABASSBOUGI[[#This Row],[PRIX UNITAIRE]]) -> 0 | G17: =+SUM(E$9:$E17)-SUM(F$9:$F17) -> 75000
E18: =+$I$2+(ABASSBOUGI[[#This Row],[QUANTITE]]*ABASSBOUGI[[#This Row],[PRIX UNITAIRE]]) -> 0 | G18: =+SUM(E$9:$E18)-SUM(F$9:$F18) -> 75000
E19: =+$I$2+(ABASSBOUGI[[#This Row],[QUANTITE]]*ABASSBOUGI[[#This Row],[PRIX UNITAIRE]]) -> 0 | G19: =+SUM(E$9:$E19)-SUM(F$9:$F19) -> 75000
E20: =+$I$2+(ABASSBOUGI[[#This Row],[QUANTITE]]*ABASSBOUGI[[#This Row],[PRIX UNITAIRE]]) -> 0 | G20: =+SUM(E$9:$E20)-SUM(F$9:$F20) -> 75000
E21: =+$I$2+(ABASSBOUGI[[#This Row],[QUANTITE]]*ABASSBOUGI[[#This Row],[PRIX UNITAIRE]]) -> 0 | G21: =+SUM(E$9:$E21)-SUM(F$9:$F21) -> 75000
E22: =+$I$2+(ABASSBOUGI[[#This Row],[QUANTITE]]*ABASSBOUGI[[#This Row],[PRIX UNITAIRE]]) -> 0 | G22: =+SUM(E$9:$E22)-SUM(F$9:$F22) -> 75000
... E71: =+$I$2+(ABASSBOUGI[[#This Row],[QUANTITE]]*ABASSBOUGI[[#This Row],[PRIX UNITAIRE]]) -> 0 | G71: =+SUM(E$9:$E71)-SUM(F$9:$F71) -> 75000

Sheet DIVERS
I2: 0
D3: ANNEE | E3: CHIFFRE AFFAIRE | F3: TOTAL VERSEMENT | G3: SOLDE
D4: BILAN | E4: =+SUM(DIVERSFOURNISSEUR[TOTAL MONTANT]) -> 0 | F4: =+SUM(DIVERSFOURNISSEUR[VERSEMENT]) -> 0 | G4: =+E4-F4 -> 0
B5: NOM CLIENT
B6: DIVERS FOURNISSEURS
A8: DATE | B8: NOM FOURNISSEUR | C8: DESIGNATION | D8: QUANTITE | E8: PRIX UNITAIRE | F8: TOTAL MONTANT | G8: VERSEMENT | H8: SOLDE
F9: =+$I$2+(DIVERSFOURNISSEUR[[#This Row],[QUANTITE]]*DIVERSFOURNISSEUR[[#This Row],[PRIX UNITAIRE]]) -> 0 | H9: =+SUM($F$9:F9)-SUM($G$9:G9) -> 0
F10: =+$I$2+(DIVERSFOURNISSEUR[[#This Row],[QUANTITE]]*DIVERSFOURNISSEUR[[#This Row],[PRIX UNITAIRE]]) -> 0 | H10: =+SUM($F$9:F10)-SUM($G$9:G10) -> 0
F11: =+$I$2+(DIVERSFOURNISSEUR[[#This Row],[QUANTITE]]*DIVERSFOURNISSEUR[[#This Row],[PRIX UNITAIRE]]) -> 0 | H11: =+SUM($F$9:F11)-SUM($G$9:G11) -> 0
F12: =+$I$2+(DIVERSFOURNISSEUR[[#This Row],[QUANTITE]]*DIVERSFOURNISSEUR[[#This Row],[PRIX UNITAIRE]]) -> 0 | H12: =+SUM($F$9:F12)-SUM($G$9:G12) -> 0
F13: =+$I$2+(DIVERSFOURNISSEUR[[#This Row],[QUANTITE]]*DIVERSFOURNISSEUR[[#This Row],[PRIX UNITAIRE]]) -> 0 | H13: =+SUM($F$9:F13)-SUM($G$9:G13) -> 0
F14: =+$I$2+(DIVERSFOURNISSEUR[[#This Row],[QUANTITE]]*DIVERSFOURNISSEUR[[#This Row],[PRIX UNITAIRE]]) -> 0 | H14: =+SUM($F$9:F14)-SUM($G$9:G14) -> 0
F15: =+$I$2+(DIVERSFOURNISSEUR[[#This Row],[QUANTITE]]*DIVERSFOURNISSEUR[[#This Row],[PRIX UNITAIRE]]) -> 0 | H15: =+SUM($F$9:F15)-SUM($G$9:G15) -> 0
F16: =+$I$2+(DIVERSFOURNISSEUR[[#This Row],[QUANTITE]]*DIVERSFOURNISSEUR[[#This Row],[PRIX UNITAIRE]]) -> 0 | H16: =+SUM($F$9:F16)-SUM($G$9:G16) -> 0
F17: =+$I$2+(DIVERSFOURNISSEUR[[#This Row],[QUANTITE]]*DIVERSFOURNISSEUR[[#This Row],[PRIX UNITAIRE]]) -> 0 | H17: =+SUM($F$9:F17)-SUM($G$9:G17) -> 0
F18: =+$I$2+(DIVERSFOURNISSEUR[[#This Row],[QUANTITE]]*DIVERSFOURNISSEUR[[#This Row],[PRIX UNITAIRE]]) -> 0 | H18: =+SUM($F$9:F18)-SUM($G$9:G18) -> 0
F19: =+$I$2+(DIVERSFOURNISSEUR[[#This Row],[QUANTITE]]*DIVERSFOURNISSEUR[[#This Row],[PRIX UNITAIRE]]) -> 0 | H19: =+SUM($F$9:F19)-SUM($G$9:G19) -> 0
F20: =+$I$2+(DIVERSFOURNISSEUR[[#This Row],[QUANTITE]]*DIVERSFOURNISSEUR[[#This Row],[PRIX UNITAIRE]]) -> 0 | H20: =+SUM($F$9:F20)-SUM($G$9:G20) -> 0
... F69: =+$I$2+(DIVERSFOURNISSEUR[[#This Row],[QUANTITE]]*DIVERSFOURNISSEUR[[#This Row],[PRIX UNITAIRE]]) -> 0 | H69: =+SUM($F$9:F69)-SUM($G$9:G69) -> 0

Sheet ROULEMENT MONDIAL
I2: 0
D3: ANNEE | E3: CHIFFRE AFFAIRE | F3: TOTAL VERSEMENT | G3: SOLDE
D4: BILAN | E4: =+SUM(ROULEMENTMONDIAL[TOTAL MONTANT]) -> 291285.56 | F4: =+SUM(ROULEMENTMONDIAL[VERSEMENT]) -> 285000 | G4: =+E4-F4 -> 6285.56
B5: NOM CLIENT
B6: ROULEMENT MONDIAL | E6: FALSE
A8: DATE | B8: DESIGNATION | C8: QUANTITE | D8: PRIX UNITAIRE | E8: TOTAL MONTANT | F8: VERSEMENT | G8: SOLDE
A9: 46062 | B9: BOUGIES | C9: 5 | D9: 10884 | E9: 54420 | F9: 0 | G9: =+SUM(E$9:$E9)-SUM(F$9:$F9) -> 54420
A10: 45414 | B10: COURROIE B109 | C10: 4 | D10: 9310 | E10: 37240 | F10: 0 | G10: =+SUM(E$9:$E10)-SUM(F$9:$F10) -> 91660
A11: 45450 | B11: COURROIE B112 | C11: 4 | D11: 9581 | E11: 38324 | F11: 0 | G11: =+SUM(E$9:$E11)-SUM(F$9:$F11) -> 129984
A12: 45516 | B12: 7PK1030 | C12: 1 | D12: 7766 | E12: 7766 | F12: 0 | G12: =+SUM(E$9:$E12)-SUM(F$9:$F12) -> 137750
A13: 45550 | B13: ROULEMENT 30211 TIMKEN | C13: 4 | D13: 18736 | E13: 74944 | F13: 0 | G13: =+SUM(E$9:$E13)-SUM(F$9:$F13) -> 212694
A14: 46094 | B14: PLAQUETTE DE FREIN NISHIMBO NP3008 | C14: 2 | D14: 17146.53 | E14: 34293.06 | F14: 0 | G14: =+SUM(E$9:$E14)-SUM(F$9:$F14) -> 246987.06
A15: 46094 | B15: PLAQUETTE DE FREIN TRW GDB3239AT | C15: 3 | D15: 12599.5 | E15: 37798.5 | F15: 0 | G15: =+SUM(E$9:$E15)-SUM(F$9:$F15) -> 284785.56
A16: 46095 | B16: VERSEMENT | C16: 1 | D16: 0 | E16: 0 | F16: 285000 | G16: =+SUM(E$9:$E16)-SUM(F$9:$F16) -> -214.44
A17: 46100 | B17: 6PK1203 | C17: 1 | D17: 6500 | E17: =+$I$2+(ROULEMENTMONDIAL[[#This Row],[QUANTITE]]*ROULEMENTMONDIAL[[#This Row],[PRIX UNITAIRE]]) -> 6500 | G17: =+SUM(E$9:$E17)-SUM(F$9:$F17) -> 6285.56
E18: =+$I$2+(ROULEMENTMONDIAL[[#This Row],[QUANTITE]]*ROULEMENTMONDIAL[[#This Row],[PRIX UNITAIRE]]) -> 0 | G18: =+SUM(E$9:$E18)-SUM(F$9:$F18) -> 6285.56
E19: =+$I$2+(ROULEMENTMONDIAL[[#This Row],[QUANTITE]]*ROULEMENTMONDIAL[[#This Row],[PRIX UNITAIRE]]) -> 0 | G19: =+SUM(E$9:$E19)-SUM(F$9:$F19) -> 6285.56
E20: =+$I$2+(ROULEMENTMONDIAL[[#This Row],[QUANTITE]]*ROULEMENTMONDIAL[[#This Row],[PRIX UNITAIRE]]) -> 0 | G20: =+SUM(E$9:$E20)-SUM(F$9:$F20) -> 6285.56
E21: =+$I$2+(ROULEMENTMONDIAL[[#This Row],[QUANTITE]]*ROULEMENTMONDIAL[[#This Row],[PRIX UNITAIRE]]) -> 0 | G21: =+SUM(E$9:$E21)-SUM(F$9:$F21) -> 6285.56
E22: =+$I$2+(ROULEMENTMONDIAL[[#This Row],[QUANTITE]]*ROULEMENTMONDIAL[[#This Row],[PRIX UNITAIRE]]) -> 0 | G22: =+SUM(E$9:$E22)-SUM(F$9:$F22) -> 6285.56
E23: =+$I$2+(ROULEMENTMONDIAL[[#This Row],[QUANTITE]]*ROULEMENTMONDIAL[[#This Row],[PRIX UNITAIRE]]) -> 0 | G23: =+SUM(E$9:$E23)-SUM(F$9:$F23) -> 6285.56
E24: =+$I$2+(ROULEMENTMONDIAL[[#This Row],[QUANTITE]]*ROULEMENTMONDIAL[[#This Row],[PRIX UNITAIRE]]) -> 0 | G24: =+SUM(E$9:$E24)-SUM(F$9:$F24) -> 6285.56
E25: =+$I$2+(ROULEMENTMONDIAL[[#This Row],[QUANTITE]]*ROULEMENTMONDIAL[[#This Row],[PRIX UNITAIRE]]) -> 0 | G25: =+SUM(E$9:$E25)-SUM(F$9:$F25) -> 6285.56
E26: =+$I$2+(ROULEMENTMONDIAL[[#This Row],[QUANTITE]]*ROULEMENTMONDIAL[[#This Row],[PRIX UNITAIRE]]) -> 0 | G26: =+SUM(E$9:$E26)-SUM(F$9:$F26) -> 6285.56
E27: =+$I$2+(ROULEMENTMONDIAL[[#This Row],[QUANTITE]]*ROULEMENTMONDIAL[[#This Row],[PRIX UNITAIRE]]) -> 0 | G27: =+SUM(E$9:$E27)-SUM(F$9:$F27) -> 6285.56
E28: =+$I$2+(ROULEMENTMONDIAL[[#This Row],[QUANTITE]]*ROULEMENTMONDIAL[[#This Row],[PRIX UNITAIRE]]) -> 0 | G28: =+SUM(E$9:$E28)-SUM(F$9:$F28) -> 6285.56
E29: =+$I$2+(ROULEMENTMONDIAL[[#This Row],[QUANTITE]]*ROULEMENTMONDIAL[[#This Row],[PRIX UNITAIRE]]) -> 0 | G29: =+SUM(E$9:$E29)-SUM(F$9:$F29) -> 6285.56
... E69: =+$I$2+(ROULEMENTMONDIAL[[#This Row],[QUANTITE]]*ROULEMENTMONDIAL[[#This Row],[PRIX UNITAIRE]]) -> 0 | G69: =+SUM(E$9:$E69)-SUM(F$9:$F69) -> 6285.56

Sheet CACOMIAF
I2: 0
D3: ANNEE | E3: CHIFFRE AFFAIRE | F3: TOTAL VERSEMENT | G3: SOLDE
D4: BILAN | E4: =+SUM(CACOMIAF[TOTAL MONTANT]) -> 0 | F4: =+SUM(CACOMIAF[VERSEMENT]) -> 0 | G4: =+E4-F4 -> 0
B5: NOM CLIENT
B6: CACOMIAF
A8: DATE | B8: DESIGNATION | C8: QUANTITE | D8: PRIX UNITAIRE | E8: TOTAL MONTANT | F8: VERSEMENT | G8: SOLDE
E9: =+$I$2+(CACOMIAF[[#This Row],[QUANTITE]]*CACOMIAF[[#This Row],[PRIX UNITAIRE]]) -> 0 | G9: =+SUM(E$9:$E9)-SUM(F$9:$F9) -> 0
E10: =+$I$2+(CACOMIAF[[#This Row],[QUANTITE]]*CACOMIAF[[#This Row],[PRIX UNITAIRE]]) -> 0 | G10: =+SUM(E$9:$E10)-SUM(F$9:$F10) -> 0
E11: =+$I$2+(CACOMIAF[[#This Row],[QUANTITE]]*CACOMIAF[[#This Row],[PRIX UNITAIRE]]) -> 0 | G11: =+SUM(E$9:$E11)-SUM(F$9:$F11) -> 0
E12: =+$I$2+(CACOMIAF[[#This Row],[QUANTITE]]*CACOMIAF[[#This Row],[PRIX UNITAIRE]]) -> 0 | G12: =+SUM(E$9:$E12)-SUM(F$9:$F12) -> 0
E13: =+$I$2+(CACOMIAF[[#This Row],[QUANTITE]]*CACOMIAF[[#This Row],[PRIX UNITAIRE]]) -> 0 | G13: =+SUM(E$9:$E13)-SUM(F$9:$F13) -> 0
E14: =+$I$2+(CACOMIAF[[#This Row],[QUANTITE]]*CACOMIAF[[#This Row],[PRIX UNITAIRE]]) -> 0 | G14: =+SUM(E$9:$E14)-SUM(F$9:$F14) -> 0
E15: =+$I$2+(CACOMIAF[[#This Row],[QUANTITE]]*CACOMIAF[[#This Row],[PRIX UNITAIRE]]) -> 0 | G15: =+SUM(E$9:$E15)-SUM(F$9:$F15) -> 0
E16: =+$I$2+(CACOMIAF[[#This Row],[QUANTITE]]*CACOMIAF[[#This Row],[PRIX UNITAIRE]]) -> 0 | G16: =+SUM(E$9:$E16)-SUM(F$9:$F16) -> 0
E17: =+$I$2+(CACOMIAF[[#This Row],[QUANTITE]]*CACOMIAF[[#This Row],[PRIX UNITAIRE]]) -> 0 | G17: =+SUM(E$9:$E17)-SUM(F$9:$F17) -> 0
E18: =+$I$2+(CACOMIAF[[#This Row],[QUANTITE]]*CACOMIAF[[#This Row],[PRIX UNITAIRE]]) -> 0 | G18: =+SUM(E$9:$E18)-SUM(F$9:$F18) -> 0
E19: =+$I$2+(CACOMIAF[[#This Row],[QUANTITE]]*CACOMIAF[[#This Row],[PRIX UNITAIRE]]) -> 0 | G19: =+SUM(E$9:$E19)-SUM(F$9:$F19) -> 0
E20: =+$I$2+(CACOMIAF[[#This Row],[QUANTITE]]*CACOMIAF[[#This Row],[PRIX UNITAIRE]]) -> 0 | G20: =+SUM(E$9:$E20)-SUM(F$9:$F20) -> 0
... E69: =+$I$2+(CACOMIAF[[#This Row],[QUANTITE]]*CACOMIAF[[#This Row],[PRIX UNITAIRE]]) -> 0 | G69: =+SUM(E$9:$E69)-SUM(F$9:$F69) -> 0

Sheet HASSAN KAFARANI
I2: 0
D3: ANNEE | E3: CHIFFRE AFFAIRE | F3: TOTAL VERSEMENT | G3: SOLDE
D4: BILAN | E4: =+SUM(HASSANKAFARANI[TOTAL MONTANT]) -> 5177500 | F4: =+SUM(HASSANKAFARANI[VERSEMENT]) -> 4977500 | G4: =+E4-F4 -> 200000
B5: NOM CLIENT
B6: HASSAN KAFARANI
A8: DATE | B8: DESIGNATION | C8: QUANTITE | D8: PRIX UNITAIRE | E8: TOTAL MONTANT | F8: VERSEMENT | G8: SOLDE
A9: 46073 | B9: POINT DE DEPART | C9: 1 | D9: 4687500 | E9: 4687500 | F9: 0 | G9: =+SUM(E$9:$E9)-SUM(F$9:$F9) -> 4687500
A10: 46074 | E10: 0 | F10: 1500000 | G10: =+SUM(E$9:$E10)-SUM(F$9:$F10) -> 3187500
A11: 46079 | B11: BATTERIE 150 AH NAVAL POWER | C11: 5 | D11: 58000 | E11: 290000 | F11: 0 | G11: =+SUM(E$9:$E11)-SUM(F$9:$F11) -> 3477500
A12: 46084 | B12: VERSEMENT | C12: 1 | E12: 0 | F12: 1477500 | G12: =+SUM(E$9:$E12)-SUM(F$9:$F12) -> 2000000
A13: 46085 | B13: APEX 10W40 (5L) | C13: 20 | D13: 10000 | E13: 200000 | F13: 0 | G13: =+SUM(E$9:$E13)-SUM(F$9:$F13) -> 2200000
A14: 46099 | B14: VERSEMENT | C14: 1 | E14: 0 | F14: 2000000 | G14: =+SUM(E$9:$E14)-SUM(F$9:$F14) -> 200000
E15: =+$I$2+(HASSANKAFARANI[[#This Row],[QUANTITE]]*HASSANKAFARANI[[#This Row],[PRIX UNITAIRE]]) -> 0 | G15: =+SUM(E$9:$E15)-SUM(F$9:$F15) -> 200000
E16: =+$I$2+(HASSANKAFARANI[[#This Row],[QUANTITE]]*HASSANKAFARANI[[#This Row],[PRIX UNITAIRE]]) -> 0 | G16: =+SUM(E$9:$E16)-SUM(F$9:$F16) -> 200000
E17: =+$I$2+(HASSANKAFARANI[[#This Row],[QUANTITE]]*HASSANKAFARANI[[#This Row],[PRIX UNITAIRE]]) -> 0 | G17: =+SUM(E$9:$E17)-SUM(F$9:$F17) -> 200000
E18: =+$I$2+(HASSANKAFARANI[[#This Row],[QUANTITE]]*HASSANKAFARANI[[#This Row],[PRIX UNITAIRE]]) -> 0 | G18: =+SUM(E$9:$E18)-SUM(F$9:$F18) -> 200000
E19: =+$I$2+(HASSANKAFARANI[[#This Row],[QUANTITE]]*HASSANKAFARANI[[#This Row],[PRIX UNITAIRE]]) -> 0 | G19: =+SUM(E$9:$E19)-SUM(F$9:$F19) -> 200000
E20: =+$I$2+(HASSANKAFARANI[[#This Row],[QUANTITE]]*HASSANKAFARANI[[#This Row],[PRIX UNITAIRE]]) -> 0 | G20: =+SUM(E$9:$E20)-SUM(F$9:$F20) -> 200000
E21: =+$I$2+(HASSANKAFARANI[[#This Row],[QUANTITE]]*HASSANKAFARANI[[#This Row],[PRIX UNITAIRE]]) -> 0 | G21: =+SUM(E$9:$E21)-SUM(F$9:$F21) -> 200000
E22: =+$I$2+(HASSANKAFARANI[[#This Row],[QUANTITE]]*HASSANKAFARANI[[#This Row],[PRIX UNITAIRE]]) -> 0 | G22: =+SUM(E$9:$E22)-SUM(F$9:$F22) -> 200000
E23: =+$I$2+(HASSANKAFARANI[[#This Row],[QUANTITE]]*HASSANKAFARANI[[#This Row],[PRIX UNITAIRE]]) -> 0 | G23: =+SUM(E$9:$E23)-SUM(F$9:$F23) -> 200000
E24: =+$I$2+(HASSANKAFARANI[[#This Row],[QUANTITE]]*HASSANKAFARANI[[#This Row],[PRIX UNITAIRE]]) -> 0 | G24: =+SUM(E$9:$E24)-SUM(F$9:$F24) -> 200000
E25: =+$I$2+(HASSANKAFARANI[[#This Row],[QUANTITE]]*HASSANKAFARANI[[#This Row],[PRIX UNITAIRE]]) -> 0 | G25: =+SUM(E$9:$E25)-SUM(F$9:$F25) -> 200000
E26: =+$I$2+(HASSANKAFARANI[[#This Row],[QUANTITE]]*HASSANKAFARANI[[#This Row],[PRIX UNITAIRE]]) -> 0 | G26: =+SUM(E$9:$E26)-SUM(F$9:$F26) -> 200000
... E69: =+$I$2+(HASSANKAFARANI[[#This Row],[QUANTITE]]*HASSANKAFARANI[[#This Row],[PRIX UNITAIRE]]) -> 0 | G69: =+SUM(E$9:$E69)-SUM(F$9:$F69) -> 200000

Sheet VICTOR
A2: µµ | I2: 0
D3: ANNEE | E3: CHIFFRE AFFAIRE | F3: TOTAL VERSEMENT | G3: SOLDE
D4: BILAN | E4: =+SUM(VICTOR[TOTAL MONTANT]) -> 995000 | F4: =+SUM(VICTOR[VERSEMENT]) -> 715000 | G4: =+E4-F4 -> 280000
B5: NOM CLIENT
B6: VICTOR
A8: DATE | B8: DESIGNATION | C8: QUANTITE | D8: PRIX UNITAIRE | E8: TOTAL MONTANT | F8: VERSEMENT | G8: SOLDE
A9: 46071 | B9: JEU DE PLAQUETTE VPS D1060-3JA0A | C9: 1 | D9: 10000 | E9: 10000 | F9: 0 | G9: =+SUM(E$9:$E9)-SUM(F$9:$F9) -> 10000
A10: 46072 | B10: ALTERNATEUR PAJERO (COMMANDE ANNULER) | C10: 0 | D10: 80000 | E10: 0 | F10: 0 | G10: =+SUM(E$9:$E10)-SUM(F$9:$F10) -> 10000
A11: 46072 | B11: FILTRE A AIR HIGHLANDER - 17801-20040 | C11: 1 | D11: 5000 | E11: 5000 | F11: 0 | G11: =+SUM(E$9:$E11)-SUM(F$9:$F11) -> 15000
A12: 46072 | B12: JOINT DE CACHE CULBUTEUR MAZDA 6 | C12: 1 | D12: 15000 | E12: 15000 | F12: 0 | G12: =+SUM(E$9:$E12)-SUM(F$9:$F12) -> 30000
A13: 46072 | B13: DISQUE DE ROUE AVANT MUTSIBISHI PAJERO | C13: 1 | D13: 50000 | E13: 50000 | F13: 0 | G13: =+SUM(E$9:$E13)-SUM(F$9:$F13) -> 80000
A14: 46072 | B14: DISQUE DE ROUE AR MUTSIBISHI PAJERO | C14: 1 | D14: 50000 | E14: 50000 | F14: 0 | G14: =+SUM(E$9:$E14)-SUM(F$9:$F14) -> 130000
A15: 46072 | B15: JEU DE PLAQUETTE AVANT MUTSIBISHI PAJERO | C15: 1 | D15: 10000 | E15: 10000 | F15: 0 | G15: =+SUM(E$9:$E15)-SUM(F$9:$F15) -> 140000
A16: 46072 | B16: JEU DE PLAQUETTE AR MUTSIBISHI PAJERO | C16: 1 | D16: 10000 | E16: 10000 | F16: 0 | G16: =+SUM(E$9:$E16)-SUM(F$9:$F16) -> 150000
A17: 46073 | B17: RETOUR POMPE DE DIRECTION SANDERO | C17: 1 | E17: 0 | F17: 40000 | G17: =+SUM(E$9:$E17)-SUM(F$9:$F17) -> 110000
A18: 46079 | B18: POMPE A ESSENCE NISSAN | C18: 1 | D18: 50000 | E18: 50000 | F18: 0 | G18: =+SUM(E$9:$E18)-SUM(F$9:$F18) -> 160000
A19: 46079 | B19: ROBOT AVANT 54830-0U000 | C19: 2 | D19: 10000 | E19: 20000 | F19: 0 | G19: =+SUM(E$9:$E19)-SUM(F$9:$F19) -> 180000
A20: 46079 | B20: AMORTISSEURS AV D3 | C20: 2 | D20: 40000 | E20: 80000 | F20: 0 | G20: =+SUM(E$9:$E20)-SUM(F$9:$F20) -> 260000
A21: 46079 | B21: DISQUE AV C1 | C21: 2 | D21: 45000 | E21: 90000 | F21: 0 | G21: =+SUM(E$9:$E21)-SUM(F$9:$F21) -> 350000
A22: 46079 | B22: JEU DE PLAQUETTE AVANT 2S VPS | C22: 1 | D22: 10000 | E22: 10000 | F22: 0 | G22: =+SUM(E$9:$E22)-SUM(F$9:$F22) -> 360000
A23: 46079 | B23: FILTRE A POLLEN 3S | C23: 1 | D23: 5000 | E23: 5000 | F23: 0 | G23: =+SUM(E$9:$E23)-SUM(F$9:$F23) -> 365000
A24: 46074 | B24: CREMAILLERE FORD RANGER | C24: 1 | D24: 180000 | E24: 180000 | F24: 0 | G24: =+SUM(E$9:$E24)-SUM(F$9:$F24) -> 545000
A25: 46074 | B25: ROTULES DE DIR AVANT FORD RANGER | C25: 2 | D25: 7500 | E25: 15000 | F25: 0 | G25: =+SUM(E$9:$E25)-SUM(F$9:$F25) -> 560000
A26: 46081 | B26: MOYEU ARRIERE AVENSIS 2005 | C26: 2 | D26: 25000 | E26: 50000 | F26: 0 | G26: =+SUM(E$9:$E26)-SUM(F$9:$F26) -> 610000
A27: 46081 | B27: ROTULES DE DIR 56820-2E900 | C27: 2 | D27: 7500 | E27: 15000 | F27: 0 | G27: =+SUM(E$9:$E27)-SUM(F$9:$F27) -> 625000
A28: 46085 | B28: PLAQUETTE AV BT 50 | C28: 2 | D28: 15000 | E28: 30000 | F28: 0 | G28: =+SUM(E$9:$E28)-SUM(F$9:$F28) -> 655000
A29: 46085 | B29: GARNITURE DE FREIN TOYOTA RUSH | C29: 1 | D29: 20000 | E29: 20000 | F29: 0 | G29: =+SUM(E$9:$E29)-SUM(F$9:$F29) -> 675000
A30: 46088 | B30: VERSEMENT | C30: 1 | E30: 0 | F30: 675000 | G30: =+SUM(E$9:$E30)-SUM(F$9:$F30) -> 0
A31: 46090 | B31: DISQUE DE ROUE AR PRADO 60311 | C31: 2 | D31: 25000 | E31: 50000 | F31: 0 | G31: =+SUM(E$9:$E31)-SUM(F$9:$F31) -> 50000
A32: 46090 | B32: DISQUE DE ROUE AV PRADO 60150 | C32: 2 | D32: 25000 | E32: 50000 | F32: 0 | G32: =+SUM(E$9:$E32)-SUM(F$9:$F32) -> 100000
A33: 46090 | B33: ROBOT AVANT 54830-4A000 | C33: 2 | D33: 5000 | E33: 10000 | F33: 0 | G33: =+SUM(E$9:$E33)-SUM(F$9:$F33) -> 110000
A34: 46090 | B34: ROTULES DIRECTION 45045-09800 | C34: 2 | D34: 7500 | E34: 15000 | F34: 0 | G34: =+SUM(E$9:$E34)-SUM(F$9:$F34) -> 125000
A35: 46094 | B35: SILENT BLOC DE BRAS AV PAJERO SPORT | C35: 4 | D35: 5000 | E35: 20000 | G35: =+SUM(E$9:$E35)-SUM(F$9:$F35) -> 145000
A36: 46094 | B36: ROBOT AV PAJERO SPORT | C36: 2 | D36: 7500 | E36: 15000 | G36: =+SUM(E$9:$E36)-SUM(F$9:$F36) -> 160000
A37: 46094 | B37: ROTULES DE DIRECTION PAJERO SPORT | C37: 2 | D37: 7500 | E37: 15000 | G37: =+SUM(E$9:$E37)-SUM(F$9:$F37) -> 175000
A38: 46094 | B38: EMBOUTS DE CREMAILLERE PAJERO SPORT | C38: 2 | D38: 7500 | E38: 15000 | G38: =+SUM(E$9:$E38)-SUM(F$9:$F38) -> 190000
A39: 46094 | B39: ROBOTS AV ACURA | C39: 2 | D39: 10000 | E39: =VICTOR[[#This Row],[QUANTITE]]*VICTOR[[#This Row],[PRIX UNITAIRE]] -> 20000 | G39: =+SUM(E$9:$E39)-SUM(F$9:$F39) -> 210000
A40: 46253 | B40: DISQUE DE ROUE AR FJ CRUISER | C40: 2 | D40: 25000 | E40: =VICTOR[[#This Row],[QUANTITE]]*VICTOR[[#This Row],[PRIX UNITAIRE]] -> 50000 | G40: =+SUM(E$9:$E40)-SUM(F$9:$F40) -> 260000
A41: 46253 | B41: PLAQUETTE DE FREIN AR FJ CRUISIER | C41: 1 | D41: 10000 | E41: =VICTOR[[#This Row],[QUANTITE]]*VICTOR[[#This Row],[PRIX UNITAIRE]] -> 10000 | G41: =+SUM(E$9:$E41)-SUM(F$9:$F41) -> 270000
A42: 46253 | B42: PLAQUETTE DE FREIN AV FJ CRUISER | C42: 1 | D42: 10000 | E42: =VICTOR[[#This Row],[QUANTITE]]*VICTOR[[#This Row],[PRIX UNITAIRE]] -> 10000 | G42: =+SUM(E$9:$E42)-SUM(F$9:$F42) -> 280000
...

Sheet SOLO
I2: 0
D3: ANNEE | E3: CHIFFRE AFFAIRE | F3: TOTAL VERSEMENT | G3: SOLDE
D4: BILAN | E4: =+SUM(SOLO[TOTAL MONTANT]) -> 70000 | F4: =+SUM(SOLO[VERSEMENT]) -> 0 | G4: =+E4-F4 -> 70000
B5: NOM CLIENT
B6: SOLO
A8: DATE | B8: DESIGNATION | C8: QUANTITE | D8: PRIX UNITAIRE | E8: TOTAL MONTANT | F8: VERSEMENT | G8: SOLDE
A9: 46102 | B9: 215/60r17 kapsen | C9: 2 | D9: 35000 | E9: =SOLO[[#This Row],[QUANTITE]]*SOLO[[#This Row],[PRIX UNITAIRE]] -> 70000 | G9: =SUM(E$9:$E9)-SUM(F$9:$F9) -> 70000
G10: =SUM(E$9:$E10)-SUM(F$9:$F10) -> 70000
G11: =SUM(E$9:$E11)-SUM(F$9:$F11) -> 70000
G12: =SUM(E$9:$E12)-SUM(F$9:$F12) -> 70000
G13: =SUM(E$9:$E13)-SUM(F$9:$F13) -> 70000
G14: =SUM(E$9:$E14)-SUM(F$9:$F14) -> 70000
G15: =SUM(E$9:$E15)-SUM(F$9:$F15) -> 70000
G16: =SUM(E$9:$E16)-SUM(F$9:$F16) -> 70000
G17: =SUM(E$9:$E17)-SUM(F$9:$F17) -> 70000
G18: =SUM(E$9:$E18)-SUM(F$9:$F18) -> 70000
G19: =SUM(E$9:$E19)-SUM(F$9:$F19) -> 70000
G20: =SUM(E$9:$E20)-SUM(F$9:$F20) -> 70000
G21: =SUM(E$9:$E21)-SUM(F$9:$F21) -> 70000
... G40: =SUM(E$9:$E40)-SUM(F$9:$F40) -> 70000
E41: =+$I$2+(SOLO[[#This Row],[QUANTITE]]*SOLO[[#This Row],[PRIX UNITAIRE]]) -> 0 | G41: =SUM(E$9:$E41)-SUM(F$9:$F41) -> 70000
E42: =+$I$2+(SOLO[[#This Row],[QUANTITE]]*SOLO[[#This Row],[PRIX UNITAIRE]]) -> 0 | G42: =SUM(E$9:$E42)-SUM(F$9:$F42) -> 70000
E43: =+$I$2+(SOLO[[#This Row],[QUANTITE]]*SOLO[[#This Row],[PRIX UNITAIRE]]) -> 0 | G43: =SUM(E$9:$E43)-SUM(F$9:$F43) -> 70000
E44: =+$I$2+(SOLO[[#This Row],[QUANTITE]]*SOLO[[#This Row],[PRIX UNITAIRE]]) -> 0 | G44: =SUM(E$9:$E44)-SUM(F$9:$F44) -> 70000
E45: =+$I$2+(SOLO[[#This Row],[QUANTITE]]*SOLO[[#This Row],[PRIX UNITAIRE]]) -> 0 | G45: =SUM(E$9:$E45)-SUM(F$9:$F45) -> 70000

Sheet ABASS KANSSA
I2: 0
D3: ANNEE | E3: CHIFFRE AFFAIRE | F3: TOTAL VERSEMENT | G3: SOLDE
D4: BILAN | E4: =+SUM(ABASSKANSSA[TOTAL MONTANT]) -> 0 | F4: =+SUM(ABASSKANSSA[VERSEMENT]) -> 0 | G4: =+E4-F4 -> 0
B5: NOM CLIENT
B6: ABASS KANSSA
A8: DATE | B8: DESIGNATION | C8: QUANTITE | D8: PRIX UNITAIRE | E8: TOTAL MONTANT | F8: VERSEMENT | G8: SOLDE
E9: =+$I$2+(ABASSKANSSA[[#This Row],[QUANTITE]]*ABASSKANSSA[[#This Row],[PRIX UNITAIRE]]) -> 0 | G9: =+SUM(E$9:$E9)-SUM(F$9:$F9) -> 0
E10: =+$I$2+(ABASSKANSSA[[#This Row],[QUANTITE]]*ABASSKANSSA[[#This Row],[PRIX UNITAIRE]]) -> 0 | G10: =+SUM(E$9:$E10)-SUM(F$9:$F10) -> 0
E11: =+$I$2+(ABASSKANSSA[[#This Row],[QUANTITE]]*ABASSKANSSA[[#This Row],[PRIX UNITAIRE]]) -> 0 | G11: =+SUM(E$9:$E11)-SUM(F$9:$F11) -> 0
E12: =+$I$2+(ABASSKANSSA[[#This Row],[QUANTITE]]*ABASSKANSSA[[#This Row],[PRIX UNITAIRE]]) -> 0 | G12: =+SUM(E$9:$E12)-SUM(F$9:$F12) -> 0
E13: =+$I$2+(ABASSKANSSA[[#This Row],[QUANTITE]]*ABASSKANSSA[[#This Row],[PRIX UNITAIRE]]) -> 0 | G13: =+SUM(E$9:$E13)-SUM(F$9:$F13) -> 0
E14: =+$I$2+(ABASSKANSSA[[#This Row],[QUANTITE]]*ABASSKANSSA[[#This Row],[PRIX UNITAIRE]]) -> 0 | G14: =+SUM(E$9:$E14)-SUM(F$9:$F14) -> 0
E15: =+$I$2+(ABASSKANSSA[[#This Row],[QUANTITE]]*ABASSKANSSA[[#This Row],[PRIX UNITAIRE]]) -> 0 | G15: =+SUM(E$9:$E15)-SUM(F$9:$F15) -> 0
E16: =+$I$2+(ABASSKANSSA[[#This Row],[QUANTITE]]*ABASSKANSSA[[#This Row],[PRIX UNITAIRE]]) -> 0 | G16: =+SUM(E$9:$E16)-SUM(F$9:$F16) -> 0
E17: =+$I$2+(ABASSKANSSA[[#This Row],[QUANTITE]]*ABASSKANSSA[[#This Row],[PRIX UNITAIRE]]) -> 0 | G17: =+SUM(E$9:$E17)-SUM(F$9:$F17) -> 0
E18: =+$I$2+(ABASSKANSSA[[#This Row],[QUANTITE]]*ABASSKANSSA[[#This Row],[PRIX UNITAIRE]]) -> 0 | G18: =+SUM(E$9:$E18)-SUM(F$9:$F18) -> 0
E19: =+$I$2+(ABASSKANSSA[[#This Row],[QUANTITE]]*ABASSKANSSA[[#This Row],[PRIX UNITAIRE]]) -> 0 | G19: =+SUM(E$9:$E19)-SUM(F$9:$F19) -> 0
E20: =+$I$2+(ABASSKANSSA[[#This Row],[QUANTITE]]*ABASSKANSSA[[#This Row],[PRIX UNITAIRE]]) -> 0 | G20: =+SUM(E$9:$E20)-SUM(F$9:$F20) -> 0
... E69: =+$I$2+(ABASSKANSSA[[#This Row],[QUANTITE]]*ABASSKANSSA[[#This Row],[PRIX UNITAIRE]]) -> 0 | G69: =+SUM(E$9:$E69)-SUM(F$9:$F69) -> 0

Sheet SAKO
I2: 0
D3: ANNEE | E3: CHIFFRE AFFAIRE | F3: TOTAL VERSEMENT | G3: SOLDE
D4: BILAN | E4: =+SUM(SAKO[TOTAL MONTANT]) -> 0 | F4: =+SUM(SAKO[VERSEMENT]) -> 0 | G4: =+E4-F4 -> 0
B5: NOM CLIENT
B6: SAKO
A8: DATE | B8: DESIGNATION | C8: QUANTITE | D8: PRIX UNITAIRE | E8: TOTAL MONTANT | F8: VERSEMENT | G8: SOLDE
E9: =+$I$2+(SAKO[[#This Row],[QUANTITE]]*SAKO[[#This Row],[PRIX UNITAIRE]]) -> 0 | G9: =+SUM(E$9:$E9)-SUM(F$9:$F9) -> 0
E10: =+$I$2+(SAKO[[#This Row],[QUANTITE]]*SAKO[[#This Row],[PRIX UNITAIRE]]) -> 0 | G10: =+SUM(E$9:$E10)-SUM(F$9:$F10) -> 0
E11: =+$I$2+(SAKO[[#This Row],[QUANTITE]]*SAKO[[#This Row],[PRIX UNITAIRE]]) -> 0 | G11: =+SUM(E$9:$E11)-SUM(F$9:$F11) -> 0
E12: =+$I$2+(SAKO[[#This Row],[QUANTITE]]*SAKO[[#This Row],[PRIX UNITAIRE]]) -> 0 | G12: =+SUM(E$9:$E12)-SUM(F$9:$F12) -> 0
E13: =+$I$2+(SAKO[[#This Row],[QUANTITE]]*SAKO[[#This Row],[PRIX UNITAIRE]]) -> 0 | G13: =+SUM(E$9:$E13)-SUM(F$9:$F13) -> 0
E14: =+$I$2+(SAKO[[#This Row],[QUANTITE]]*SAKO[[#This Row],[PRIX UNITAIRE]]) -> 0 | G14: =+SUM(E$9:$E14)-SUM(F$9:$F14) -> 0
E15: =+$I$2+(SAKO[[#This Row],[QUANTITE]]*SAKO[[#This Row],[PRIX UNITAIRE]]) -> 0 | G15: =+SUM(E$9:$E15)-SUM(F$9:$F15) -> 0
E16: =+$I$2+(SAKO[[#This Row],[QUANTITE]]*SAKO[[#This Row],[PRIX UNITAIRE]]) -> 0 | G16: =+SUM(E$9:$E16)-SUM(F$9:$F16) -> 0
E17: =+$I$2+(SAKO[[#This Row],[QUANTITE]]*SAKO[[#This Row],[PRIX UNITAIRE]]) -> 0 | G17: =+SUM(E$9:$E17)-SUM(F$9:$F17) -> 0
E18: =+$I$2+(SAKO[[#This Row],[QUANTITE]]*SAKO[[#This Row],[PRIX UNITAIRE]]) -> 0 | G18: =+SUM(E$9:$E18)-SUM(F$9:$F18) -> 0
E19: =+$I$2+(SAKO[[#This Row],[QUANTITE]]*SAKO[[#This Row],[PRIX UNITAIRE]]) -> 0 | G19: =+SUM(E$9:$E19)-SUM(F$9:$F19) -> 0
E20: =+$I$2+(SAKO[[#This Row],[QUANTITE]]*SAKO[[#This Row],[PRIX UNITAIRE]]) -> 0 | G20: =+SUM(E$9:$E20)-SUM(F$9:$F20) -> 0
... E69: =+$I$2+(SAKO[[#This Row],[QUANTITE]]*SAKO[[#This Row],[PRIX UNITAIRE]]) -> 0 | G69: =+SUM(E$9:$E69)-SUM(F$9:$F69) -> 0

Sheet AHMAD WESLAKE
I2: 0
D3: ANNEE | E3: CHIFFRE AFFAIRE | F3: TOTAL VERSEMENT | G3: SOLDE
D4: BILAN | E4: =+SUM(AHMADWESLAKE[TOTAL MONTANT]) -> 525000 | F4: =+SUM(AHMADWESLAKE[VERSEMENT]) -> 0 | G4: =+E4-F4 -> 525000
B5: NOM CLIENT
B6: AHMAD WESLAKE
A8: DATE | B8: DESIGNATION | C8: QUANTITE | D8: PRIX UNITAIRE | E8: TOTAL MONTANT | F8: VERSEMENT | G8: SOLDE
A9: 46099 | B9: PNEU 12.00R24(SAMIH) | C9: 3 | D9: 175000 | E9: 525000 | F9: 0 | G9: =+SUM(E$9:$E9)-SUM(F$9:$F9) -> 525000
E10: =$I$2+(AHMADWESLAKE[[#This Row],[QUANTITE]]*AHMADWESLAKE[[#This Row],[PRIX UNITAIRE]]) -> 0 | G10: =+SUM(E$9:$E10)-SUM(F$9:$F10) -> 525000
