Workbook

Sheet TABLEAU
A1: N

Sheet YOUBA ADZOPE
H2: 0
D3: ANNEE | E3: CHIFFRE AFFAIRE | F3: TOTAL VERSEMENT | G3: SOLDE
D4: BILAN | E4: =+SUM(SENATBL47[TOTAL MONTANT]) -> 580000 | F4: =+SUM(SENATBL47[VERSEMENT]) -> 0 | G4: =+E4-F4 -> 580000
B5: NOM CLIENT
B6: YOUBA ADZOPE | E6: TRUE
A8: DATE | B8: DESIGNATION | C8: QUANTITE | D8: PRIX UNITAIRE | E8: TOTAL MONTANT | F8: VERSEMENT | G8: SOLDE
A9: 46049 | B9: PNEU 8.25R16 | C9: 2 | D9: 75000 | E9: =+$H$2+(SENATBL47[[#This Row],[QUANTITE]]*SENATBL47[[#This Row],[PRIX UNITAIRE]]) -> 150000 | G9: =SUM(E$9:$E9)-SUM(F$9:$F9) -> 150000
E10: =+$H$2+(SENATBL47[[#This Row],[QUANTITE]]*SENATBL47[[#This Row],[PRIX UNITAIRE]]) -> 0 | G10: =SUM(E$9:$E10)-SUM(F$9:$F10) -> 150000
A11: 46049 | B11: BATTERIE 120AH | C11: 2 | D11: 85000 | E11: =+$H$2+(SENATBL47[[#This Row],[QUANTITE]]*SENATBL47[[#This Row],[PRIX UNITAIRE]]) -> 170000 | G11: =SUM(E$9:$E11)-SUM(F$9:$F11) -> 320000
A12: 46063 | B12: PNEU 315/80R22.5 MIXTE | C12: 2 | D12: 130000 | E12: =+$H$2+(SENATBL47[[#This Row],[QUANTITE]]*SENATBL47[[#This Row],[PRIX UNITAIRE]]) -> 260000 | G12: =SUM(E$9:$E12)-SUM(F$9:$F12) -> 580000
E13: =+$H$2+(SENATBL47[[#This Row],[QUANTITE]]*SENATBL47[[#This Row],[PRIX UNITAIRE]]) -> 0 | G13: =SUM(E$9:$E13)-SUM(F$9:$F13) -> 580000
E14: =+$H$2+(SENATBL47[[#This Row],[QUANTITE]]*SENATBL47[[#This Row],[PRIX UNITAIRE]]) -> 0 | G14: =SUM(E$9:$E14)-SUM(F$9:$F14) -> 580000
E15: =+$H$2+(SENATBL47[[#This Row],[QUANTITE]]*SENATBL47[[#This Row],[PRIX UNITAIRE]]) -> 0 | G15: =SUM(E$9:$E15)-SUM(F$9:$F15) -> 580000
E16: =+$H$2+(SENATBL47[[#This Row],[QUANTITE]]*SENATBL47[[#This Row],[PRIX UNITAIRE]]) -> 0 | G16: =SUM(E$9:$E16)-SUM(F$9:$F16) -> 580000
E17: =+$H$2+(SENATBL47[[#This Row],[QUANTITE]]*SENATBL47[[#This Row],[PRIX UNITAIRE]]) -> 0 | G17: =SUM(E$9:$E17)-SUM(F$9:$F17) -> 580000
E18: =+$H$2+(SENATBL47[[#This Row],[QUANTITE]]*SENATBL47[[#This Row],[PRIX UNITAIRE]]) -> 0 | G18: =SUM(E$9:$E18)-SUM(F$9:$F18) -> 580000
E19: =+$H$2+(SENATBL47[[#This Row],[QUANTITE]]*SENATBL47[[#This Row],[PRIX UNITAIRE]]) -> 0 | G19: =SUM(E$9:$E19)-SUM(F$9:$F19) -> 580000
E20: =+$H$2+(SENATBL47[[#This Row],[QUANTITE]]*SENATBL47[[#This Row],[PRIX UNITAIRE]]) -> 0 | G20: =SUM(E$9:$E20)-SUM(F$9:$F20) -> 580000
E21: =+$H$2+(SENATBL47[[#This Row],[QUANTITE]]*SENATBL47[[#This Row],[PRIX UNITAIRE]]) -> 0 | G21: =SUM(E$9:$E21)-SUM(F$9:$F21) -> 580000
E22: =+$H$2+(SENATBL47[[#This Row],[QUANTITE]]*SENATBL47[[#This Row],[PRIX UNITAIRE]]) -> 0 | G22: =SUM(E$9:$E22)-SUM(F$9:$F22) -> 580000
E23: =+$H$2+(SENATBL47[[#This Row],[QUANTITE]]*SENATBL47[[#This Row],[PRIX UNITAIRE]]) -> 0 | G23: =SUM(E$9:$E23)-SUM(F$9:$F23) -> 580000
E24: =+$H$2+(SENATBL47[[#This Row],[QUANTITE]]*SENATBL47[[#This Row],[PRIX UNITAIRE]]) -> 0 | G24: =SUM(E$9:$E24)-SUM(F$9:$F24) -> 580000
... E159: =+$H$2+(SENATBL47[[#This Row],[QUANTITE]]*SENATBL47[[#This Row],[PRIX UNITAIRE]]) -> 0 | G159: =SUM(E$9:$E159)-SUM(F$9:$F159) -> 580000

Sheet NETCOM
I2: 0
D3: ANNEE | E3: CHIFFRE AFFAIRE | F3: TOTAL VERSEMENT | G3: SOLDE
D4: BILAN | E4: =+SUM(NETCOM[TOTAL MONTANT]) -> 7550000 | F4: =+SUM(NETCOM[VERSEMENT]) -> 3890000 | G4: =+E4-F4 -> 3660000
B5: NOM CLIENT
B6: NETCOM | E6: TRUE
A8: DATE | B8: DESIGNATION | C8: QUANTITE | D8: PRIX UNITAIRE | E8: TOTAL MONTANT | F8: VERSEMENT | G8: SOLDE
A9: 45863 | B9: NETCOM | E9: =+$I$2+(NETCOM[[#This Row],[QUANTITE]]*NETCOM[[#This Row],[PRIX UNITAIRE]]) -> 0 | G9: =SUM(E$9:$E9)-SUM(F$9:$F9) -> 0
A10: 45863 | B10: PNEU BLACKRIDER 315/80R22.5 MIXTE | C10: 4 | D10: 150000 | E10: =+$I$2+(NETCOM[[#This Row],[QUANTITE]]*NETCOM[[#This Row],[PRIX UNITAIRE]]) -> 600000 | G10: =SUM(E$9:$E10)-SUM(F$9:$F10) -> 600000
A11: 45863 | B11: PNEU 13R22.5 | C11: 1 | D11: 165000 | E11: =+$I$2+(NETCOM[[#This Row],[QUANTITE]]*NETCOM[[#This Row],[PRIX UNITAIRE]]) -> 165000 | G11: =SUM(E$9:$E11)-SUM(F$9:$F11) -> 765000
A12: 45863 | B12: PNEU 385/65R22.5 LONGTRACK | C12: 2 | D12: 185000 | E12: =+$I$2+(NETCOM[[#This Row],[QUANTITE]]*NETCOM[[#This Row],[PRIX UNITAIRE]]) -> 370000 | G12: =SUM(E$9:$E12)-SUM(F$9:$F12) -> 1135000
A13: 45863 | B13: BATTERIE 150 AH AUTO ENERGY | C13: 4 | D13: 110000 | E13: =+$I$2+(NETCOM[[#This Row],[QUANTITE]]*NETCOM[[#This Row],[PRIX UNITAIRE]]) -> 440000 | G13: =SUM(E$9:$E13)-SUM(F$9:$F13) -> 1575000
A14: 45863 | B14: PAYE PAR CHEQUE | E14: =+$I$2+(NETCOM[[#This Row],[QUANTITE]]*NETCOM[[#This Row],[PRIX UNITAIRE]]) -> 0 | F14: 1575000 | G14: =SUM(E$9:$E14)-SUM(F$9:$F14) -> 0
A15: 45871 | B15: HUILE MOTEUR SAE50 200L | C15: 1 | D15: 400000 | E15: =+$I$2+(NETCOM[[#This Row],[QUANTITE]]*NETCOM[[#This Row],[PRIX UNITAIRE]]) -> 400000 | G15: =SUM(E$9:$E15)-SUM(F$9:$F15) -> 400000
A16: 45871 | B16: HUILE HYDROLIQUE 68 200L | C16: 2 | D16: 400000 | E16: =+$I$2+(NETCOM[[#This Row],[QUANTITE]]*NETCOM[[#This Row],[PRIX UNITAIRE]]) -> 800000 | G16: =SUM(E$9:$E16)-SUM(F$9:$F16) -> 1200000
A17: 45871 | B17: PAYE PAR CHEQUE | E17: =+$I$2+(NETCOM[[#This Row],[QUANTITE]]*NETCOM[[#This Row],[PRIX UNITAIRE]]) -> 0 | F17: 1200000 | G17: =SUM(E$9:$E17)-SUM(F$9:$F17) -> 0
A18: 45882 | B18: PNEU 255/55R20 GLEDE | C18: 1 | D18: 80000 | E18: =+$I$2+(NETCOM[[#This Row],[QUANTITE]]*NETCOM[[#This Row],[PRIX UNITAIRE]]) -> 80000 | G18: =SUM(E$9:$E18)-SUM(F$9:$F18) -> 80000
A19: 45882 | B19: PNEU 265/65R18 GLEDE | C19: 1 | D19: 65000 | E19: =+$I$2+(NETCOM[[#This Row],[QUANTITE]]*NETCOM[[#This Row],[PRIX UNITAIRE]]) -> 65000 | G19: =SUM(E$9:$E19)-SUM(F$9:$F19) -> 145000
A20: 45888 | B20: PNEU 315/80R22.5 MIXTE | C20: 4 | D20: 150000 | E20: =+$I$2+(NETCOM[[#This Row],[QUANTITE]]*NETCOM[[#This Row],[PRIX UNITAIRE]]) -> 600000 | G20: =SUM(E$9:$E20)-SUM(F$9:$F20) -> 745000
A21: 45888 | B21: PNEU 385/65R22.5 LONGTRACK | C21: 2 | D21: 185000 | E21: =+$I$2+(NETCOM[[#This Row],[QUANTITE]]*NETCOM[[#This Row],[PRIX UNITAIRE]]) -> 370000 | G21: =SUM(E$9:$E21)-SUM(F$9:$F21) -> 1115000
A22: 45951 | B22: BARIQUE 68 200L | C22: 1 | D22: 400000 | E22: =+$I$2+(NETCOM[[#This Row],[QUANTITE]]*NETCOM[[#This Row],[PRIX UNITAIRE]]) -> 400000 | G22: =SUM(E$9:$E22)-SUM(F$9:$F22) -> 1515000
A23: 45951 | B23: BARIQUE SAE 50 | C23: 1 | D23: 400000 | E23: =+$I$2+(NETCOM[[#This Row],[QUANTITE]]*NETCOM[[#This Row],[PRIX UNITAIRE]]) -> 400000 | G23: =SUM(E$9:$E23)-SUM(F$9:$F23) -> 1915000
A24: 45964 | B24: HUILE HYDRAULIQUE 68 200L | C24: 1 | D24: 400000 | E24: =+$I$2+(NETCOM[[#This Row],[QUANTITE]]*NETCOM[[#This Row],[PRIX UNITAIRE]]) -> 400000 | G24: =SUM(E$9:$E24)-SUM(F$9:$F24) -> 2315000
A25: 45978 | B25: PAYER PAR CHEQUE N°000428 | C25: 1 | D25: 0 | E25: =+$I$2+(NETCOM[[#This Row],[QUANTITE]]*NETCOM[[#This Row],[PRIX UNITAIRE]]) -> 0 | F25: 1115000 | G25: =SUM(E$9:$E25)-SUM(F$9:$F25) -> 1200000
A26: 46000 | B26: PNEU 315/80R22.5 MIXTE | C26: 4 | D26: 150000 | E26: =+$I$2+(NETCOM[[#This Row],[QUANTITE]]*NETCOM[[#This Row],[PRIX UNITAIRE]]) -> 600000 | G26: =SUM(E$9:$E26)-SUM(F$9:$F26) -> 1800000
A27: 46013 | B27: BATTERIE 200AH ESAN | C27: 2 | D27: 120000 | E27: =+$I$2+(NETCOM[[#This Row],[QUANTITE]]*NETCOM[[#This Row],[PRIX UNITAIRE]]) -> 240000 | G27: =SUM(E$9:$E27)-SUM(F$9:$F27) -> 2040000
A28: 46044 | B28: PNEU 385/65R22.5 LONGTRACK | C28: 2 | D28: 185000 | E28: =+$I$2+(NETCOM[[#This Row],[QUANTITE]]*NETCOM[[#This Row],[PRIX UNITAIRE]]) -> 370000 | G28: =SUM(E$9:$E28)-SUM(F$9:$F28) -> 2410000
A29: 46044 | B29: PNEU 13R22.5 | C29: 1 | D29: 165000 | E29: =+$I$2+(NETCOM[[#This Row],[QUANTITE]]*NETCOM[[#This Row],[PRIX UNITAIRE]]) -> 165000 | G29: =SUM(E$9:$E29)-SUM(F$9:$F29) -> 2575000
A30: 46044 | B30: PNEU 315/80R22.5 MIXTE | C30: 3 | D30: 150000 | E30: =+$I$2+(NETCOM[[#This Row],[QUANTITE]]*NETCOM[[#This Row],[PRIX UNITAIRE]]) -> 450000 | G30: =SUM(E$9:$E30)-SUM(F$9:$F30) -> 3025000
A31: 46102 | B31: PNEU 315/80R22.5 MIXTE | C31: 3 | D31: 150000 | E31: =+$I$2+(NETCOM[[#This Row],[QUANTITE]]*NETCOM[[#This Row],[PRIX UNITAIRE]]) -> 450000 | G31: =SUM(E$9:$E31)-SUM(F$9:$F31) -> 3475000
A32: 46102 | B32: PNEU 385/65R22.5 MIXTE | C32: 1 | D32: 185000 | E32: =+$I$2+(NETCOM[[#This Row],[QUANTITE]]*NETCOM[[#This Row],[PRIX UNITAIRE]]) -> 185000 | G32: =SUM(E$9:$E32)-SUM(F$9:$F32) -> 3660000
E33: =+$I$2+(NETCOM[[#This Row],[QUANTITE]]*NETCOM[[#This Row],[PRIX UNITAIRE]]) -> 0 | G33: =SUM(E$9:$E33)-SUM(F$9:$F33) -> 3660000
E34: =+$I$2+(NETCOM[[#This Row],[QUANTITE]]*NETCOM[[#This Row],[PRIX UNITAIRE]]) -> 0 | G34: =SUM(E$9:$E34)-SUM(F$9:$F34) -> 3660000
E35: =+$I$2+(NETCOM[[#This Row],[QUANTITE]]*NETCOM[[#This Row],[PRIX UNITAIRE]]) -> 0 | G35: =SUM(E$9:$E35)-SUM(F$9:$F35) -> 3660000
E36: =+$I$2+(NETCOM[[#This Row],[QUANTITE]]*NETCOM[[#This Row],[PRIX UNITAIRE]]) -> 0 | G36: =SUM(E$9:$E36)-SUM(F$9:$F36) -> 3660000
E37: =+$I$2+(NETCOM[[#This Row],[QUANTITE]]*NETCOM[[#This Row],[PRIX UNITAIRE]]) -> 0 | G37: =SUM(E$9:$E37)-SUM(F$9:$F37) -> 3660000
E38: =+$I$2+(NETCOM[[#This Row],[QUANTITE]]*NETCOM[[#This Row],[PRIX UNITAIRE]]) -> 0 | G38: =SUM(E$9:$E38)-SUM(F$9:$F38) -> 3660000
E39: =+$I$2+(NETCOM[[#This Row],[QUANTITE]]*NETCOM[[#This Row],[PRIX UNITAIRE]]) -> 0 | G39: =SUM(E$9:$E39)-SUM(F$9:$F39) -> 3660000
E40: =+$I$2+(NETCOM[[#This Row],[QUANTITE]]*NETCOM[[#This Row],[PRIX UNITAIRE]]) -> 0 | G40: =SUM(E$9:$E40)-SUM(F$9:$F40) -> 3660000
E41: =+$I$2+(NETCOM[[#This Row],[QUANTITE]]*NETCOM[[#This Row],[PRIX UNITAIRE]]) -> 0 | G41: =SUM(E$9:$E41)-SUM(F$9:$F41) -> 3660000
E42: =+$I$2+(NETCOM[[#This Row],[QUANTITE]]*NETCOM[[#This Row],[PRIX UNITAIRE]]) -> 0 | G42: =SUM(E$9:$E42)-SUM(F$9:$F42) -> 3660000
...

Sheet FIDAA
I2: 0
D3: ANNEE | E3: CHIFFRE AFFAIRE | F3: TOTAL VERSEMENT | G3: SOLDE
D4: BILAN | E4: =+SUM(FIDAA[TOTAL MONTANT]) -> 55549350 | F4: =+SUM(FIDAA[VERSEMENT]) -> 48815000 | G4: =+E4-F4 -> 6734350
B5: NOM CLIENT
B6: FIDAA | E6: TRUE
A8: DATE | B8: DESIGNATION | C8: QUANTITE | D8: PRIX UNITAIRE | E8: TOTAL MONTANT | F8: VERSEMENT | G8: SOLDE
A9: 45363 | B9: BATTERIE 200AH OURSUN | C9: 2 | D9: 90000 | E9: =+$I$2+(FIDAA[[#This Row],[QUANTITE]]*FIDAA[[#This Row],[PRIX UNITAIRE]]) -> 180000 | G9: =SUM(E$9:$E9)-SUM(F$9:$F9) -> 180000
B10: BATTERIE 150AH OURSUN | C10: 4 | D10: 70000 | E10: =+$I$2+(FIDAA[[#This Row],[QUANTITE]]*FIDAA[[#This Row],[PRIX UNITAIRE]]) -> 280000 | G10: =SUM(E$9:$E10)-SUM(F$9:$F10) -> 460000
B11: BATTERIE 120AH BEYONIX | C11: 4 | D11: 55000 | E11: =+$I$2+(FIDAA[[#This Row],[QUANTITE]]*FIDAA[[#This Row],[PRIX UNITAIRE]]) -> 220000 | G11: =SUM(E$9:$E11)-SUM(F$9:$F11) -> 680000
B12: BATTERIE 100AH OURSUN | C12: 4 | D12: 48000 | E12: =+$I$2+(FIDAA[[#This Row],[QUANTITE]]*FIDAA[[#This Row],[PRIX UNITAIRE]]) -> 192000 | G12: =SUM(E$9:$E12)-SUM(F$9:$F12) -> 872000
B13: BATTERIE 75AH BEYONIX | C13: 10 | D13: 27500 | E13: =+$I$2+(FIDAA[[#This Row],[QUANTITE]]*FIDAA[[#This Row],[PRIX UNITAIRE]]) -> 275000 | G13: =SUM(E$9:$E13)-SUM(F$9:$F13) -> 1147000
B14: BETTERIE 55AH OURSUN | C14: 4 | D14: 27000 | E14: =+$I$2+(FIDAA[[#This Row],[QUANTITE]]*FIDAA[[#This Row],[PRIX UNITAIRE]]) -> 108000 | G14: =SUM(E$9:$E14)-SUM(F$9:$F14) -> 1255000
B15: BATTERIE 45AH VEGA TH | C15: 2 | D15: 25000 | E15: =+$I$2+(FIDAA[[#This Row],[QUANTITE]]*FIDAA[[#This Row],[PRIX UNITAIRE]]) -> 50000 | G15: =SUM(E$9:$E15)-SUM(F$9:$F15) -> 1305000
B16: BATTERIE 45AH TEKOMA TB | C16: 2 | D16: 25000 | E16: =+$I$2+(FIDAA[[#This Row],[QUANTITE]]*FIDAA[[#This Row],[PRIX UNITAIRE]]) -> 50000 | G16: =SUM(E$9:$E16)-SUM(F$9:$F16) -> 1355000
B17: BATTERIE 90AH VISCA | C17: 2 | D17: 45000 | E17: =+$I$2+(FIDAA[[#This Row],[QUANTITE]]*FIDAA[[#This Row],[PRIX UNITAIRE]]) -> 90000 | G17: =SUM(E$9:$E17)-SUM(F$9:$F17) -> 1445000
B18: PNEU 195R15C HABLEAD | C18: 4 | D18: 32000 | E18: =+$I$2+(FIDAA[[#This Row],[QUANTITE]]*FIDAA[[#This Row],[PRIX UNITAIRE]]) -> 128000 | G18: =SUM(E$9:$E18)-SUM(F$9:$F18) -> 1573000
B19: PNEU 195/65R15 ZEXTOUR | C19: 4 | D19: 20000 | E19: =+$I$2+(FIDAA[[#This Row],[QUANTITE]]*FIDAA[[#This Row],[PRIX UNITAIRE]]) -> 80000 | G19: =SUM(E$9:$E19)-SUM(F$9:$F19) -> 1653000
B20: PNEU 265/70R16 APLUS | C20: 4 | D20: 45000 | E20: =+$I$2+(FIDAA[[#This Row],[QUANTITE]]*FIDAA[[#This Row],[PRIX UNITAIRE]]) -> 180000 | G20: =SUM(E$9:$E20)-SUM(F$9:$F20) -> 1833000
B21: PNEU 205/55R16 Z3EXTOUR | C21: 4 | D21: 27500 | E21: =+$I$2+(FIDAA[[#This Row],[QUANTITE]]*FIDAA[[#This Row],[PRIX UNITAIRE]]) -> 110000 | G21: =SUM(E$9:$E21)-SUM(F$9:$F21) -> 1943000
... B27: PNEU 255/70R16 KAPSEN | C27: 4 | D27: 47500 | E27: =+$I$2+(FIDAA[[#This Row],[QUANTITE]]*FIDAA[[#This Row],[PRIX UNITAIRE]]) -> 190000 | G27: =SUM(E$9:$E27)-SUM(F$9:$F27) -> 2611000
A28: 45365 | B28: PNEU TRANSMATE 235/65R16C | C28: 4 | D28: 40000 | E28: =+$I$2+(FIDAA[[#This Row],[QUANTITE]]*FIDAA[[#This Row],[PRIX UNITAIRE]]) -> 160000 | G28: =SUM(E$9:$E28)-SUM(F$9:$F28) -> 2771000
B29: PNEU TRANSMATE 175/70R14 | C29: 10 | D29: 16000 | E29: =+$I$2+(FIDAA[[#This Row],[QUANTITE]]*FIDAA[[#This Row],[PRIX UNITAIRE]]) -> 160000 | G29: =SUM(E$9:$E29)-SUM(F$9:$F29) -> 2931000
B30: PNEU TRANSMATE 185/60R15 | C30: 4 | D30: 22500 | E30: =+$I$2+(FIDAA[[#This Row],[QUANTITE]]*FIDAA[[#This Row],[PRIX UNITAIRE]]) -> 90000 | G30: =SUM(E$9:$E30)-SUM(F$9:$F30) -> 3021000
B31: PNEU TRANSMATE 185/65R15 | C31: 4 | D31: 22500 | E31: =+$I$2+(FIDAA[[#This Row],[QUANTITE]]*FIDAA[[#This Row],[PRIX UNITAIRE]]) -> 90000 | G31: =SUM(E$9:$E31)-SUM(F$9:$F31) -> 3111000
B32: PNEU TRANSMATE 225/70R15C | C32: 10 | D32: 33000 | E32: =+$I$2+(FIDAA[[#This Row],[QUANTITE]]*FIDAA[[#This Row],[PRIX UNITAIRE]]) -> 330000 | G32: =SUM(E$9:$E32)-SUM(F$9:$F32) -> 3441000
B33: PNEU TRANSMATE 215/65R16 | C33: 10 | D33: 32000 | E33: =+$I$2+(FIDAA[[#This Row],[QUANTITE]]*FIDAA[[#This Row],[PRIX UNITAIRE]]) -> 320000 | G33: =SUM(E$9:$E33)-SUM(F$9:$F33) -> 3761000
B34: PNEU TRANSMATE 235/70R16 | C34: 4 | D34: 35000 | E34: =+$I$2+(FIDAA[[#This Row],[QUANTITE]]*FIDAA[[#This Row],[PRIX UNITAIRE]]) -> 140000 | G34: =SUM(E$9:$E34)-SUM(F$9:$F34) -> 3901000
B35: PNEU TRANSMATE 225/65R17 | C35: 4 | D35: 33000 | E35: =+$I$2+(FIDAA[[#This Row],[QUANTITE]]*FIDAA[[#This Row],[PRIX UNITAIRE]]) -> 132000 | G35: =SUM(E$9:$E35)-SUM(F$9:$F35) -> 4033000
B36: PNEU TRANSMATE 235/65R17 | C36: 4 | D36: 35000 | E36: =+$I$2+(FIDAA[[#This Row],[QUANTITE]]*FIDAA[[#This Row],[PRIX UNITAIRE]]) -> 140000 | G36: =SUM(E$9:$E36)-SUM(F$9:$F36) -> 4173000
B37: PNEU TRANSMATE 285/65R17 | C37: 4 | D37: 65000 | E37: =+$I$2+(FIDAA[[#This Row],[QUANTITE]]*FIDAA[[#This Row],[PRIX UNITAIRE]]) -> 260000 | G37: =SUM(E$9:$E37)-SUM(F$9:$F37) -> 4433000
B38: PNEU TRANSMATE 235/60R18 | C38: 4 | D38: 40000 | E38: =+$I$2+(FIDAA[[#This Row],[QUANTITE]]*FIDAA[[#This Row],[PRIX UNITAIRE]]) -> 160000 | G38: =SUM(E$9:$E38)-SUM(F$9:$F38) -> 4593000
B39: PNEU TRANSMATE 265/60R18 | C39: 4 | D39: 55000 | E39: =+$I$2+(FIDAA[[#This Row],[QUANTITE]]*FIDAA[[#This Row],[PRIX UNITAIRE]]) -> 220000 | G39: =SUM(E$9:$E39)-SUM(F$9:$F39) -> 4813000
B40: PNEU BLACK RIDER 315/80R22,5 | C40: 4 | D40: 102500 | E40: =+$I$2+(FIDAA[[#This Row],[QUANTITE]]*FIDAA[[#This Row],[PRIX UNITAIRE]]) -> 410000 | G40: =SUM(E$9:$E40)-SUM(F$9:$F40) -> 5223000
... B67: BALAIE ESSUI GLACE VALEO 22 | C67: 2 | D67: 7500 | E67: =+$I$2+(FIDAA[[#This Row],[QUANTITE]]*FIDAA[[#This Row],[PRIX UNITAIRE]]) -> 15000 | G67: =SUM(E$9:$E67)-SUM(F$9:$F67) -> 6694350
A68: 45353 | B68: REGLEMENT ESPECES | C68: 1 | D68: 0 | E68: =+$I$2+(FIDAA[[#This Row],[QUANTITE]]*FIDAA[[#This Row],[PRIX UNITAIRE]]) -> 0 | F68: 1000000 | G68: =SUM(E$9:$E68)-SUM(F$9:$F68) -> 5694350
A69: 45376 | B69: CRIC 35T | C69: 1 | D69: 28000 | E69: =+$I$2+(FIDAA[[#This Row],[QUANTITE]]*FIDAA[[#This Row],[PRIX UNITAIRE]]) -> 28000 | G69: =SUM(E$9:$E69)-SUM(F$9:$F69) -> 5722350
B70: CRIC 20T | C70: 1 | D70: 23000 | E70: =+$I$2+(FIDAA[[#This Row],[QUANTITE]]*FIDAA[[#This Row],[PRIX UNITAIRE]]) -> 23000 | G70: =SUM(E$9:$E70)-SUM(F$9:$F70) -> 5745350
B71: HUILE MOTEUR 5W30 | C71: 4 | D71: 12000 | E71: =+$I$2+(FIDAA[[#This Row],[QUANTITE]]*FIDAA[[#This Row],[PRIX UNITAIRE]]) -> 48000 | G71: =SUM(E$9:$E71)-SUM(F$9:$F71) -> 5793350
B72: HUILE MOTEUR 5W40 | C72: 4 | D72: 12000 | E72: =+$I$2+(FIDAA[[#This Row],[QUANTITE]]*FIDAA[[#This Row],[PRIX UNITAIRE]]) -> 48000 | G72: =SUM(E$9:$E72)-SUM(F$9:$F72) -> 5841350
B73: HUILE MOITEUR 10W40 | C73: 4 | D73: 12000 | E73: =+$I$2+(FIDAA[[#This Row],[QUANTITE]]*FIDAA[[#This Row],[PRIX UNITAIRE]]) -> 48000 | G73: =SUM(E$9:$E73)-SUM(F$9:$F73) -> 5889350
...

Sheet SOLO
I2: 0
D3: ANNEE | E3: CHIFFRE AFFAIRE | F3: TOTAL VERSEMENT | G3: SOLDE
D4: BILAN | E4: =+SUM(SOLO[TOTAL MONTANT]) -> 7209500 | F4: =+SUM(SOLO[VERSEMENT]) -> 4010000 | G4: =+E4-F4 -> 3199500
B5: NOM CLIENT
B6: SOLO
A8: DATE | B8: DESIGNATION | C8: QUANTITE | D8: PRIX UNITAIRE | E8: TOTAL MONTANT | F8: VERSEMENT | G8: SOLDE
A9: 46072 | B9: SOLDE DEPART | C9: 1 | D9: 7209500 | E9: 7209500 | G9: =SUM(E$9:$E9)-SUM(F$9:$F9) -> 7209500
A10: 46072 | C10: 1 | F10: 3010000 | G10: =SUM(E$9:$E10)-SUM(F$9:$F10) -> 4199500
A11: 46074 | C11: 1 | F11: 1000000 | G11: =SUM(E$9:$E11)-SUM(F$9:$F11) -> 3199500
A12: 46081 | B12: 195/65R15 GLEDE | C12: 4 | E12: =+$I$2+(SOLO[[#This Row],[QUANTITE]]*SOLO[[#This Row],[PRIX UNITAIRE]]) -> 0 | G12: =SUM(E$9:$E12)-SUM(F$9:$F12) -> 3199500
A13: 46083 | B13: 265/65R17 GLEDE | C13: 4 | G13: =SUM(E$9:$E13)-SUM(F$9:$F13) -> 3199500
A14: 46083 | B14: 175/70R14 GLEDE | C14: 10 | G14: =SUM(E$9:$E14)-SUM(F$9:$F14) -> 3199500
A15: 46087 | B15: PNEU 245/55R19 GLEDE | C15: 1 | G15: =SUM(E$9:$E15)-SUM(F$9:$F15) -> 3199500
A16: 46091 | B16: 245/55R19 GLEDE | C16: 2 | G16: =SUM(E$9:$E16)-SUM(F$9:$F16) -> 3199500
A17: 46095 | B17: 165/70R14 GLEDE | C17: 1 | G17: =SUM(E$9:$E17)-SUM(F$9:$F17) -> 3199500
G18: =SUM(E$9:$E18)-SUM(F$9:$F18) -> 3199500
G19: =SUM(E$9:$E19)-SUM(F$9:$F19) -> 3199500
G20: =SUM(E$9:$E20)-SUM(F$9:$F20) -> 3199500
G21: =SUM(E$9:$E21)-SUM(F$9:$F21) -> 3199500
G22: =SUM(E$9:$E22)-SUM(F$9:$F22) -> 3199500
G23: =SUM(E$9:$E23)-SUM(F$9:$F23) -> 3199500
G24: =SUM(E$9:$E24)-SUM(F$9:$F24) -> 3199500
G25: =SUM(E$9:$E25)-SUM(F$9:$F25) -> 3199500
G26: =SUM(E$9:$E26)-SUM(F$9:$F26) -> 3199500
G27: =SUM(E$9:$E27)-SUM(F$9:$F27) -> 3199500
G28: =SUM(E$9:$E28)-SUM(F$9:$F28) -> 3199500
G29: =SUM(E$9:$E29)-SUM(F$9:$F29) -> 3199500
... G40: =SUM(E$9:$E40)-SUM(F$9:$F40) -> 3199500
E41: =+$I$2+(SOLO[[#This Row],[QUANTITE]]*SOLO[[#This Row],[PRIX UNITAIRE]]) -> 0 | G41: =SUM(E$9:$E41)-SUM(F$9:$F41) -> 3199500
E42: =+$I$2+(SOLO[[#This Row],[QUANTITE]]*SOLO[[#This Row],[PRIX UNITAIRE]]) -> 0 | G42: =SUM(E$9:$E42)-SUM(F$9:$F42) -> 3199500
E43: =+$I$2+(SOLO[[#This Row],[QUANTITE]]*SOLO[[#This Row],[PRIX UNITAIRE]]) -> 0 | G43: =SUM(E$9:$E43)-SUM(F$9:$F43) -> 3199500
E44: =+$I$2+(SOLO[[#This Row],[QUANTITE]]*SOLO[[#This Row],[PRIX UNITAIRE]]) -> 0 | G44: =SUM(E$9:$E44)-SUM(F$9:$F44) -> 3199500
E45: =+$I$2+(SOLO[[#This Row],[QUANTITE]]*SOLO[[#This Row],[PRIX UNITAIRE]]) -> 0 | G45: =SUM(E$9:$E45)-SUM(F$9:$F45) -> 3199500

Sheet SENAT BL
I2: 0
D3: ANNEE | E3: CHIFFRE AFFAIRE | F3: TOTAL VERSEMENT | G3: SOLDE
D4: BILAN | E4: =+SUM(SENATBL[TOTAL MONTANT]) -> 193356500 | F4: =+SUM(SENATBL[VERSEMENT]) -> 0 | G4: =+E4-F4 -> 193356500
B5: NOM CLIENT
B6: SENAT
A8: DATE | B8: DESIGNATION | C8: QUANTITE | D8: PRIX UNITAIRE | E8: TOTAL MONTANT | F8: VERSEMENT | G8: SOLDE
A9: 46099 | B9: SOLDE DE DEPART | C9: 1 | D9: 190457500 | E9: =SENATBL[[#This Row],[PRIX UNITAIRE]]*SENATBL[[#This Row],[QUANTITE]] -> 190457500 | G9: =SUM(E$9:$E9)-SUM(F$9:$F9) -> 190457500
A10: 46099 | B10: PEINTURE NISSAN | C10: 1 | D10: 585000 | E10: =SENATBL[[#This Row],[PRIX UNITAIRE]]*SENATBL[[#This Row],[QUANTITE]] -> 585000 | G10: =SUM(E$9:$E10)-SUM(F$9:$F10) -> 191042500
A11: 46099 | B11: Vidange complet d115018 ford | C11: 1 | D11: 214500 | E11: =SENATBL[[#This Row],[PRIX UNITAIRE]]*SENATBL[[#This Row],[QUANTITE]] -> 214500 | G11: =SUM(E$9:$E11)-SUM(F$9:$F11) -> 191257000
A12: 46099 | B12: NETTOYAGE DE SYSTÈME CLIM | C12: 1 | D12: 50000 | E12: =SENATBL[[#This Row],[PRIX UNITAIRE]]*SENATBL[[#This Row],[QUANTITE]] -> 50000 | G12: =SUM(E$9:$E12)-SUM(F$9:$F12) -> 191307000
A13: 46099 | B13: MAIN DOEUVRE D115018 | C13: 1 | D13: 45000 | E13: =SENATBL[[#This Row],[PRIX UNITAIRE]]*SENATBL[[#This Row],[QUANTITE]] -> 45000 | G13: =SUM(E$9:$E13)-SUM(F$9:$F13) -> 191352000
A14: 46099 | B14: BATTERIE 75 AH ENERGY | C14: 1 | D14: 115000 | E14: =SENATBL[[#This Row],[PRIX UNITAIRE]]*SENATBL[[#This Row],[QUANTITE]] -> 115000 | G14: =SUM(E$9:$E14)-SUM(F$9:$F14) -> 191467000
A15: 46100 | B15: FIXATION PLAQUE DE PROTECTION | C15: 1 | D15: 55000 | E15: =SENATBL[[#This Row],[PRIX UNITAIRE]]*SENATBL[[#This Row],[QUANTITE]] -> 55000 | G15: =SUM(E$9:$E15)-SUM(F$9:$F15) -> 191522000
A16: 46100 | B16: POMPE A EAU ELECTRONIQUE 5024 | C16: 1 | D16: 320000 | E16: =SENATBL[[#This Row],[PRIX UNITAIRE]]*SENATBL[[#This Row],[QUANTITE]] -> 320000 | G16: =SUM(E$9:$E16)-SUM(F$9:$F16) -> 191842000
A17: 46100 | B17: COURROIE 5024 | C17: 1 | D17: 45000 | E17: =SENATBL[[#This Row],[PRIX UNITAIRE]]*SENATBL[[#This Row],[QUANTITE]] -> 45000 | G17: =SUM(E$9:$E17)-SUM(F$9:$F17) -> 191887000
A18: 46100 | B18: TENDEUR DE COURROIE 5024 | C18: 1 | D18: 175000 | E18: =SENATBL[[#This Row],[PRIX UNITAIRE]]*SENATBL[[#This Row],[QUANTITE]] -> 175000 | G18: =SUM(E$9:$E18)-SUM(F$9:$F18) -> 192062000
A19: 46100 | B19: LIQUIDE DE RADIA 5024 | C19: 1 | D19: 15000 | E19: =SENATBL[[#This Row],[PRIX UNITAIRE]]*SENATBL[[#This Row],[QUANTITE]] -> 15000 | G19: =SUM(E$9:$E19)-SUM(F$9:$F19) -> 192077000
A20: 46100 | B20: REPARATION TURBO 5024 | C20: 1 | D20: 500000 | E20: =SENATBL[[#This Row],[PRIX UNITAIRE]]*SENATBL[[#This Row],[QUANTITE]] -> 500000 | G20: =SUM(E$9:$E20)-SUM(F$9:$F20) -> 192577000
... A28: 46100 | B28: MAIN DOEUVRE | C28: 1 | D28: 100000 | E28: =SENATBL[[#This Row],[PRIX UNITAIRE]]*SENATBL[[#This Row],[QUANTITE]] -> 100000 | G28: =SUM(E$9:$E28)-SUM(F$9:$F28) -> 193356500
E29: =SENATBL[[#This Row],[PRIX UNITAIRE]]*SENATBL[[#This Row],[QUANTITE]] -> 0 | G29: =SUM(E$9:$E29)-SUM(F$9:$F29) -> 193356500
E30: =SENATBL[[#This Row],[PRIX UNITAIRE]]*SENATBL[[#This Row],[QUANTITE]] -> 0 | G30: =SUM(E$9:$E30)-SUM(F$9:$F30) -> 193356500
E31: =SENATBL[[#This Row],[PRIX UNITAIRE]]*SENATBL[[#This Row],[QUANTITE]] -> 0 | G31: =SUM(E$9:$E31)-SUM(F$9:$F31) -> 193356500
E32: =SENATBL[[#This Row],[PRIX UNITAIRE]]*SENATBL[[#This Row],[QUANTITE]] -> 0 | G32: =SUM(E$9:$E32)-SUM(F$9:$F32) -> 193356500
E33: =SENATBL[[#This Row],[PRIX UNITAIRE]]*SENATBL[[#This Row],[QUANTITE]] -> 0 | G33: =SUM(E$9:$E33)-SUM(F$9:$F33) -> 193356500
E34: =SENATBL[[#This Row],[PRIX UNITAIRE]]*SENATBL[[#This Row],[QUANTITE]] -> 0 | G34: =SUM(E$9:$E34)-SUM(F$9:$F34) -> 193356500
E35: =SENATBL[[#This Row],[PRIX UNITAIRE]]*SENATBL[[#This Row],[QUANTITE]] -> 0 | G35: =SUM(E$9:$E35)-SUM(F$9:$F35) -> 193356500
E36: =SENATBL[[#This Row],[PRIX UNITAIRE]]*SENATBL[[#This Row],[QUANTITE]] -> 0 | G36: =SUM(E$9:$E36)-SUM(F$9:$F36) -> 193356500
E37: =SENATBL[[#This Row],[PRIX UNITAIRE]]*SENATBL[[#This Row],[QUANTITE]] -> 0 | G37: =SUM(E$9:$E37)-SUM(F$9:$F37) -> 193356500
E38: =SENATBL[[#This Row],[PRIX UNITAIRE]]*SENATBL[[#This Row],[QUANTITE]] -> 0 | G38: =SUM(E$9:$E38)-SUM(F$9:$F38) -> 193356500
E39: =SENATBL[[#This Row],[PRIX UNITAIRE]]*SENATBL[[#This Row],[QUANTITE]] -> 0 | G39: =SUM(E$9:$E39)-SUM(F$9:$F39) -> 193356500
E40: =SENATBL[[#This Row],[PRIX UNITAIRE]]*SENATBL[[#This Row],[QUANTITE]] -> 0 | G40: =SUM(E$9:$E40)-SUM(F$9:$F40) -> 193356500
... E109: =SENATBL[[#This Row],[PRIX UNITAIRE]]*SENATBL[[#This Row],[QUANTITE]] -> 0 | G109: =SUM(E$9:$E109)-SUM(F$9:$F109) -> 193356500

Sheet PETIT SOLO
I2: 0
D3: ANNEE | E3: CHIFFRE AFFAIRE | F3: TOTAL VERSEMENT | G3: SOLDE
D4: BILAN | E4: =+SUM(PETITSOLO[TOTAL MONTANT]) -> 5517500 | F4: =+SUM(PETITSOLO[VERSEMENT]) -> 5347500 | G4: =+E4-F4 -> 170000
B5: NOM CLIENT
B6: PETIT SOLO
A8: DATE | B8: DESIGNATION | C8: QUANTITE | D8: PRIX UNITAIRE | E8: TOTAL MONTANT | F8: VERSEMENT | G8: SOLDE
A9: 45834 | B9: PNEU TRANSMATE 235/55R17 | C9: 4 | D9: 35000 | E9: =+$I$2+(PETITSOLO[[#This Row],[QUANTITE]]*PETITSOLO[[#This Row],[PRIX UNITAIRE]]) -> 140000 | G9: =SUM(E$9:$E9)-SUM(F$9:$F9) -> 140000
A10: 45839 | B10: PNEUTRANSMATE 225/45R17 | C10: 2 | D10: 35000 | E10: =+$I$2+(PETITSOLO[[#This Row],[QUANTITE]]*PETITSOLO[[#This Row],[PRIX UNITAIRE]]) -> 70000 | G10: =SUM(E$9:$E10)-SUM(F$9:$F10) -> 210000
A11: 45840 | B11: PNEU 235/60R18 TRANSMATE | C11: 4 | D11: 40000 | E11: =+$I$2+(PETITSOLO[[#This Row],[QUANTITE]]*PETITSOLO[[#This Row],[PRIX UNITAIRE]]) -> 160000 | G11: =SUM(E$9:$E11)-SUM(F$9:$F11) -> 370000
A12: 45846 | B12: PNEU 245/40R20 GLEDE | C12: 2 | D12: 50000 | E12: =+$I$2+(PETITSOLO[[#This Row],[QUANTITE]]*PETITSOLO[[#This Row],[PRIX UNITAIRE]]) -> 100000 | G12: =SUM(E$9:$E12)-SUM(F$9:$F12) -> 470000
A13: 45847 | B13: PNEU 235/65R17 GLEDE | C13: 4 | D13: 35000 | E13: =+$I$2+(PETITSOLO[[#This Row],[QUANTITE]]*PETITSOLO[[#This Row],[PRIX UNITAIRE]]) -> 140000 | G13: =SUM(E$9:$E13)-SUM(F$9:$F13) -> 610000
A14: 45848 | B14: PNEU 235/60R18 GLEDE | C14: 2 | D14: 40000 | E14: =+$I$2+(PETITSOLO[[#This Row],[QUANTITE]]*PETITSOLO[[#This Row],[PRIX UNITAIRE]]) -> 80000 | G14: =SUM(E$9:$E14)-SUM(F$9:$F14) -> 690000
A15: 45849 | B15: PNEU 225/50R17 GLEDDE | C15: 10 | D15: 35000 | E15: =+$I$2+(PETITSOLO[[#This Row],[QUANTITE]]*PETITSOLO[[#This Row],[PRIX UNITAIRE]]) -> 350000 | G15: =SUM(E$9:$E15)-SUM(F$9:$F15) -> 1040000
A16: 45849 | B16: PNEU 235/60R18 GLEDE | C16: 4 | D16: 42500 | E16: =+$I$2+(PETITSOLO[[#This Row],[QUANTITE]]*PETITSOLO[[#This Row],[PRIX UNITAIRE]]) -> 170000 | G16: =SUM(E$9:$E16)-SUM(F$9:$F16) -> 1210000
A17: 45836 | B17: PNEU 235/55R19 GLEDE | C17: 4 | D17: 42500 | E17: =+$I$2+(PETITSOLO[[#This Row],[QUANTITE]]*PETITSOLO[[#This Row],[PRIX UNITAIRE]]) -> 170000 | G17: =SUM(E$9:$E17)-SUM(F$9:$F17) -> 1380000
A18: 45850 | B18: PAYE | E18: =+$I$2+(PETITSOLO[[#This Row],[QUANTITE]]*PETITSOLO[[#This Row],[PRIX UNITAIRE]]) -> 0 | F18: 1380000 | G18: =SUM(E$9:$E18)-SUM(F$9:$F18) -> 0
A19: 45852 | B19: PNEU 235/60R18 GLED | C19: 4 | D19: 40000 | E19: =+$I$2+(PETITSOLO[[#This Row],[QUANTITE]]*PETITSOLO[[#This Row],[PRIX UNITAIRE]]) -> 160000 | G19: =SUM(E$9:$E19)-SUM(F$9:$F19) -> 160000
A20: 45852 | B20: PNEU 255/55R20 GLEDE | C20: 4 | D20: 50000 | E20: =+$I$2+(PETITSOLO[[#This Row],[QUANTITE]]*PETITSOLO[[#This Row],[PRIX UNITAIRE]]) -> 200000 | G20: =SUM(E$9:$E20)-SUM(F$9:$F20) -> 360000
A21: 45856 | B21: PNEU 205/55R16 GLEDE | C21: 2 | D21: 25000 | E21: =+$I$2+(PETITSOLO[[#This Row],[QUANTITE]]*PETITSOLO[[#This Row],[PRIX UNITAIRE]]) -> 50000 | G21: =SUM(E$9:$E21)-SUM(F$9:$F21) -> 410000
A22: 45853 | B22: PNEU 225.65R17 GLEDE | C22: 0 | E22: =+$I$2+(PETITSOLO[[#This Row],[QUANTITE]]*PETITSOLO[[#This Row],[PRIX UNITAIRE]]) -> 0 | G22: =SUM(E$9:$E22)-SUM(F$9:$F22) -> 410000
A23: 45855 | B23: PNEU 255/50R20 GLEDE | C23: 4 | D23: 50000 | E23: =+$I$2+(PETITSOLO[[#This Row],[QUANTITE]]*PETITSOLO[[#This Row],[PRIX UNITAIRE]]) -> 200000 | G23: =SUM(E$9:$E23)-SUM(F$9:$F23) -> 610000
A24: 45856 | B24: PAYE | E24: =+$I$2+(PETITSOLO[[#This Row],[QUANTITE]]*PETITSOLO[[#This Row],[PRIX UNITAIRE]]) -> 0 | F24: 610000 | G24: =SUM(E$9:$E24)-SUM(F$9:$F24) -> 0
A25: 45860 | B25: PNEU 225/55R19 GLEDE | C25: 2 | D25: 42500 | E25: =+$I$2+(PETITSOLO[[#This Row],[QUANTITE]]*PETITSOLO[[#This Row],[PRIX UNITAIRE]]) -> 85000 | G25: =SUM(E$9:$E25)-SUM(F$9:$F25) -> 85000
A26: 45861 | B26: PNEU 175/70R14 | C26: 6 | D26: 16000 | E26: =+$I$2+(PETITSOLO[[#This Row],[QUANTITE]]*PETITSOLO[[#This Row],[PRIX UNITAIRE]]) -> 96000 | G26: =SUM(E$9:$E26)-SUM(F$9:$F26) -> 181000
A27: 45862 | B27: PNEU 235/60R18 GLEDE | C27: 2 | D27: 40000 | E27: =+$I$2+(PETITSOLO[[#This Row],[QUANTITE]]*PETITSOLO[[#This Row],[PRIX UNITAIRE]]) -> 80000 | G27: =SUM(E$9:$E27)-SUM(F$9:$F27) -> 261000
A28: 45863 | B28: PNEU 225/55R18 GLEDE | C28: 6 | D28: 40000 | E28: =+$I$2+(PETITSOLO[[#This Row],[QUANTITE]]*PETITSOLO[[#This Row],[PRIX UNITAIRE]]) -> 240000 | G28: =SUM(E$9:$E28)-SUM(F$9:$F28) -> 501000
A29: 45864 | B29: PNEU 225/55R19 GLEDE | C29: 4 | E29: =+$I$2+(PETITSOLO[[#This Row],[QUANTITE]]*PETITSOLO[[#This Row],[PRIX UNITAIRE]]) -> 0 | G29: =SUM(E$9:$E29)-SUM(F$9:$F29) -> 501000
A30: 45861 | B30: PNEU 245/50R20 KHUMO | C30: 2 | D30: 140000 | E30: =+$I$2+(PETITSOLO[[#This Row],[QUANTITE]]*PETITSOLO[[#This Row],[PRIX UNITAIRE]]) -> 280000 | G30: =SUM(E$9:$E30)-SUM(F$9:$F30) -> 781000
A31: 45857 | B31: PNEU 225/65R17 GLEDE | C31: 2 | D31: 35000 | E31: =+$I$2+(PETITSOLO[[#This Row],[QUANTITE]]*PETITSOLO[[#This Row],[PRIX UNITAIRE]]) -> 70000 | G31: =SUM(E$9:$E31)-SUM(F$9:$F31) -> 851000
A32: 45857 | B32: PNEU 225/55R18 GLEDE | C32: 4 | D32: 40000 | E32: =+$I$2+(PETITSOLO[[#This Row],[QUANTITE]]*PETITSOLO[[#This Row],[PRIX UNITAIRE]]) -> 160000 | G32: =SUM(E$9:$E32)-SUM(F$9:$F32) -> 1011000
A33: 45864 | B33: PAYE | E33: =+$I$2+(PETITSOLO[[#This Row],[QUANTITE]]*PETITSOLO[[#This Row],[PRIX UNITAIRE]]) -> 0 | F33: 780000 | G33: =SUM(E$9:$E33)-SUM(F$9:$F33) -> 231000
A34: 45868 | B34: PNEU 225/65R17 GLEDE | C34: 4 | D34: 35000 | E34: =+$I$2+(PETITSOLO[[#This Row],[QUANTITE]]*PETITSOLO[[#This Row],[PRIX UNITAIRE]]) -> 140000 | G34: =SUM(E$9:$E34)-SUM(F$9:$F34) -> 371000
A35: 45871 | B35: PNEU 225/55R19 GLEDE | C35: 2 | D35: 42500 | E35: =+$I$2+(PETITSOLO[[#This Row],[QUANTITE]]*PETITSOLO[[#This Row],[PRIX UNITAIRE]]) -> 85000 | G35: =SUM(E$9:$E35)-SUM(F$9:$F35) -> 456000
A36: 45874 | B36: PNEU 265/60R18 GLEDE | C36: 4 | E36: =+$I$2+(PETITSOLO[[#This Row],[QUANTITE]]*PETITSOLO[[#This Row],[PRIX UNITAIRE]]) -> 0 | G36: =SUM(E$9:$E36)-SUM(F$9:$F36) -> 456000
A37: 45864 | B37: PNEU 235/55R19 GLEDE | C37: 3 | D37: 42500 | E37: =+$I$2+(PETITSOLO[[#This Row],[QUANTITE]]*PETITSOLO[[#This Row],[PRIX UNITAIRE]]) -> 127500 | G37: =SUM(E$9:$E37)-SUM(F$9:$F37) -> 583500
A38: 45864 | B38: PNEU 225/655R19 GLEDE | C38: 4 | D38: 42500 | E38: =+$I$2+(PETITSOLO[[#This Row],[QUANTITE]]*PETITSOLO[[#This Row],[PRIX UNITAIRE]]) -> 170000 | G38: =SUM(E$9:$E38)-SUM(F$9:$F38) -> 753500
A39: 45877 | B39: PNEU 225/60R18 GLEDE | C39: 4 | D39: 40000 | E39: =+$I$2+(PETITSOLO[[#This Row],[QUANTITE]]*PETITSOLO[[#This Row],[PRIX UNITAIRE]]) -> 160000 | G39: =SUM(E$9:$E39)-SUM(F$9:$F39) -> 913500
A40: 45877 | B40: PNEU 235/60R18 GLEDE | C40: 4 | E40: =+$I$2+(PETITSOLO[[#This Row],[QUANTITE]]*PETITSOLO[[#This Row],[PRIX UNITAIRE]]) -> 0 | G40: =SUM(E$9:$E40)-SUM(F$9:$F40) -> 913500
A41: 45880 | B41: PNEU 255/40R18 GLEDE | C41: 2 | E41: =+$I$2+(PETITSOLO[[#This Row],[QUANTITE]]*PETITSOLO[[#This Row],[PRIX UNITAIRE]]) -> 0 | G41: =SUM(E$9:$E41)-SUM(F$9:$F41) -> 913500
A42: 45881 | B42: PNEU 225./60R17 GLEDE | C42: 4 | D42: 35000 | E42: =+$I$2+(PETITSOLO[[#This Row],[QUANTITE]]*PETITSOLO[[#This Row],[PRIX UNITAIRE]]) -> 140000 | G42: =SUM(E$9:$E42)-SUM(F$9:$F42) -> 1053500
...

Sheet SEINA
I2: 0
D3: ANNEE | E3: CHIFFRE AFFAIRE | F3: TOTAL VERSEMENT | G3: SOLDE
D4: BILAN | E4: =+SUM(SEINA[TOTAL MONTANT]) -> 72485000 | F4: =+SUM(SEINA[VERSEMENT]) -> 70325000 | G4: =+E4-F4 -> 2160000
B5: NOM CLIENT
B6: SEINA
A8: DATE | B8: DESIGNATION | C8: QUANTITE | D8: PRIX UNITAIRE | E8: TOTAL MONTANT | F8: VERSEMENT | G8: SOLDE
A9: 45084 | B9: PNEU 315/80R22,5 MIXTE | C9: 20 | D9: 125000 | E9: =+$I$2+(SEINA[[#This Row],[QUANTITE]]*SEINA[[#This Row],[PRIX UNITAIRE]]) -> 2500000 | F9: 0 | G9: =SUM(E$9:$E9)-SUM(F$9:$F9) -> 2500000
B10: PNEU 750R16 JK GD | C10: 10 | D10: 95000 | E10: =+$I$2+(SEINA[[#This Row],[QUANTITE]]*SEINA[[#This Row],[PRIX UNITAIRE]]) -> 950000 | F10: 0 | G10: =SUM(E$9:$E10)-SUM(F$9:$F10) -> 3450000
A11: 45121 | B11: VERSEMENT | C11: 1 | D11: 0 | E11: =+$I$2+(SEINA[[#This Row],[QUANTITE]]*SEINA[[#This Row],[PRIX UNITAIRE]]) -> 0 | F11: 3450000 | G11: =SUM(E$9:$E11)-SUM(F$9:$F11) -> 0
A12: 45187 | B12: PNEU 245/65R17 KAPSEN | C12: 4 | D12: 60000 | E12: =+$I$2+(SEINA[[#This Row],[QUANTITE]]*SEINA[[#This Row],[PRIX UNITAIRE]]) -> 240000 | F12: 0 | G12: =SUM(E$9:$E12)-SUM(F$9:$F12) -> 240000
A13: 45187 | B13: PNEU 215/55R17 HABLEAD | C13: 4 | D13: 50000 | E13: =+$I$2+(SEINA[[#This Row],[QUANTITE]]*SEINA[[#This Row],[PRIX UNITAIRE]]) -> 200000 | F13: 0 | G13: =SUM(E$9:$E13)-SUM(F$9:$F13) -> 440000
A14: 45191 | B14: PNEU 750R16 JK GD | C14: 80 | D14: 95000 | E14: =+$I$2+(SEINA[[#This Row],[QUANTITE]]*SEINA[[#This Row],[PRIX UNITAIRE]]) -> 7600000 | F14: 0 | G14: =SUM(E$9:$E14)-SUM(F$9:$F14) -> 8040000
B15: PNEU 385/65R22.5 KELLY | C15: 8 | D15: 350000 | E15: =+$I$2+(SEINA[[#This Row],[QUANTITE]]*SEINA[[#This Row],[PRIX UNITAIRE]]) -> 2800000 | F15: 0 | G15: =SUM(E$9:$E15)-SUM(F$9:$F15) -> 10840000
B16: PNEU 315/80R22,5 MIXTE | C16: 30 | D16: 125000 | E16: =+$I$2+(SEINA[[#This Row],[QUANTITE]]*SEINA[[#This Row],[PRIX UNITAIRE]]) -> 3750000 | F16: 0 | G16: =SUM(E$9:$E16)-SUM(F$9:$F16) -> 14590000
B17: VERSEMENT | C17: 1 | D17: 0 | E17: =+$I$2+(SEINA[[#This Row],[QUANTITE]]*SEINA[[#This Row],[PRIX UNITAIRE]]) -> 0 | F17: 14590000 | G17: =SUM(E$9:$E17)-SUM(F$9:$F17) -> 0
A18: 45323 | B18: HOUSSE FAUTEUIL CUIR | C18: 1 | D18: 65000 | E18: =+$I$2+(SEINA[[#This Row],[QUANTITE]]*SEINA[[#This Row],[PRIX UNITAIRE]]) -> 65000 | F18: 0 | G18: =SUM(E$9:$E18)-SUM(F$9:$F18) -> 65000
B19: TAPIS ORIGINAL MITSUBISHI | C19: 1 | D19: 40000 | E19: =+$I$2+(SEINA[[#This Row],[QUANTITE]]*SEINA[[#This Row],[PRIX UNITAIRE]]) -> 40000 | F19: 0 | G19: =SUM(E$9:$E19)-SUM(F$9:$F19) -> 105000
B20: CHAMPOIN AUTO WASH LIQUI MOLY | C20: 1 | D20: 15000 | E20: =+$I$2+(SEINA[[#This Row],[QUANTITE]]*SEINA[[#This Row],[PRIX UNITAIRE]]) -> 15000 | F20: 0 | G20: =SUM(E$9:$E20)-SUM(F$9:$F20) -> 120000
B21: NETTOYANT TABLEAU DE BOARD | C21: 1 | D21: 10000 | E21: =+$I$2+(SEINA[[#This Row],[QUANTITE]]*SEINA[[#This Row],[PRIX UNITAIRE]]) -> 10000 | F21: 0 | G21: =SUM(E$9:$E21)-SUM(F$9:$F21) -> 130000
B22: EXTINCTEUR 1000ML | C22: 1 | D22: 10000 | E22: =+$I$2+(SEINA[[#This Row],[QUANTITE]]*SEINA[[#This Row],[PRIX UNITAIRE]]) -> 10000 | F22: 0 | G22: =SUM(E$9:$E22)-SUM(F$9:$F22) -> 140000
B23: TRIANGLE GRANDE TAILLE | C23: 1 | D23: 5000 | E23: =+$I$2+(SEINA[[#This Row],[QUANTITE]]*SEINA[[#This Row],[PRIX UNITAIRE]]) -> 5000 | F23: 0 | G23: =SUM(E$9:$E23)-SUM(F$9:$F23) -> 145000
B24: COUVRE COLANT | C24: 1 | D24: 10000 | E24: =+$I$2+(SEINA[[#This Row],[QUANTITE]]*SEINA[[#This Row],[PRIX UNITAIRE]]) -> 10000 | F24: 0 | G24: =SUM(E$9:$E24)-SUM(F$9:$F24) -> 155000
A25: 45328 | B25: PNEU 235/65R18 KAPSEN | C25: 4 | D25: 65000 | E25: =+$I$2+(SEINA[[#This Row],[QUANTITE]]*SEINA[[#This Row],[PRIX UNITAIRE]]) -> 260000 | F25: 0 | G25: =SUM(E$9:$E25)-SUM(F$9:$F25) -> 415000
B26: HUILE DE FREIN DOT4 | C26: 1 | D26: 5000 | E26: =+$I$2+(SEINA[[#This Row],[QUANTITE]]*SEINA[[#This Row],[PRIX UNITAIRE]]) -> 5000 | F26: 0 | G26: =SUM(E$9:$E26)-SUM(F$9:$F26) -> 420000
B27: EAU DE RADIATEUR 5L VALEO | C27: 1 | D27: 15000 | E27: =+$I$2+(SEINA[[#This Row],[QUANTITE]]*SEINA[[#This Row],[PRIX UNITAIRE]]) -> 15000 | F27: 0 | G27: =SUM(E$9:$E27)-SUM(F$9:$F27) -> 435000
A28: 45342 | B28: PNEU 235/70R16 APLUS | C28: 4 | D28: 60000 | E28: =+$I$2+(SEINA[[#This Row],[QUANTITE]]*SEINA[[#This Row],[PRIX UNITAIRE]]) -> 240000 | F28: 0 | G28: =SUM(E$9:$E28)-SUM(F$9:$F28) -> 675000
A29: 45366 | B29: PNEU 265/65R17 KAPSEN | C29: 4 | D29: 60000 | E29: =+$I$2+(SEINA[[#This Row],[QUANTITE]]*SEINA[[#This Row],[PRIX UNITAIRE]]) -> 240000 | F29: 0 | G29: =SUM(E$9:$E29)-SUM(F$9:$F29) -> 915000
A30: 45371 | B30: PNEU 750R16 JK GD | C30: 6 | D30: 95000 | E30: =+$I$2+(SEINA[[#This Row],[QUANTITE]]*SEINA[[#This Row],[PRIX UNITAIRE]]) -> 570000 | F30: 0 | G30: =SUM(E$9:$E30)-SUM(F$9:$F30) -> 1485000
A31: 45374 | B31: PNEU 9,5R17,5 | C31: 2 | D31: 85000 | E31: =+$I$2+(SEINA[[#This Row],[QUANTITE]]*SEINA[[#This Row],[PRIX UNITAIRE]]) -> 170000 | F31: 0 | G31: =SUM(E$9:$E31)-SUM(F$9:$F31) -> 1655000
B32: PNEU 235/75R17,5 | C32: 2 | D32: 85000 | E32: =+$I$2+(SEINA[[#This Row],[QUANTITE]]*SEINA[[#This Row],[PRIX UNITAIRE]]) -> 170000 | F32: 0 | G32: =SUM(E$9:$E32)-SUM(F$9:$F32) -> 1825000
A33: 45355 | B33: PNEU 13R22,5 MIXTE | C33: 5 | D33: 160000 | E33: =+$I$2+(SEINA[[#This Row],[QUANTITE]]*SEINA[[#This Row],[PRIX UNITAIRE]]) -> 800000 | F33: 0 | G33: =SUM(E$9:$E33)-SUM(F$9:$F33) -> 2625000
A34: 45464 | B34: PNEU 245/40R18 | C34: 2 | D34: 55000 | E34: =+$I$2+(SEINA[[#This Row],[QUANTITE]]*SEINA[[#This Row],[PRIX UNITAIRE]]) -> 110000 | F34: 0 | G34: =SUM(E$9:$E34)-SUM(F$9:$F34) -> 2735000
A35: 45477 | B35: PARALLELISME+EQULIBRAGE | C35: 1 | D35: 20000 | E35: =+$I$2+(SEINA[[#This Row],[QUANTITE]]*SEINA[[#This Row],[PRIX UNITAIRE]]) -> 20000 | F35: 0 | G35: =SUM(E$9:$E35)-SUM(F$9:$F35) -> 2755000
A36: 45499 | B36: PNEU 23,5-25 | C36: 2 | D36: 900000 | E36: =+$I$2+(SEINA[[#This Row],[QUANTITE]]*SEINA[[#This Row],[PRIX UNITAIRE]]) -> 1800000 | F36: 0 | G36: =SUM(E$9:$E36)-SUM(F$9:$F36) -> 4555000
A37: 45504 | B37: PARALLELISME/L200-8956HZ01 | C37: 1 | D37: 10000 | E37: =+$I$2+(SEINA[[#This Row],[QUANTITE]]*SEINA[[#This Row],[PRIX UNITAIRE]]) -> 10000 | F37: 0 | G37: =SUM(E$9:$E37)-SUM(F$9:$F37) -> 4565000
A38: 45509 | B38: PNEU 255/50R20 KAPSEN -/FORD | C38: 2 | D38: 85000 | E38: =+$I$2+(SEINA[[#This Row],[QUANTITE]]*SEINA[[#This Row],[PRIX UNITAIRE]]) -> 170000 | F38: 0 | G38: =SUM(E$9:$E38)-SUM(F$9:$F38) -> 4735000
A39: 45513 | B39: PNEU 9,5R17,5 | C39: 16 | D39: 85000 | E39: =+$I$2+(SEINA[[#This Row],[QUANTITE]]*SEINA[[#This Row],[PRIX UNITAIRE]]) -> 1360000 | F39: 0 | G39: =SUM(E$9:$E39)-SUM(F$9:$F39) -> 6095000
A40: 45527 | B40: PNEU 235/55R19 TRANSMETRE/ NISSAN | C40: 4 | D40: 65000 | E40: =+$I$2+(SEINA[[#This Row],[QUANTITE]]*SEINA[[#This Row],[PRIX UNITAIRE]]) -> 260000 | F40: 0 | G40: =SUM(E$9:$E40)-SUM(F$9:$F40) -> 6355000
B41: TAPIS ORGINAL NISSAN | C41: 1 | D41: 25000 | E41: =+$I$2+(SEINA[[#This Row],[QUANTITE]]*SEINA[[#This Row],[PRIX UNITAIRE]]) -> 25000 | F41: 0 | G41: =SUM(E$9:$E41)-SUM(F$9:$F41) -> 6380000
A42: 45538 | B42: PNEU 385/65R22.5 KELLY | C42: 2 | D42: 330000 | E42: =+$I$2+(SEINA[[#This Row],[QUANTITE]]*SEINA[[#This Row],[PRIX UNITAIRE]]) -> 660000 | F42: 0 | G42: =SUM(E$9:$E42)-SUM(F$9:$F42) -> 7040000
...

Sheet SAMFO
I2: 0
D3: ANNEE | E3: CHIFFRE AFFAIRE | F3: TOTAL VERSEMENT | G3: SOLDE
D4: BILAN | E4: =+SUM(SAMFO[TOTAL MONTANT]) -> 57593429 | F4: =+SUM(SAMFO[VERSEMENT]) -> 57590000 | G4: =+E4-F4 -> 3429
B5: NOM CLIENT
B6: SAMFO
A8: DATE | B8: DESIGNATION | C8: QUANTITE | D8: PRIX UNITAIRE | E8: TOTAL MONTANT | F8: VERSEMENT | G8: SOLDE
A9: 45641 | B9: INVENTAIRE | C9: 1 | D9: 21202800 | E9: =+$I$2+(SAMFO[[#This Row],[QUANTITE]]*SAMFO[[#This Row],[PRIX UNITAIRE]]) -> 21202800 | G9: =+SUM(E$9:$E9)-SUM(F$9:$F9) -> 21202800
A10: 45644 | B10: PNEU 9,5R17,5 | C10: 2 | D10: 68000 | E10: =+$I$2+(SAMFO[[#This Row],[QUANTITE]]*SAMFO[[#This Row],[PRIX UNITAIRE]]) -> 136000 | G10: =+SUM(E$9:$E10)-SUM(F$9:$F10) -> 21338800
A11: 45649 | B11: PNEU 225/65R17 | C11: 4 | D11: 45000 | E11: =+$I$2+(SAMFO[[#This Row],[QUANTITE]]*SAMFO[[#This Row],[PRIX UNITAIRE]]) -> 180000 | G11: =+SUM(E$9:$E11)-SUM(F$9:$F11) -> 21518800
A12: 45654 | B12: ESPECE | E12: =+$I$2+(SAMFO[[#This Row],[QUANTITE]]*SAMFO[[#This Row],[PRIX UNITAIRE]]) -> 0 | F12: 1444000 | G12: =+SUM(E$9:$E12)-SUM(F$9:$F12) -> 20074800
A13: 45661 | B13: ESPECE | E13: =+$I$2+(SAMFO[[#This Row],[QUANTITE]]*SAMFO[[#This Row],[PRIX UNITAIRE]]) -> 0 | F13: 619000 | G13: =+SUM(E$9:$E13)-SUM(F$9:$F13) -> 19455800
A14: 45668 | B14: ESPECE | E14: =+$I$2+(SAMFO[[#This Row],[QUANTITE]]*SAMFO[[#This Row],[PRIX UNITAIRE]]) -> 0 | F14: 960000 | G14: =+SUM(E$9:$E14)-SUM(F$9:$F14) -> 18495800
A15: 45670 | B15: PNEU 750R15 BRIDGESTONE | C15: 2 | D15: 105000 | E15: =+$I$2+(SAMFO[[#This Row],[QUANTITE]]*SAMFO[[#This Row],[PRIX UNITAIRE]]) -> 210000 | G15: =+SUM(E$9:$E15)-SUM(F$9:$F15) -> 18705800
A16: 45674 | B16: ESPECE | E16: =+$I$2+(SAMFO[[#This Row],[QUANTITE]]*SAMFO[[#This Row],[PRIX UNITAIRE]]) -> 0 | F16: 796000 | G16: =+SUM(E$9:$E16)-SUM(F$9:$F16) -> 17909800
A17: 45678 | B17: PNEU 215/65R16 TRANSMATE | C17: 4 | D17: 35000 | E17: =+$I$2+(SAMFO[[#This Row],[QUANTITE]]*SAMFO[[#This Row],[PRIX UNITAIRE]]) -> 140000 | G17: =+SUM(E$9:$E17)-SUM(F$9:$F17) -> 18049800
A18: 45678 | B18: PNEU 9,5R17,5 | C18: 4 | D18: 70000 | E18: =+$I$2+(SAMFO[[#This Row],[QUANTITE]]*SAMFO[[#This Row],[PRIX UNITAIRE]]) -> 280000 | G18: =+SUM(E$9:$E18)-SUM(F$9:$F18) -> 18329800
A19: 45678 | B19: PNEU 315/80R22,5 BLACK RIDER | C19: 2 | D19: 105000 | E19: =+$I$2+(SAMFO[[#This Row],[QUANTITE]]*SAMFO[[#This Row],[PRIX UNITAIRE]]) -> 210000 | G19: =+SUM(E$9:$E19)-SUM(F$9:$F19) -> 18539800
A20: 45678 | B20: PNEU 7,50R16 BLACK RIDER | C20: 2 | D20: 40000 | E20: =+$I$2+(SAMFO[[#This Row],[QUANTITE]]*SAMFO[[#This Row],[PRIX UNITAIRE]]) -> 80000 | G20: =+SUM(E$9:$E20)-SUM(F$9:$F20) -> 18619800
A21: 45678 | B21: PNEU 13R22,5 KAPSEN | C21: 2 | D21: 135000 | E21: =+$I$2+(SAMFO[[#This Row],[QUANTITE]]*SAMFO[[#This Row],[PRIX UNITAIRE]]) -> 270000 | G21: =+SUM(E$9:$E21)-SUM(F$9:$F21) -> 18889800
A22: 45682 | B22: ESPECE | E22: =+$I$2+(SAMFO[[#This Row],[QUANTITE]]*SAMFO[[#This Row],[PRIX UNITAIRE]]) -> 0 | F22: 806000 | G22: =+SUM(E$9:$E22)-SUM(F$9:$F22) -> 18083800
A23: 45684 | B23: BATTERIE 180AH WHIL | C23: 5 | D23: 60000 | E23: =+$I$2+(SAMFO[[#This Row],[QUANTITE]]*SAMFO[[#This Row],[PRIX UNITAIRE]]) -> 300000 | G23: =+SUM(E$9:$E23)-SUM(F$9:$F23) -> 18383800
A24: 45684 | B24: BATTERIE 180AH TACOMA | C24: 1 | D24: 65000 | E24: =+$I$2+(SAMFO[[#This Row],[QUANTITE]]*SAMFO[[#This Row],[PRIX UNITAIRE]]) -> 65000 | G24: =+SUM(E$9:$E24)-SUM(F$9:$F24) -> 18448800
A25: 45684 | B25: BATTERIE 75AH CONTINENTAL | C25: 5 | D25: 43000 | E25: =+$I$2+(SAMFO[[#This Row],[QUANTITE]]*SAMFO[[#This Row],[PRIX UNITAIRE]]) -> 215000 | G25: =+SUM(E$9:$E25)-SUM(F$9:$F25) -> 18663800
A26: 45685 | B26: BATTERIE 100AH CONTINENTAL | C26: 5 | D26: 60000 | E26: =+$I$2+(SAMFO[[#This Row],[QUANTITE]]*SAMFO[[#This Row],[PRIX UNITAIRE]]) -> 300000 | G26: =+SUM(E$9:$E26)-SUM(F$9:$F26) -> 18963800
A27: 45685 | B27: BATTERIE 90AH CONTINENTAL | C27: 7 | D27: 55000 | E27: =+$I$2+(SAMFO[[#This Row],[QUANTITE]]*SAMFO[[#This Row],[PRIX UNITAIRE]]) -> 385000 | G27: =+SUM(E$9:$E27)-SUM(F$9:$F27) -> 19348800
A28: 45685 | B28: BATTERIE 150AH ESAN | C28: 2 | D28: 60000 | E28: =+$I$2+(SAMFO[[#This Row],[QUANTITE]]*SAMFO[[#This Row],[PRIX UNITAIRE]]) -> 120000 | G28: =+SUM(E$9:$E28)-SUM(F$9:$F28) -> 19468800
A29: 45685 | B29: BATTERIE 120AH BEYONIX | C29: 1 | D29: 55000 | E29: =+$I$2+(SAMFO[[#This Row],[QUANTITE]]*SAMFO[[#This Row],[PRIX UNITAIRE]]) -> 55000 | G29: =+SUM(E$9:$E29)-SUM(F$9:$F29) -> 19523800
A30: 45685 | B30: BATTERIE 200AH TACOMA | C30: 1 | D30: 90000 | E30: =+$I$2+(SAMFO[[#This Row],[QUANTITE]]*SAMFO[[#This Row],[PRIX UNITAIRE]]) -> 90000 | G30: =+SUM(E$9:$E30)-SUM(F$9:$F30) -> 19613800
A31: 45686 | B31: BARIQUE HUILE 10W 200L | C31: 1 | D31: 300000 | E31: =+$I$2+(SAMFO[[#This Row],[QUANTITE]]*SAMFO[[#This Row],[PRIX UNITAIRE]]) -> 300000 | G31: =+SUM(E$9:$E31)-SUM(F$9:$F31) -> 19913800
A32: 45686 | B32: BARIQUE HUILE 15W40 200L | C32: 1 | D32: 360000 | E32: =+$I$2+(SAMFO[[#This Row],[QUANTITE]]*SAMFO[[#This Row],[PRIX UNITAIRE]]) -> 360000 | G32: =+SUM(E$9:$E32)-SUM(F$9:$F32) -> 20273800
A33: 45689 | B33: ESPECE | E33: =+$I$2+(SAMFO[[#This Row],[QUANTITE]]*SAMFO[[#This Row],[PRIX UNITAIRE]]) -> 0 | F33: 2100000 | G33: =+SUM(E$9:$E33)-SUM(F$9:$F33) -> 18173800
A34: 45691 | B34: PNEU 7,50R16 TAITONG | C34: 4 | D34: 45000 | E34: =+$I$2+(SAMFO[[#This Row],[QUANTITE]]*SAMFO[[#This Row],[PRIX UNITAIRE]]) -> 180000 | G34: =+SUM(E$9:$E34)-SUM(F$9:$F34) -> 18353800
A35: 45691 | B35: PNEU 265/65R17 | C35: 2 | D35: 50000 | E35: =+$I$2+(SAMFO[[#This Row],[QUANTITE]]*SAMFO[[#This Row],[PRIX UNITAIRE]]) -> 100000 | G35: =+SUM(E$9:$E35)-SUM(F$9:$F35) -> 18453800
A36: 45691 | B36: PNEU 225/70R15C TRANSMATE | C36: 4 | D36: 40000 | E36: =+$I$2+(SAMFO[[#This Row],[QUANTITE]]*SAMFO[[#This Row],[PRIX UNITAIRE]]) -> 160000 | G36: =+SUM(E$9:$E36)-SUM(F$9:$F36) -> 18613800
A37: 45691 | B37: BATTERIE 75AH ESAN | C37: 5 | D37: 25000 | E37: =+$I$2+(SAMFO[[#This Row],[QUANTITE]]*SAMFO[[#This Row],[PRIX UNITAIRE]]) -> 125000 | G37: =+SUM(E$9:$E37)-SUM(F$9:$F37) -> 18738800
A38: 45691 | B38: BATTERIE 100AH BEYONIX | C38: 2 | D38: 45000 | E38: =+$I$2+(SAMFO[[#This Row],[QUANTITE]]*SAMFO[[#This Row],[PRIX UNITAIRE]]) -> 90000 | G38: =+SUM(E$9:$E38)-SUM(F$9:$F38) -> 18828800
A39: 45691 | B39: PNEU 315/80R22,5 BLACK RIDER | C39: 2 | D39: 105000 | E39: =+$I$2+(SAMFO[[#This Row],[QUANTITE]]*SAMFO[[#This Row],[PRIX UNITAIRE]]) -> 210000 | G39: =+SUM(E$9:$E39)-SUM(F$9:$F39) -> 19038800
A40: 45692 | B40: PNEU 13R22,5 MIXTE | C40: 4 | D40: 135000 | E40: =+$I$2+(SAMFO[[#This Row],[QUANTITE]]*SAMFO[[#This Row],[PRIX UNITAIRE]]) -> 540000 | G40: =+SUM(E$9:$E40)-SUM(F$9:$F40) -> 19578800
A41: 45695 | B41: PNEU 265/65R17 | C41: 2 | D41: 50000 | E41: =+$I$2+(SAMFO[[#This Row],[QUANTITE]]*SAMFO[[#This Row],[PRIX UNITAIRE]]) -> 100000 | G41: =+SUM(E$9:$E41)-SUM(F$9:$F41) -> 19678800
A42: 45696 | B42: ESPECE | E42: =+$I$2+(SAMFO[[#This Row],[QUANTITE]]*SAMFO[[#This Row],[PRIX UNITAIRE]]) -> 0 | F42: 1188000 | G42: =+SUM(E$9:$E42)-SUM(F$9:$F42) -> 18490800
...

Sheet FBD
I2: 0
D3: ANNEE | E3: CHIFFRE AFFAIRE | F3: TOTAL VERSEMENT | G3: SOLDE
D4: BILAN | E4: =+SUM(FBD[TOTAL MONTANT]) -> 194226350 | F4: =+SUM(FBD[VERSEMENT]) -> 160676000 | G4: =+E4-F4 -> 33550350
B5: NOM CLIENT
B6: FBD
A8: DATE | B8: DESIGNATION | C8: QUANTITE | D8: PRIX UNITAIRE | E8: TOTAL MONTANT | F8: VERSEMENT | G8: SOLDE
A9: 45641 | B9: INVENTAIRE | C9: 1 | D9: 15294000 | E9: =+$I$2+(FBD[[#This Row],[QUANTITE]]*FBD[[#This Row],[PRIX UNITAIRE]]) -> 15294000 | G9: =+SUM(E$9:$E9)-SUM(F$9:$F9) -> 15294000
A10: 45645 | B10: BIDON D'HUILE 15W40 20L | C10: 4 | D10: 33000 | E10: =+$I$2+(FBD[[#This Row],[QUANTITE]]*FBD[[#This Row],[PRIX UNITAIRE]]) -> 132000 | G10: =+SUM(E$9:$E10)-SUM(F$9:$F10) -> 15426000
A11: 45646 | B11: BARRIQUE DE GRAISSE | C11: 1 | D11: 33000 | E11: =+$I$2+(FBD[[#This Row],[QUANTITE]]*FBD[[#This Row],[PRIX UNITAIRE]]) -> 33000 | G11: =+SUM(E$9:$E11)-SUM(F$9:$F11) -> 15459000
A12: 45646 | B12: PNEU 13R22.5 | C12: 4 | D12: 128000 | E12: =+$I$2+(FBD[[#This Row],[QUANTITE]]*FBD[[#This Row],[PRIX UNITAIRE]]) -> 512000 | G12: =+SUM(E$9:$E12)-SUM(F$9:$F12) -> 15971000
A13: 45646 | B13: PNEU 9.5R17.5 | C13: 4 | D13: 50000 | E13: =+$I$2+(FBD[[#This Row],[QUANTITE]]*FBD[[#This Row],[PRIX UNITAIRE]]) -> 200000 | G13: =+SUM(E$9:$E13)-SUM(F$9:$F13) -> 16171000
A14: 45646 | B14: PNEU 315/80R22.5 GD | C14: 2 | D14: 105000 | E14: =+$I$2+(FBD[[#This Row],[QUANTITE]]*FBD[[#This Row],[PRIX UNITAIRE]]) -> 210000 | G14: =+SUM(E$9:$E14)-SUM(F$9:$F14) -> 16381000
A15: 45646 | B15: PNEU 7.50R16 | C15: 2 | D15: 70000 | E15: =+$I$2+(FBD[[#This Row],[QUANTITE]]*FBD[[#This Row],[PRIX UNITAIRE]]) -> 140000 | G15: =+SUM(E$9:$E15)-SUM(F$9:$F15) -> 16521000
A16: 45650 | B16: PNEU 13R22.5 GD | C16: 8 | D16: 128000 | E16: =+$I$2+(FBD[[#This Row],[QUANTITE]]*FBD[[#This Row],[PRIX UNITAIRE]]) -> 1024000 | G16: =+SUM(E$9:$E16)-SUM(F$9:$F16) -> 17545000
A17: 45650 | B17: CRIC 50T | C17: 4 | D17: 25000 | E17: =+$I$2+(FBD[[#This Row],[QUANTITE]]*FBD[[#This Row],[PRIX UNITAIRE]]) -> 100000 | G17: =+SUM(E$9:$E17)-SUM(F$9:$F17) -> 17645000
A18: 45650 | B18: BATTERIE 75AH ESAN | C18: 4 | D18: 23500 | E18: =+$I$2+(FBD[[#This Row],[QUANTITE]]*FBD[[#This Row],[PRIX UNITAIRE]]) -> 94000 | G18: =+SUM(E$9:$E18)-SUM(F$9:$F18) -> 17739000
A19: 45653 | B19: PNEU 315/80R22.5 ZEXTOUR | C19: 6 | D19: 95000 | E19: =+$I$2+(FBD[[#This Row],[QUANTITE]]*FBD[[#This Row],[PRIX UNITAIRE]]) -> 570000 | G19: =+SUM(E$9:$E19)-SUM(F$9:$F19) -> 18309000
A20: 45654 | B20: ESPECE | E20: =+$I$2+(FBD[[#This Row],[QUANTITE]]*FBD[[#This Row],[PRIX UNITAIRE]]) -> 0 | F20: 582000 | G20: =+SUM(E$9:$E20)-SUM(F$9:$F20) -> 17727000
A21: 45656 | B21: PNEU TRANSMATE 155/70R13 | C21: 2 | D21: 22000 | E21: =+$I$2+(FBD[[#This Row],[QUANTITE]]*FBD[[#This Row],[PRIX UNITAIRE]]) -> 44000 | G21: =+SUM(E$9:$E21)-SUM(F$9:$F21) -> 17771000
A22: 45656 | B22: FILTRE A HUILE 15600-41010 | C22: 4 | D22: 5000 | E22: =+$I$2+(FBD[[#This Row],[QUANTITE]]*FBD[[#This Row],[PRIX UNITAIRE]]) -> 20000 | G22: =+SUM(E$9:$E22)-SUM(F$9:$F22) -> 17791000
A23: 45660 | B23: ESPECE | E23: =+$I$2+(FBD[[#This Row],[QUANTITE]]*FBD[[#This Row],[PRIX UNITAIRE]]) -> 0 | F23: 1046000 | G23: =+SUM(E$9:$E23)-SUM(F$9:$F23) -> 16745000
A24: 45664 | B24: CHEQUE | E24: =+$I$2+(FBD[[#This Row],[QUANTITE]]*FBD[[#This Row],[PRIX UNITAIRE]]) -> 0 | F24: 1100000 | G24: =+SUM(E$9:$E24)-SUM(F$9:$F24) -> 15645000
A25: 45664 | B25: PNEU 315/80R22,5 | C25: 12 | D25: 95000 | E25: =+$I$2+(FBD[[#This Row],[QUANTITE]]*FBD[[#This Row],[PRIX UNITAIRE]]) -> 1140000 | G25: =+SUM(E$9:$E25)-SUM(F$9:$F25) -> 16785000
A26: 45664 | B26: PNEU 13R22,5 MIXTE | C26: 2 | D26: 120000 | E26: =+$I$2+(FBD[[#This Row],[QUANTITE]]*FBD[[#This Row],[PRIX UNITAIRE]]) -> 240000 | G26: =+SUM(E$9:$E26)-SUM(F$9:$F26) -> 17025000
A27: 45664 | B27: PNEU 175/70R14 | C27: 4 | D27: 20000 | E27: =+$I$2+(FBD[[#This Row],[QUANTITE]]*FBD[[#This Row],[PRIX UNITAIRE]]) -> 80000 | G27: =+SUM(E$9:$E27)-SUM(F$9:$F27) -> 17105000
A28: 45664 | B28: BATTERIE 100AH ESAN | C28: 2 | D28: 40000 | E28: =+$I$2+(FBD[[#This Row],[QUANTITE]]*FBD[[#This Row],[PRIX UNITAIRE]]) -> 80000 | G28: =+SUM(E$9:$E28)-SUM(F$9:$F28) -> 17185000
A29: 45664 | B29: PNEU 235/75R17,5 | C29: 4 | D29: 45000 | E29: =+$I$2+(FBD[[#This Row],[QUANTITE]]*FBD[[#This Row],[PRIX UNITAIRE]]) -> 180000 | G29: =+SUM(E$9:$E29)-SUM(F$9:$F29) -> 17365000
A30: 45665 | B30: HUILE DE FREIN STOP | C30: 10 | D30: 3500 | E30: =+$I$2+(FBD[[#This Row],[QUANTITE]]*FBD[[#This Row],[PRIX UNITAIRE]]) -> 35000 | G30: =+SUM(E$9:$E30)-SUM(F$9:$F30) -> 17400000
A31: 45666 | B31: BLACKRIDER 315/80R22,5 | C31: 5 | D31: 95000 | E31: =+$I$2+(FBD[[#This Row],[QUANTITE]]*FBD[[#This Row],[PRIX UNITAIRE]]) -> 475000 | G31: =+SUM(E$9:$E31)-SUM(F$9:$F31) -> 17875000
A32: 45668 | B32: ESPECE | E32: =+$I$2+(FBD[[#This Row],[QUANTITE]]*FBD[[#This Row],[PRIX UNITAIRE]]) -> 0 | F32: 3637500 | G32: =+SUM(E$9:$E32)-SUM(F$9:$F32) -> 14237500
A33: 45668 | B33: CHEQUE | E33: =+$I$2+(FBD[[#This Row],[QUANTITE]]*FBD[[#This Row],[PRIX UNITAIRE]]) -> 0 | F33: 720000 | G33: =+SUM(E$9:$E33)-SUM(F$9:$F33) -> 13517500
A34: 45670 | B34: PNEU 225/75R16C | C34: 2 | D34: 40000 | E34: =+$I$2+(FBD[[#This Row],[QUANTITE]]*FBD[[#This Row],[PRIX UNITAIRE]]) -> 80000 | G34: =+SUM(E$9:$E34)-SUM(F$9:$F34) -> 13597500
A35: 45672 | B35: BATTERIE 75AH ESAN | C35: 10 | D35: 23500 | E35: =+$I$2+(FBD[[#This Row],[QUANTITE]]*FBD[[#This Row],[PRIX UNITAIRE]]) -> 235000 | G35: =+SUM(E$9:$E35)-SUM(F$9:$F35) -> 13832500
A36: 45672 | B36: BATTERIE 150AH | C36: 4 | D36: 65000 | E36: =+$I$2+(FBD[[#This Row],[QUANTITE]]*FBD[[#This Row],[PRIX UNITAIRE]]) -> 260000 | G36: =+SUM(E$9:$E36)-SUM(F$9:$F36) -> 14092500
A37: 45672 | B37: PNEU 315/80R22,5 MIXTE | C37: 4 | D37: 95000 | E37: =+$I$2+(FBD[[#This Row],[QUANTITE]]*FBD[[#This Row],[PRIX UNITAIRE]]) -> 380000 | G37: =+SUM(E$9:$E37)-SUM(F$9:$F37) -> 14472500
A38: 45672 | B38: PNEU 315/80R22,5 PD | C38: 1 | D38: 107500 | E38: =+$I$2+(FBD[[#This Row],[QUANTITE]]*FBD[[#This Row],[PRIX UNITAIRE]]) -> 107500 | G38: =+SUM(E$9:$E38)-SUM(F$9:$F38) -> 14580000
A39: 45672 | B39: BATTERIE 200AH | C39: 4 | D39: 80000 | E39: =+$I$2+(FBD[[#This Row],[QUANTITE]]*FBD[[#This Row],[PRIX UNITAIRE]]) -> 320000 | G39: =+SUM(E$9:$E39)-SUM(F$9:$F39) -> 14900000
A40: 45672 | B40: BATTERIE 180AH | C40: 2 | D40: 65000 | E40: =+$I$2+(FBD[[#This Row],[QUANTITE]]*FBD[[#This Row],[PRIX UNITAIRE]]) -> 130000 | G40: =+SUM(E$9:$E40)-SUM(F$9:$F40) -> 15030000
A41: 45674 | B41: ESPECE | E41: =+$I$2+(FBD[[#This Row],[QUANTITE]]*FBD[[#This Row],[PRIX UNITAIRE]]) -> 0 | F41: 1755000 | G41: =+SUM(E$9:$E41)-SUM(F$9:$F41) -> 13275000
A42: 45678 | B42: PNEU 315/80R22,5 BLACKRIDER | C42: 4 | D42: 105000 | E42: =+$I$2+(FBD[[#This Row],[QUANTITE]]*FBD[[#This Row],[PRIX UNITAIRE]]) -> 420000 | G42: =+SUM(E$9:$E42)-SUM(F$9:$F42) -> 13695000
...

Sheet ARTCI
I1: 0
D3: ANNEE | E3: CHIFFRE AFFAIRE | F3: TOTAL VERSEMENT | G3: SOLDE
D4: BILAN | E4: =+SUM(ARTCI[TOTAL MONTANT]) -> 5945000 | F4: =+SUM(ARTCI[VERSEMENT]) -> 5945000 | G4: =+E4-F4 -> 0
B5: NOM CLIENT
B6: ARTCI
A8: DATE | B8: DESIGNATION | C8: QUANTITE | D8: PRIX UNITAIRE | E8: TOTAL MONTANT | F8: VERSEMENT | G8: SOLDE
A9: 45786 | B9: PNEU 225/60R17 TRANSMATE / 1216LP01 | C9: 4 | D9: 75000 | E9: =$I$1+(ARTCI[[#This Row],[QUANTITE]]*ARTCI[[#This Row],[PRIX UNITAIRE]]) -> 300000 | G9: =SUM(E$9:$E9)-SUM(F$9:$F9) -> 300000
A10: 45791 | B10: PNEU 205/75R17,5 TAITONG / AA-744-PE | C10: 1 | D10: 80000 | E10: =$I$1+(ARTCI[[#This Row],[QUANTITE]]*ARTCI[[#This Row],[PRIX UNITAIRE]]) -> 80000 | G10: =SUM(E$9:$E10)-SUM(F$9:$F10) -> 380000
A11: 45791 | B11: JANTE 17,5 | C11: 1 | D11: 60000 | E11: =$I$1+(ARTCI[[#This Row],[QUANTITE]]*ARTCI[[#This Row],[PRIX UNITAIRE]]) -> 60000 | G11: =SUM(E$9:$E11)-SUM(F$9:$F11) -> 440000
A12: 45846 | B12: PAYE PAR CHEQUE | C12: 1 | D12: 0 | E12: =$I$1+(ARTCI[[#This Row],[QUANTITE]]*ARTCI[[#This Row],[PRIX UNITAIRE]]) -> 0 | F12: 300000 | G12: =SUM(E$9:$E12)-SUM(F$9:$F12) -> 140000
A13: 45846 | B13: PAYE EN ESPECES | C13: 1 | D13: 1305000 | E13: =$I$1+(ARTCI[[#This Row],[QUANTITE]]*ARTCI[[#This Row],[PRIX UNITAIRE]]) -> 1305000 | F13: 140000 | G13: =SUM(E$9:$E13)-SUM(F$9:$F13) -> 1305000
A14: 45856 | B14: PNEU 215/50R17 GLEDE | C14: 5 | D14: 65000 | E14: =$I$1+(ARTCI[[#This Row],[QUANTITE]]*ARTCI[[#This Row],[PRIX UNITAIRE]]) -> 325000 | G14: =SUM(E$9:$E14)-SUM(F$9:$F14) -> 1630000
A15: 45856 | B15: SILENTBLOC DE BRAS AV | C15: 4 | D15: 20000 | E15: =$I$1+(ARTCI[[#This Row],[QUANTITE]]*ARTCI[[#This Row],[PRIX UNITAIRE]]) -> 80000 | G15: =SUM(E$9:$E15)-SUM(F$9:$F15) -> 1710000
A16: 45880 | B16: PNEU 225/50R17 GLEDE | C16: 5 | D16: 65000 | E16: =$I$1+(ARTCI[[#This Row],[QUANTITE]]*ARTCI[[#This Row],[PRIX UNITAIRE]]) -> 325000 | G16: =SUM(E$9:$E16)-SUM(F$9:$F16) -> 2035000
A17: 45903 | B17: PNEU 225/50R17 GLEDE | C17: 4 | D17: 65000 | E17: =$I$1+(ARTCI[[#This Row],[QUANTITE]]*ARTCI[[#This Row],[PRIX UNITAIRE]]) -> 260000 | G17: =SUM(E$9:$E17)-SUM(F$9:$F17) -> 2295000
A18: 45903 | B18: PNE 205/60R16 GLEDE | C18: 1 | D18: 65000 | E18: =$I$1+(ARTCI[[#This Row],[QUANTITE]]*ARTCI[[#This Row],[PRIX UNITAIRE]]) -> 65000 | G18: =SUM(E$9:$E18)-SUM(F$9:$F18) -> 2360000
A19: 45905 | B19: PAYE CHEQUE | E19: =$I$1+(ARTCI[[#This Row],[QUANTITE]]*ARTCI[[#This Row],[PRIX UNITAIRE]]) -> 0 | F19: 540000 | G19: =SUM(E$9:$E19)-SUM(F$9:$F19) -> 1820000
A20: 45905 | B20: PAYE CHEQUE | E20: =$I$1+(ARTCI[[#This Row],[QUANTITE]]*ARTCI[[#This Row],[PRIX UNITAIRE]]) -> 0 | F20: 975000 | G20: =SUM(E$9:$E20)-SUM(F$9:$F20) -> 845000
A21: 45912 | B21: PNEU 185/65R15 | C21: 5 | D21: 45000 | E21: =$I$1+(ARTCI[[#This Row],[QUANTITE]]*ARTCI[[#This Row],[PRIX UNITAIRE]]) -> 225000 | G21: =SUM(E$9:$E21)-SUM(F$9:$F21) -> 1070000
A22: 45912 | B22: PNEU 315/40R21 | C22: 2 | D22: 200000 | E22: =$I$1+(ARTCI[[#This Row],[QUANTITE]]*ARTCI[[#This Row],[PRIX UNITAIRE]]) -> 400000 | G22: =SUM(E$9:$E22)-SUM(F$9:$F22) -> 1470000
A23: 45912 | B23: PNEU 275/45R21 | C23: 2 | D23: 150000 | E23: =$I$1+(ARTCI[[#This Row],[QUANTITE]]*ARTCI[[#This Row],[PRIX UNITAIRE]]) -> 300000 | G23: =SUM(E$9:$E23)-SUM(F$9:$F23) -> 1770000
A24: 45912 | B24: MONTAGE/ PARALLELISME | C24: 1 | D24: 10000 | E24: =$I$1+(ARTCI[[#This Row],[QUANTITE]]*ARTCI[[#This Row],[PRIX UNITAIRE]]) -> 10000 | G24: =SUM(E$9:$E24)-SUM(F$9:$F24) -> 1780000
A25: 45919 | B25: PAYE CHEQUE | E25: =$I$1+(ARTCI[[#This Row],[QUANTITE]]*ARTCI[[#This Row],[PRIX UNITAIRE]]) -> 0 | F25: 1000000 | G25: =SUM(E$9:$E25)-SUM(F$9:$F25) -> 780000
A26: 45923 | B26: PNEU 185/65R15 GLEDE | C26: 5 | D26: 45000 | E26: =$I$1+(ARTCI[[#This Row],[QUANTITE]]*ARTCI[[#This Row],[PRIX UNITAIRE]]) -> 225000 | G26: =SUM(E$9:$E26)-SUM(F$9:$F26) -> 1005000
C27: 1 | D27: 400000 | E27: =$I$1+(ARTCI[[#This Row],[QUANTITE]]*ARTCI[[#This Row],[PRIX UNITAIRE]]) -> 400000 | G27: =SUM(E$9:$E27)-SUM(F$9:$F27) -> 1405000
A28: 45940 | B28: PNEU 235/60R18 GLEDE | C28: 4 | D28: 85000 | E28: =$I$1+(ARTCI[[#This Row],[QUANTITE]]*ARTCI[[#This Row],[PRIX UNITAIRE]]) -> 340000 | G28: =SUM(E$9:$E28)-SUM(F$9:$F28) -> 1745000
A29: 45940 | B29: PAYE PAR CHEQUE | E29: =$I$1+(ARTCI[[#This Row],[QUANTITE]]*ARTCI[[#This Row],[PRIX UNITAIRE]]) -> 0 | F29: 340000 | G29: =SUM(E$9:$E29)-SUM(F$9:$F29) -> 1405000
A30: 45961 | B30: PNEU 235/50R20 BRIDGESTONE / MAZDA | C30: 1 | D30: 225000 | E30: =$I$1+(ARTCI[[#This Row],[QUANTITE]]*ARTCI[[#This Row],[PRIX UNITAIRE]]) -> 225000 | G30: =SUM(E$9:$E30)-SUM(F$9:$F30) -> 1630000
B31: PAYER PAR CHEQUE N° | C31: 1 | D31: 0 | E31: =$I$1+(ARTCI[[#This Row],[QUANTITE]]*ARTCI[[#This Row],[PRIX UNITAIRE]]) -> 0 | F31: 235000 | G31: =SUM(E$9:$E31)-SUM(F$9:$F31) -> 1395000
A32: 45986 | B32: PNEU 305/40R20 PIRELI - BMW AA-417-HG | C32: 2 | D32: 290000 | E32: =$I$1+(ARTCI[[#This Row],[QUANTITE]]*ARTCI[[#This Row],[PRIX UNITAIRE]]) -> 580000 | G32: =SUM(E$9:$E32)-SUM(F$9:$F32) -> 1975000
A33: 45986 | B33: PNEU 275/45R20 PIRELI - BMW | C33: 2 | D33: 220000 | E33: =$I$1+(ARTCI[[#This Row],[QUANTITE]]*ARTCI[[#This Row],[PRIX UNITAIRE]]) -> 440000 | G33: =SUM(E$9:$E33)-SUM(F$9:$F33) -> 2415000
E34: =$I$1+(ARTCI[[#This Row],[QUANTITE]]*ARTCI[[#This Row],[PRIX UNITAIRE]]) -> 0 | F34: 1195000 | G34: =SUM(E$9:$E34)-SUM(F$9:$F34) -> 1220000
A35: 46048 | B35: PAYER PAR CHEQUE N° | C35: 1 | D35: 0 | E35: =$I$1+(ARTCI[[#This Row],[QUANTITE]]*ARTCI[[#This Row],[PRIX UNITAIRE]]) -> 0 | F35: 1220000 | G35: =SUM(E$9:$E35)-SUM(F$9:$F35) -> 0
E36: =$I$1+(ARTCI[[#This Row],[QUANTITE]]*ARTCI[[#This Row],[PRIX UNITAIRE]]) -> 0 | G36: =SUM(E$9:$E36)-SUM(F$9:$F36) -> 0
E37: =$I$1+(ARTCI[[#This Row],[QUANTITE]]*ARTCI[[#This Row],[PRIX UNITAIRE]]) -> 0 | G37: =SUM(E$9:$E37)-SUM(F$9:$F37) -> 0
E38: =$I$1+(ARTCI[[#This Row],[QUANTITE]]*ARTCI[[#This Row],[PRIX UNITAIRE]]) -> 0 | G38: =SUM(E$9:$E38)-SUM(F$9:$F38) -> 0
E39: =$I$1+(ARTCI[[#This Row],[QUANTITE]]*ARTCI[[#This Row],[PRIX UNITAIRE]]) -> 0 | G39: =SUM(E$9:$E39)-SUM(F$9:$F39) -> 0
E40: =$I$1+(ARTCI[[#This Row],[QUANTITE]]*ARTCI[[#This Row],[PRIX UNITAIRE]]) -> 0 | G40: =SUM(E$9:$E40)-SUM(F$9:$F40) -> 0
E41: =$I$1+(ARTCI[[#This Row],[QUANTITE]]*ARTCI[[#This Row],[PRIX UNITAIRE]]) -> 0 | G41: =SUM(E$9:$E41)-SUM(F$9:$F41) -> 0
E42: =$I$1+(ARTCI[[#This Row],[QUANTITE]]*ARTCI[[#This Row],[PRIX UNITAIRE]]) -> 0 | G42: =SUM(E$9:$E42)-SUM(F$9:$F42) -> 0
...

Sheet AFCHEM-SOFACO
I2: 0
D3: ANNEE | E3: CHIFFRE AFFAIRE | F3: TOTAL VERSEMENT | G3: SOLDE
D4: BILAN | E4: =+SUM(SOFACO[TOTAL MONTANT]) -> 7042000 | F4: =+SUM(SOFACO[VERSEMENT]) -> 5360000 | G4: =+E4-F4 -> 1682000
B5: NOM CLIENT
B6: AFCHEM-SOFACO
A8: DATE | B8: DESIGNATION | C8: QUANTITE | D8: PRIX UNITAIRE | E8: TOTAL MONTANT | F8: VERSEMENT | G8: SOLDE
A9: 45798 | B9: PNEU 315/80R22,5 EUROPEEN | C9: 2 | D9: 325000 | E9: =+$I$2+(SOFACO[[#This Row],[QUANTITE]]*SOFACO[[#This Row],[PRIX UNITAIRE]]) -> 650000 | G9: =+SUM(E$9:$E9)-SUM(F$9:$F9) -> 650000
A10: 45799 | B10: PNEU 205R16C BRIDGESTONE / AA-610-EP | C10: 4 | D10: 135000 | E10: =+$I$2+(SOFACO[[#This Row],[QUANTITE]]*SOFACO[[#This Row],[PRIX UNITAIRE]]) -> 540000 | G10: =+SUM(E$9:$E10)-SUM(F$9:$F10) -> 1190000
A11: 45799 | B11: PNEU 205R16C BRIDGESTONE / 8850JA01 | C11: 4 | D11: 135000 | E11: =+$I$2+(SOFACO[[#This Row],[QUANTITE]]*SOFACO[[#This Row],[PRIX UNITAIRE]]) -> 540000 | G11: =+SUM(E$9:$E11)-SUM(F$9:$F11) -> 1730000
A12: 45811 | B12: PNEU 225/60R17 DUNLOP / 4876JF01 | C12: 4 | D12: 135000 | E12: =+$I$2+(SOFACO[[#This Row],[QUANTITE]]*SOFACO[[#This Row],[PRIX UNITAIRE]]) -> 540000 | G12: =+SUM(E$9:$E12)-SUM(F$9:$F12) -> 2270000
A13: 45847 | B13: PAYE CHEQUE | F13: 1730000 | G13: =+SUM(E$9:$E13)-SUM(F$9:$F13) -> 540000
A14: 45866 | B14: PAYE CHEQUE | E14: =+$I$2+(SOFACO[[#This Row],[QUANTITE]]*SOFACO[[#This Row],[PRIX UNITAIRE]]) -> 0 | F14: 540000 | G14: =+SUM(E$9:$E14)-SUM(F$9:$F14) -> 0
A15: 45890 | B15: REPARATION TOYOTA HILUX | C15: 1 | D15: 0 | E15: =+$I$2+(SOFACO[[#This Row],[QUANTITE]]*SOFACO[[#This Row],[PRIX UNITAIRE]]) -> 0 | G15: =+SUM(E$9:$E15)-SUM(F$9:$F15) -> 0
A16: 45895 | B16: BATTERIE 75 1H | C16: 1 | D16: 65000 | E16: =+$I$2+(SOFACO[[#This Row],[QUANTITE]]*SOFACO[[#This Row],[PRIX UNITAIRE]]) -> 65000 | G16: =+SUM(E$9:$E16)-SUM(F$9:$F16) -> 65000
A17: 45915 | B17: PNEU 265/65R17 DUNLOP | C17: 1 | D17: 150000 | E17: =+$I$2+(SOFACO[[#This Row],[QUANTITE]]*SOFACO[[#This Row],[PRIX UNITAIRE]]) -> 150000 | G17: =+SUM(E$9:$E17)-SUM(F$9:$F17) -> 215000
